Workbook

Sheet Summary
A1: Netflix (NFLX): valuation summary
A2: Values link to the model sheet (green). Switch the discount rate on the WACC tab.
A4: Company | B4: Method | C4: Share price | D4: Discount rate | E4: Bear value | F4: Base value | G4: Bull value | H4: Base vs price | I4: Implied return at price (base case) | J4: Base value (rounded)
A5: Netflix (NFLX) | B5: 10-year DCF | C5: =NFLX!B4 -> 62.52 | D5: =NFLX!B10 -> 0.095 | E5: =NFLX!B75 -> 39.490496 | F5: =NFLX!B76 -> 65.90734 | G5: =NFLX!B77 -> 90.857835 | H5: =F5/C5-1 -> 0.054180102 | I5: =NFLX!B86 -> 0.098412404 | J5: =IF(F5<10,ROUND(F5*4,0)/4,IF(F5<100,ROUND(F5,0),ROUND(F5/5,0)*5)) -> 66
A8: Not a holding. Buy below is the base value, rounded
A9: Buy below (base value, rounded) | C9: =J5 -> 66
A10: Bull value | C10: =G5 -> 90.857835
A11: Bear value | C11: =E5 -> 39.490496

Sheet NFLX
A1: Netflix (NFLX): 10-year scenario DCF
A2: Units: $ billions unless noted. Blue = input, black = formula, green = link, yellow = key lever. Years 6 to 10 fade growth, margin and reinvestment toward each scenario's terminal levels.
A4: Share price ($) | B4: 62.52 | C4: Oct 27, 2026 close (Stock Analysis)
A5: Price date | B5: Oct 27, 2026 close (Stock Analysis) | C5: Text
A6: Shares outstanding (billions) | B6: 4.106 | C6: Market cap $259.11B / price $63.10, Stock Analysis statistics, Oct 27, 2026
A7: Net cash, negative = net debt | B7: -7.1 | C7: Q3 2026 letter: cash $8.2B less gross debt about $15.3B
A8: Other non-operating assets, less outside claims | B8: 0 | C8: None
A9: Tax rate | B9: 0.165 | C9: Analyst assumption (normalized, near the reported effective rate)
A10: Discount rate (WACC), from WACC tab | B10: =WACC!B29 -> 0.095 | C10: Calculated or assumed, per the switch in WACC!B5
A11: Working capital, % of revenue change | B11: 0 | C11: Analyst assumption
A12: Base-year revenue (2026E) | B12: 51.1 | C12: 2026 guide: revenue $51.1B, 31.5% operating margin, about $12.0B FCF (Q3 2026 letter). Reinvestment includes cash content spend above amortization (about 1.1x) plus capex
A13: Selected scenario (1 Bear, 2 Base, 3 Bull) | B13: 2 | C13: Lever
A15: Year | B15: 2027 | C15: 2028 | D15: 2029 | E15: 2030 | F15: 2031 | G15: 2032 | H15: 2033 | I15: 2034 | J15: 2035 | K15: 2036 | L15: Terminal
A16: Discount period (years, mid-year) | B16: 0.5 | C16: =B16+1 -> 1.5 | D16: =C16+1 -> 2.5 | E16: =D16+1 -> 3.5 | F16: =E16+1 -> 4.5 | G16: =F16+1 -> 5.5 | H16: =G16+1 -> 6.5 | I16: =H16+1 -> 7.5 | J16: =I16+1 -> 8.5 | K16: =J16+1 -> 9.5
A17: Fade step (years 6 to 10) | B17: 0 | C17: 0 | D17: 0 | E17: 0 | F17: 0 | G17: 1 | H17: 2 | I17: 3 | J17: 4 | K17: 5
A19: Bear: engagement keeps sliding to YouTube and AI video
A20: Revenue | B20: 54 | C20: 56.5 | D20: 59 | E20: 61 | F20: 63 | G20: =F20*(1+$F21+($L21-$F21)*G$17/5) -> 64.967459 | H20: =G20*(1+$F21+($L21-$F21)*H$17/5) -> 66.895182 | I20: =H20*(1+$F21+($L21-$F21)*I$17/5) -> 68.775924 | J20: =I20*(1+$F21+($L21-$F21)*J$17/5) -> 70.602432 | K20: =J20*(1+$F21+($L21-$F21)*K$17/5) -> 72.367492 | L20: =K20*(1+L21) -> 74.17668
A21: Revenue growth (terminal column = terminal growth, input) | B21: =B20/$B$12-1 -> 0.056751468 | C21: =C20/B20-1 -> 0.046296296 | D21: =D20/C20-1 -> 0.044247788 | E21: =E20/D20-1 -> 0.033898305 | F21: =F20/E20-1 -> 0.032786885 | G21: =G20/F20-1 -> 0.031229508 | H21: =H20/G20-1 -> 0.029672131 | I21: =I20/H20-1 -> 0.028114754 | J21: =J20/I20-1 -> 0.026557377 | K21: =K20/J20-1 -> 0.025 | L21: 0.025
A22: Operating margin | B22: 0.3 | C22: 0.3 | D22: 0.3 | E22: 0.3 | F22: 0.3 | G22: =$F22+($L22-$F22)*G$17/5 -> 0.294 | H22: =$F22+($L22-$F22)*H$17/5 -> 0.288 | I22: =$F22+($L22-$F22)*I$17/5 -> 0.282 | J22: =$F22+($L22-$F22)*J$17/5 -> 0.276 | K22: =$F22+($L22-$F22)*K$17/5 -> 0.27 | L22: 0.27
A23: Operating income | B23: =B20*B22 -> 16.2 | C23: =C20*C22 -> 16.95 | D23: =D20*D22 -> 17.7 | E23: =E20*E22 -> 18.3 | F23: =F20*F22 -> 18.9 | G23: =G20*G22 -> 19.100433 | H23: =H20*H22 -> 19.265812 | I23: =I20*I22 -> 19.39481 | ... L23: =L20*L22 -> 20.027704
A24: NOPAT | B24: =B23*(1-$B$9) -> 13.527 | C24: =C23*(1-$B$9) -> 14.15325 | D24: =D23*(1-$B$9) -> 14.7795 | E24: =E23*(1-$B$9) -> 15.2805 | F24: =F23*(1-$B$9) -> 15.7815 | G24: =G23*(1-$B$9) -> 15.948862 | H24: =H23*(1-$B$9) -> 16.086953 | I24: =I23*(1-$B$9) -> 16.194667 | ... L24: =L23*(1-$B$9) -> 16.723132
A25: Net reinvestment, % of revenue | B25: 0.04 | C25: 0.04 | D25: 0.04 | E25: 0.04 | F25: 0.04 | G25: =$F25+($L25-$F25)*G$17/5 -> 0.039 | H25: =$F25+($L25-$F25)*H$17/5 -> 0.038 | I25: =$F25+($L25-$F25)*I$17/5 -> 0.037 | J25: =$F25+($L25-$F25)*J$17/5 -> 0.036 | K25: =$F25+($L25-$F25)*K$17/5 -> 0.035 | L25: 0.035
A26: Net reinvestment | B26: =B20*B25 -> 2.16 | C26: =C20*C25 -> 2.26 | D26: =D20*D25 -> 2.36 | E26: =E20*E25 -> 2.44 | F26: =F20*F25 -> 2.52 | G26: =G20*G25 -> 2.5337309 | H26: =H20*H25 -> 2.5420169 | I26: =I20*I25 -> 2.5447092 | ... L26: =L20*L25 -> 2.5961838
A27: Change in working capital | B27: =$B$11*(B20-$B$12) -> 0 | C27: =$B$11*(C20-B20) -> 0 | D27: =$B$11*(D20-C20) -> 0 | E27: =$B$11*(E20-D20) -> 0 | F27: =$B$11*(F20-E20) -> 0 | G27: =$B$11*(G20-F20) -> 0 | H27: =$B$11*(H20-G20) -> 0 | I27: =$B$11*(I20-H20) -> 0 | J27: =$B$11*(J20-I20) -> 0 | ... L27: =$B$11*(L20-K20) -> 0
A28: Free cash flow | B28: =B24-B26-B27 -> 11.367 | C28: =C24-C26-C27 -> 11.89325 | D28: =D24-D26-D27 -> 12.4195 | E28: =E24-E26-E27 -> 12.8405 | F28: =F24-F26-F27 -> 13.2615 | G28: =G24-G26-G27 -> 13.415131 | H28: =H24-H26-H27 -> 13.544936 | I28: =I24-I26-I27 -> 13.649958 | ... L28: =L24-L26-L27 -> 14.126949
A29: Discount factor | B29: =1/(1+$B$10)^B$16 -> 0.95563697 | C29: =1/(1+$B$10)^C$16 -> 0.87272782 | D29: =1/(1+$B$10)^D$16 -> 0.79701171 | E29: =1/(1+$B$10)^E$16 -> 0.72786458 | F29: =1/(1+$B$10)^F$16 -> 0.66471651 | G29: =1/(1+$B$10)^G$16 -> 0.60704704 | H29: =1/(1+$B$10)^H$16 -> 0.55438086 | I29: =1/(1+$B$10)^I$16 -> 0.50628389 | ... K29: =1/(1+$B$10)^K$16 -> 0.42224631
A30: PV of free cash flow | B30: =B28*B29 -> 10.862725 | C30: =C28*C29 -> 10.37957 | D30: =D28*D29 -> 9.8984869 | E30: =E28*E29 -> 9.3461451 | F30: =F28*F29 -> 8.815138 | G30: =G28*G29 -> 8.1436153 | H30: =H28*H29 -> 7.5090535 | I30: =I28*I29 -> 6.9107536 | ... K30: =K28*K29 -> 5.8195629
A31: Terminal value | B31: =L28/($B$10-L21) -> 201.81355 | C31: =IF($B$10>L21,"","Discount rate must exceed terminal growth")
A32: PV of terminal value | B32: =B31/(1+$B$10)^$K$16 -> 85.215029
A33: Equity value (PV FCF + PV TV + net cash + other) | B33: =SUM(B30:K30)+B32+$B$7+$B$8 -> 162.14798
A34: Value per share ($) | B34: =B33/$B$6 -> 39.490496
A35: Value vs share price | B35: =B34/$B$4-1 -> -0.36835419
A37: Base: growth slows to about 7%, margins edge up
A38: Revenue | B38: 55.5 | C38: 60 | D38: 64.5 | E38: 69 | F38: 73.5 | G38: =F38*(1+$F39+($L39-$F39)*G$17/5) -> 77.849283 | H38: =G38*(1+$F39+($L39-$F39)*H$17/5) -> 81.985449 | I38: =H38*(1+$F39+($L39-$F39)*I$17/5) -> 85.845894 | J38: =I38*(1+$F39+($L39-$F39)*J$17/5) -> 89.369308 | K38: =J38*(1+$F39+($L39-$F39)*K$17/5) -> 92.497234 | L38: =K38*(1+L39) -> 95.734637
A39: Revenue growth (terminal column = terminal growth, input) | B39: =B38/$B$12-1 -> 0.086105675 | C39: =C38/B38-1 -> 0.081081081 | D39: =D38/C38-1 -> 0.075 | E39: =E38/D38-1 -> 0.069767442 | F39: =F38/E38-1 -> 0.065217391 | G39: =G38/F38-1 -> 0.059173913 | H39: =H38/G38-1 -> 0.053130435 | I39: =I38/H38-1 -> 0.047086957 | J39: =J38/I38-1 -> 0.041043478 | K39: =K38/J38-1 -> 0.035 | L39: 0.035
A40: Operating margin | B40: 0.32 | C40: 0.33 | D40: 0.34 | E40: 0.35 | F40: 0.355 | G40: =$F40+($L40-$F40)*G$17/5 -> 0.35 | H40: =$F40+($L40-$F40)*H$17/5 -> 0.345 | I40: =$F40+($L40-$F40)*I$17/5 -> 0.34 | J40: =$F40+($L40-$F40)*J$17/5 -> 0.335 | K40: =$F40+($L40-$F40)*K$17/5 -> 0.33 | L40: 0.33
A41: Operating income | B41: =B38*B40 -> 17.76 | C41: =C38*C40 -> 19.8 | D41: =D38*D40 -> 21.93 | E41: =E38*E40 -> 24.15 | F41: =F38*F40 -> 26.0925 | G41: =G38*G40 -> 27.247249 | H41: =H38*H40 -> 28.28498 | I41: =I38*I40 -> 29.187604 | ... L41: =L38*L40 -> 31.59243
A42: NOPAT | B42: =B41*(1-$B$9) -> 14.8296 | C42: =C41*(1-$B$9) -> 16.533 | D42: =D41*(1-$B$9) -> 18.31155 | E42: =E41*(1-$B$9) -> 20.16525 | F42: =F41*(1-$B$9) -> 21.787237 | G42: =G41*(1-$B$9) -> 22.751453 | H42: =H41*(1-$B$9) -> 23.617958 | I42: =I41*(1-$B$9) -> 24.371649 | ... L42: =L41*(1-$B$9) -> 26.379679
A43: Net reinvestment, % of revenue | B43: 0.04 | C43: 0.04 | D43: 0.04 | E43: 0.04 | F43: 0.04 | G43: =$F43+($L43-$F43)*G$17/5 -> 0.039 | H43: =$F43+($L43-$F43)*H$17/5 -> 0.038 | I43: =$F43+($L43-$F43)*I$17/5 -> 0.037 | J43: =$F43+($L43-$F43)*J$17/5 -> 0.036 | K43: =$F43+($L43-$F43)*K$17/5 -> 0.035 | L43: 0.035
A44: Net reinvestment | B44: =B38*B43 -> 2.22 | C44: =C38*C43 -> 2.4 | D44: =D38*D43 -> 2.58 | E44: =E38*E43 -> 2.76 | F44: =F38*F43 -> 2.94 | G44: =G38*G43 -> 3.036122 | H44: =H38*H43 -> 3.1154471 | I44: =I38*I43 -> 3.1762981 | ... L44: =L38*L43 -> 3.3507123
...

Sheet WACC
A1: Discount rates: calculated (CAPM) versus assumed
A2: Blue = input, black = formula, green = link. The yellow switches set the rate used on the model sheet.
A5: Rate used in valuations (1 = Calculated, 2 = Assumed) | B5: 2 | C5: Switch. 2 reproduces the doc's figures
A6: Beta used (1 = Raw 5-year, 2 = Blume adjusted) | B6: 2 | C6: Blume adjusted = 0.67 x raw + 0.33
A7: Risk-free rate (10-year Treasury) | B7: 0.0531 | C7: FRED via MacroRadar, Oct 6, 2026 (same as earlier journal models)
A8: Equity risk premium | B8: 0.05 | C8: Analyst assumption
A9: Credit spread over risk-free (pre-tax cost of debt) | B9: 0.012 | C9: Analyst assumption: investment-grade spread
A12: Item | B12: NFLX | C12: Source / note
A13: Raw beta (5-year) | B13: 1.61 | C13: Stock Analysis statistics, Oct 23, 2026
A14: Beta override (blank = none) | C14: Cheniere's 0.06 raw beta reflects its own history, not its risk; 0.80 used instead
A15: Adjusted beta | B15: =0.67*IF(ISNUMBER(B14),B14,B13)+0.33 -> 1.4087 | C15: Blume: 0.67 x raw (or override) + 0.33
A16: Beta used | B16: =IF($B$6=1,IF(ISNUMBER(B14),B14,B13),B15) -> 1.4087 | C16: Per switch in B6
A17: Cost of equity | B17: =$B$7+B16*$B$8 -> 0.123535 | C17: Risk-free + beta x ERP
A18: Pre-tax cost of debt | B18: =$B$7+$B$9 -> 0.0651 | C18: Risk-free + spread
A19: Tax rate | B19: =NFLX!B9 -> 0.165 | C19: Linked from company sheet
A20: After-tax cost of debt | B20: =B18*(1-B19) -> 0.0543585
A21: Market value of equity ($B) | B21: =NFLX!B4*NFLX!B6 -> 256.70712 | C21: Price x shares
A22: Debt ($B) | B22: 15.3 | C22: Stock Analysis, total debt
A23: Equity weight | B23: =B21/(B21+B22) -> 0.94375147
A24: Debt weight | B24: =B22/(B21+B22) -> 0.056248528
A25: Calculated WACC (CAPM) | B25: =B23*B17+B24*B20 -> 0.11964392 | C25: Weighted cost of capital
A26: Assumed WACC | B26: 0.095 | C26: Analyst assumption used in the doc
A27: WACC used | B27: =IF($B$5=1,B25,B26) -> 0.095 | C27: Per switch in B5; feeds each sheet's B10
A28: Check: WACC above every terminal growth rate | B28: =IF(B27>MAX(NFLX!L21,NFLX!L39,NFLX!L57),"OK","WACC must exceed growth") -> OK
A29: Link row read by company sheets | B29: =B27 -> 0.095 | C29: Same as WACC used
