Workbook

Sheet Summary
A1: First Solar (FSLR): valuation summary
A2: Values link to the model sheet (green). Switch the discount rate on the WACC tab.
A4: Company | B4: Method | C4: Share price | D4: Discount rate | E4: Bear value | F4: Base value | G4: Bull value | H4: Base vs price | I4: Implied return at price (base case) | J4: Base value (rounded)
A5: First Solar (FSLR) | B5: 10-year DCF | C5: =FSLR!B4 -> 171.57 | D5: =FSLR!B10 -> 0.1022 | E5: =FSLR!B75 -> 73.39468 | F5: =FSLR!B76 -> 128.37795 | G5: =FSLR!B77 -> 193.21628 | H5: =F5/C5-1 -> -0.25174593 | I5: =FSLR!B86 -> 0.075764103 | J5: =IF(F5<10,ROUND(F5*4,0)/4,IF(F5<100,ROUND(F5,0),ROUND(F5/5,0)*5)) -> 130
A8: Exit plan on the positions page
A9: Base value (rounded) | C9: 125
A10: Trim above (bull value, rounded) | C10: 190
A11: Exit below (halfway, bear to base) | C11: 99
A12: Thesis-break signal | C12: Sell if the backlog falls below 35 GW, or if the Section 45X credits change.

Sheet FSLR
A1: First Solar (FSLR): 10-year scenario DCF
A2: Units: $ billions unless noted. Blue = input, black = formula, green = link, yellow = key lever. Years 6 to 10 fade growth, margin and reinvestment toward each scenario's terminal levels.
A4: Share price ($) | B4: 171.57 | C4: Oct 23, 2026 intraday (Yahoo Finance via the site's price feed)
A5: Price date | B5: Oct 23, 2026 | C5: Text
A6: Shares outstanding (billions) | B6: 0.10747 | C6: Stock Analysis statistics, Oct 23, 2026
A7: Net cash, negative = net debt | B7: 1.53 | C7: Stock Analysis statistics, Oct 23, 2026: cash less total debt
A8: Other non-operating assets, less outside claims | B8: 0 | C8: None. Margins include 45X manufacturing credits, which step down from 2030 and end after 2032
A9: Tax rate | B9: 0.12 | C9: Analyst assumption (normalized, near the reported effective rate)
A10: Discount rate (WACC), from WACC tab | B10: =WACC!B29 -> 0.1022 | C10: Calculated or assumed, per the switch in WACC!B5
A11: Working capital, % of revenue change | B11: 0.1 | C11: Analyst assumption
A12: Base-year revenue (2026E) | B12: 5.04 | C12: 2026E consensus $5.04B (Stock Analysis)
A13: Selected scenario (1 Bear, 2 Base, 3 Bull) | B13: 2 | C13: Lever
A15: Year | B15: 2027 | C15: 2028 | D15: 2029 | E15: 2030 | F15: 2031 | G15: 2032 | H15: 2033 | I15: 2034 | J15: 2035 | K15: 2036 | L15: Terminal
A16: Discount period (years, mid-year) | B16: 0.5 | C16: =B16+1 -> 1.5 | D16: =C16+1 -> 2.5 | E16: =D16+1 -> 3.5 | F16: =E16+1 -> 4.5 | G16: =F16+1 -> 5.5 | H16: =G16+1 -> 6.5 | I16: =H16+1 -> 7.5 | J16: =I16+1 -> 8.5 | K16: =J16+1 -> 9.5
A17: Fade step (years 6 to 10) | B17: 0 | C17: 0 | D17: 0 | E17: 0 | F17: 0 | G17: 1 | H17: 2 | I17: 3 | J17: 4 | K17: 5
A19: Bear: module prices fall, policy turns against solar
A20: Revenue | B20: 5 | C20: 5.3 | D20: 5.6 | E20: 5.6 | F20: 5.6 | G20: =F20*(1+$F21+($L21-$F21)*G$17/5) -> 5.6224 | H20: =G20*(1+$F21+($L21-$F21)*H$17/5) -> 5.6673792 | I20: =H20*(1+$F21+($L21-$F21)*I$17/5) -> 5.7353878 | J20: =I20*(1+$F21+($L21-$F21)*J$17/5) -> 5.827154 | K20: =J20*(1+$F21+($L21-$F21)*K$17/5) -> 5.943697 | L20: =K20*(1+L21) -> 6.062571
A21: Revenue growth (terminal column = terminal growth, input) | B21: =B20/$B$12-1 -> -0.0079365079 | C21: =C20/B20-1 -> 0.06 | D21: =D20/C20-1 -> 0.056603774 | E21: =E20/D20-1 -> 0 | F21: =F20/E20-1 -> 0 | G21: =G20/F20-1 -> 0.004 | H21: =H20/G20-1 -> 0.008 | I21: =I20/H20-1 -> 0.012 | J21: =J20/I20-1 -> 0.016 | K21: =K20/J20-1 -> 0.02 | L21: 0.02
A22: Operating margin | B22: 0.28 | C22: 0.27 | D22: 0.27 | E22: 0.2 | F22: 0.15 | G22: =$F22+($L22-$F22)*G$17/5 -> 0.14 | H22: =$F22+($L22-$F22)*H$17/5 -> 0.13 | I22: =$F22+($L22-$F22)*I$17/5 -> 0.12 | J22: =$F22+($L22-$F22)*J$17/5 -> 0.11 | K22: =$F22+($L22-$F22)*K$17/5 -> 0.1 | L22: 0.1
A23: Operating income | B23: =B20*B22 -> 1.4 | C23: =C20*C22 -> 1.431 | D23: =D20*D22 -> 1.512 | E23: =E20*E22 -> 1.12 | F23: =F20*F22 -> 0.84 | G23: =G20*G22 -> 0.787136 | H23: =H20*H22 -> 0.7367593 | I23: =I20*I22 -> 0.68824653 | ... L23: =L20*L22 -> 0.6062571
A24: NOPAT | B24: =B23*(1-$B$9) -> 1.232 | C24: =C23*(1-$B$9) -> 1.25928 | D24: =D23*(1-$B$9) -> 1.33056 | E24: =E23*(1-$B$9) -> 0.9856 | F24: =F23*(1-$B$9) -> 0.7392 | G24: =G23*(1-$B$9) -> 0.69267968 | H24: =H23*(1-$B$9) -> 0.64834818 | I24: =I23*(1-$B$9) -> 0.60565695 | ... L24: =L23*(1-$B$9) -> 0.53350625
A25: Net reinvestment, % of revenue | B25: 0.05 | C25: 0.04 | D25: 0.03 | E25: 0.03 | F25: 0.03 | G25: =$F25+($L25-$F25)*G$17/5 -> 0.03 | H25: =$F25+($L25-$F25)*H$17/5 -> 0.03 | I25: =$F25+($L25-$F25)*I$17/5 -> 0.03 | J25: =$F25+($L25-$F25)*J$17/5 -> 0.03 | K25: =$F25+($L25-$F25)*K$17/5 -> 0.03 | L25: 0.03
A26: Net reinvestment | B26: =B20*B25 -> 0.25 | C26: =C20*C25 -> 0.212 | D26: =D20*D25 -> 0.168 | E26: =E20*E25 -> 0.168 | F26: =F20*F25 -> 0.168 | G26: =G20*G25 -> 0.168672 | H26: =H20*H25 -> 0.17002138 | I26: =I20*I25 -> 0.17206163 | ... L26: =L20*L25 -> 0.18187713
A27: Change in working capital | B27: =$B$11*(B20-$B$12) -> -0.004 | C27: =$B$11*(C20-B20) -> 0.03 | D27: =$B$11*(D20-C20) -> 0.03 | E27: =$B$11*(E20-D20) -> 0 | F27: =$B$11*(F20-E20) -> 0 | G27: =$B$11*(G20-F20) -> 0.00224 | H27: =$B$11*(H20-G20) -> 0.00449792 | I27: =$B$11*(I20-H20) -> 0.006800855 | J27: =$B$11*(J20-I20) -> 0.0091766204 | ... L27: =$B$11*(L20-K20) -> 0.011887394
A28: Free cash flow | B28: =B24-B26-B27 -> 0.986 | C28: =C24-C26-C27 -> 1.01728 | D28: =D24-D26-D27 -> 1.13256 | E28: =E24-E26-E27 -> 0.8176 | F28: =F24-F26-F27 -> 0.5712 | G28: =G24-G26-G27 -> 0.52176768 | H28: =H24-H26-H27 -> 0.47382888 | I28: =I24-I26-I27 -> 0.42679446 | ... L28: =L24-L26-L27 -> 0.33974172
A29: Discount factor | B29: =1/(1+$B$10)^B$16 -> 0.95251055 | C29: =1/(1+$B$10)^C$16 -> 0.86419031 | D29: =1/(1+$B$10)^D$16 -> 0.78405943 | E29: =1/(1+$B$10)^E$16 -> 0.71135858 | F29: =1/(1+$B$10)^F$16 -> 0.64539882 | G29: =1/(1+$B$10)^G$16 -> 0.58555509 | H29: =1/(1+$B$10)^H$16 -> 0.53126029 | I29: =1/(1+$B$10)^I$16 -> 0.4819999 | ... K29: =1/(1+$B$10)^K$16 -> 0.39675841
A30: PV of free cash flow | B30: =B28*B29 -> 0.93917541 | C30: =C28*C29 -> 0.87912351 | D30: =D28*D29 -> 0.88799435 | E30: =E28*E29 -> 0.58160678 | F30: =F28*F29 -> 0.36865181 | G30: =G28*G29 -> 0.30552372 | H30: =H28*H29 -> 0.25172647 | I30: =I28*I29 -> 0.20571489 | ... K30: =K28*K29 -> 0.13215234
A31: Terminal value | B31: =L28/($B$10-L21) -> 4.133111 | C31: =IF($B$10>L21,"","Discount rate must exceed terminal growth")
A32: PV of terminal value | B32: =B31/(1+$B$10)^$K$16 -> 1.6398465
A33: Equity value (PV FCF + PV TV + net cash + other) | B33: =SUM(B30:K30)+B32+$B$7+$B$8 -> 7.8877263
A34: Value per share ($) | B34: =B33/$B$6 -> 73.39468
A35: Value vs share price | B35: =B34/$B$4-1 -> -0.57221729
A37: Base: US capacity fills, credits step down
A38: Revenue | B38: 5.8 | C38: 6.4 | D38: 6.8 | E38: 6.9 | F38: 7 | G38: =F38*(1+$F39+($L39-$F39)*G$17/5) -> 7.1161594 | H38: =G38*(1+$F39+($L39-$F39)*H$17/5) -> 7.2492007 | I38: =H38*(1+$F39+($L39-$F39)*I$17/5) -> 7.399963 | J38: =I38*(1+$F39+($L39-$F39)*J$17/5) -> 7.5694115 | K38: =J38*(1+$F39+($L39-$F39)*K$17/5) -> 7.7586467 | L38: =K38*(1+L39) -> 7.9526129
A39: Revenue growth (terminal column = terminal growth, input) | B39: =B38/$B$12-1 -> 0.15079365 | C39: =C38/B38-1 -> 0.10344828 | D39: =D38/C38-1 -> 0.0625 | E39: =E38/D38-1 -> 0.014705882 | F39: =F38/E38-1 -> 0.014492754 | G39: =G38/F38-1 -> 0.016594203 | H39: =H38/G38-1 -> 0.018695652 | I39: =I38/H38-1 -> 0.020797101 | J39: =J38/I38-1 -> 0.022898551 | K39: =K38/J38-1 -> 0.025 | L39: 0.025
A40: Operating margin | B40: 0.33 | C40: 0.34 | D40: 0.34 | E40: 0.29 | F40: 0.24 | G40: =$F40+($L40-$F40)*G$17/5 -> 0.222 | H40: =$F40+($L40-$F40)*H$17/5 -> 0.204 | I40: =$F40+($L40-$F40)*I$17/5 -> 0.186 | J40: =$F40+($L40-$F40)*J$17/5 -> 0.168 | K40: =$F40+($L40-$F40)*K$17/5 -> 0.15 | L40: 0.15
A41: Operating income | B41: =B38*B40 -> 1.914 | C41: =C38*C40 -> 2.176 | D41: =D38*D40 -> 2.312 | E41: =E38*E40 -> 2.001 | F41: =F38*F40 -> 1.68 | G41: =G38*G40 -> 1.5797874 | H41: =H38*H40 -> 1.4788369 | I41: =I38*I40 -> 1.3763931 | ... L41: =L38*L40 -> 1.1928919
A42: NOPAT | B42: =B41*(1-$B$9) -> 1.68432 | C42: =C41*(1-$B$9) -> 1.91488 | D42: =D41*(1-$B$9) -> 2.03456 | E42: =E41*(1-$B$9) -> 1.76088 | F42: =F41*(1-$B$9) -> 1.4784 | G42: =G41*(1-$B$9) -> 1.3902129 | H42: =H41*(1-$B$9) -> 1.3013765 | I42: =I41*(1-$B$9) -> 1.2112259 | ... L42: =L41*(1-$B$9) -> 1.0497449
A43: Net reinvestment, % of revenue | B43: 0.06 | C43: 0.05 | D43: 0.04 | E43: 0.03 | F43: 0.03 | G43: =$F43+($L43-$F43)*G$17/5 -> 0.03 | H43: =$F43+($L43-$F43)*H$17/5 -> 0.03 | I43: =$F43+($L43-$F43)*I$17/5 -> 0.03 | J43: =$F43+($L43-$F43)*J$17/5 -> 0.03 | K43: =$F43+($L43-$F43)*K$17/5 -> 0.03 | L43: 0.03
A44: Net reinvestment | B44: =B38*B43 -> 0.348 | C44: =C38*C43 -> 0.32 | D44: =D38*D43 -> 0.272 | E44: =E38*E43 -> 0.207 | F44: =F38*F43 -> 0.21 | G44: =G38*G43 -> 0.21348478 | H44: =H38*H43 -> 0.21747602 | I44: =I38*I43 -> 0.22199889 | ... L44: =L38*L43 -> 0.23857839
...

Sheet WACC
A1: Discount rates: calculated (CAPM) versus assumed
A2: Blue = input, black = formula, green = link. The yellow switches set the rate used on the model sheet.
A5: Rate used in valuations (1 = Calculated, 2 = Assumed) | B5: 2 | C5: Switch. 2 reproduces the doc's figures
A6: Beta used (1 = Raw 5-year, 2 = Blume adjusted) | B6: 2 | C6: Blume adjusted = 0.67 x raw + 0.33
A7: Risk-free rate (10-year Treasury) | B7: 0.0503 | C7: 10-year Treasury yield at the close on 2026-10-28; assumed rates below move with it
A8: Equity risk premium | B8: 0.05 | C8: Analyst assumption
A9: Credit spread over risk-free (pre-tax cost of debt) | B9: 0.012 | C9: Analyst assumption: investment-grade spread
A12: Item | B12: FSLR | C12: Source / note
A13: Raw beta (5-year) | B13: 1.79 | C13: Stock Analysis statistics, Oct 23, 2026
A14: Beta override (blank = none) | C14: Cheniere's 0.06 raw beta reflects its own history, not its risk; 0.80 used instead
A15: Adjusted beta | B15: =0.67*IF(ISNUMBER(B14),B14,B13)+0.33 -> 1.5293 | C15: Blume: 0.67 x raw (or override) + 0.33
A16: Beta used | B16: =IF($B$6=1,IF(ISNUMBER(B14),B14,B13),B15) -> 1.5293 | C16: Per switch in B6
A17: Cost of equity | B17: =$B$7+B16*$B$8 -> 0.126765 | C17: Risk-free + beta x ERP
A18: Pre-tax cost of debt | B18: =$B$7+$B$9 -> 0.0623 | C18: Risk-free + spread
A19: Tax rate | B19: =FSLR!B9 -> 0.12 | C19: Linked from company sheet
A20: After-tax cost of debt | B20: =B18*(1-B19) -> 0.054824
A21: Market value of equity ($B) | B21: =FSLR!B4*FSLR!B6 -> 18.438628 | C21: Price x shares
A22: Debt ($B) | B22: 0.194 | C22: Stock Analysis, total debt
A23: Equity weight | B23: =B21/(B21+B22) -> 0.98958816
A24: Debt weight | B24: =B22/(B21+B22) -> 0.010411843
A25: Calculated WACC (CAPM) | B25: =B23*B17+B24*B20 -> 0.12601596 | C25: Weighted cost of capital
A26: Assumed WACC | B26: 0.1022 | C26: Analyst assumption used in the doc
A27: WACC used | B27: =IF($B$5=1,B25,B26) -> 0.1022 | C27: Per switch in B5; feeds each sheet's B10
A28: Check: WACC above every terminal growth rate | B28: =IF(B27>MAX(FSLR!L21,FSLR!L39,FSLR!L57),"OK","WACC must exceed growth") -> OK
A29: Link row read by company sheets | B29: =B27 -> 0.1022 | C29: Same as WACC used
