Workbook

Sheet Summary
A1: JPMorgan Chase (JPM): valuation summary
A2: Values link to the model sheet (green). Switch the discount rate on the WACC tab.
A4: Company | B4: Method | C4: Share price | D4: Discount rate | E4: Bear value | F4: Base value | G4: Bull value | H4: Base vs price | I4: Implied return at price (base case) | J4: Base value (rounded)
A5: JPMorgan Chase (JPM) | B5: Residual income | C5: =JPM!B4 -> 332.07 | D5: =JPM!B8 -> 0.1 | E5: =JPM!B53 -> 191.75064 | F5: =JPM!B54 -> 258.747 | G5: =JPM!B55 -> 315.09112 | H5: =F5/C5-1 -> -0.22080585 | I5: =JPM!B65 -> 0.088038318 | J5: =IF(F5<10,ROUND(F5*4,0)/4,IF(F5<100,ROUND(F5,0),ROUND(F5/5,0)*5)) -> 260
A8: Exit plan on the positions page
A9: Base value (rounded) | C9: 260
A10: Trim above (bull value, rounded) | C10: 315
A11: Exit below (halfway, bear to base) | C11: 225
A12: Thesis-break signal | C12: Sell if return on tangible equity falls below 15%, or if net charge-offs rise quickly.
A13: Levels follow the rules on the positions page and are reset when the model changes.
A15: Notes
A16: Base value is what the business is worth if the base case plays out and you want to earn the discount rate. Implied return is what the base case earns at today's price.
A17: DCF: five explicit years, then five years fading growth, margin and reinvestment to terminal levels. FCF = operating income x (1 - tax) - net reinvestment - working capital x revenue change. Mid-year discounting from October 2026.
A18: Margins are after stock-based pay. For ServiceNow that is about 19% today, not the 31.5% non-GAAP figure, which is the main reason its value is lower than a multiple of adjusted earnings suggests.
A19: Banks: tangible book plus the present value of returns above the cost of equity (residual income). TMC: probability-weighted, from the company's 2025 study with analyst haircuts.
A20: Discount rates use a 5.31% risk-free rate and a 5% equity risk premium, the same as the earlier journal models. At these rates most quality stocks look fully priced; the implied return column shows by how much.
A21: Price and data dates are on the model sheet. Company data: Stock Analysis, company filings and releases. Research for my own records, not investment advice.

Sheet JPM
A1: JPMorgan Chase (JPM): residual income valuation
A2: Per-share values. A bank is worth its tangible book plus the present value of future returns above its cost of equity. Years 6 to 10 fade ROTCE to the terminal level.
A4: Share price ($) | B4: 332.07 | C4: Oct 23, 2026 intraday (Yahoo Finance via the site's price feed)
A5: Price date | B5: Oct 23, 2026 | C5: Text
A6: Tangible book value per share, today ($) | B6: 109.96 | C6: Price / P/TBV 3.02 (Stock Analysis, Oct 23, 2026); BVPS $132.30
A7: Payout ratio (dividends plus buybacks) | B7: 0.6 | C7: Analyst assumption
A8: Cost of equity, from WACC tab | B8: =WACC!B40 -> 0.1 | C8: Calculated or assumed, per the switch in WACC!B5
A9: Selected scenario (1 Bear, 2 Base, 3 Bull) | B9: 2 | C9: Lever
A11: Year | B11: 2027 | C11: 2028 | D11: 2029 | E11: 2030 | F11: 2031 | G11: 2032 | H11: 2033 | I11: 2034 | J11: 2035 | K11: 2036 | L11: Terminal
A12: Discount period (years) | B12: 1 | C12: 2 | D12: 3 | E12: 4 | F12: 5 | G12: 6 | H12: 7 | I12: 8 | J12: 9 | K12: 10
A13: Fade step (years 6 to 10) | B13: 0 | C13: 0 | D13: 0 | E13: 0 | F13: 0 | G13: 1 | H13: 2 | I13: 3 | J13: 4 | K13: 5
A15: Bear: credit cycle in 2027 to 2028
A16: Return on tangible equity (ROTCE) | B16: 0.17 | C16: 0.13 | D16: 0.12 | E16: 0.14 | F16: 0.15 | G16: =$F16+($L16-$F16)*G$13/5 -> 0.148 | H16: =$F16+($L16-$F16)*H$13/5 -> 0.146 | I16: =$F16+($L16-$F16)*I$13/5 -> 0.144 | J16: =$F16+($L16-$F16)*J$13/5 -> 0.142 | K16: =$F16+($L16-$F16)*K$13/5 -> 0.14 | L16: 0.14
A17: Tangible book, start of year | B17: =$B$6 -> 109.96 | C17: =B17+B19 -> 117.43728 | D17: =C17+C19 -> 123.54402 | E17: =D17+D19 -> 129.47413 | F17: =E17+E19 -> 136.72468 | G17: =F17+F19 -> 144.92816 | H17: =G17+G19 -> 153.50791 | I17: =H17+H19 -> 162.47277 | J17: =I17+I19 -> 171.8312 | ... L17: =K17+K19 -> 191.76033
A18: Earnings | B18: =B16*B17 -> 18.6932 | C18: =C16*C17 -> 15.266846 | D18: =D16*D17 -> 14.825282 | E18: =E16*E17 -> 18.126378 | F18: =F16*F17 -> 20.508702 | G18: =G16*G17 -> 21.449368 | H18: =H16*H17 -> 22.412155 | I18: =I16*I17 -> 23.396079 | ... K18: =K16*K17 -> 25.42277
A19: Retained earnings | B19: =B18*(1-$B$7) -> 7.47728 | C19: =C18*(1-$B$7) -> 6.1067386 | D19: =D18*(1-$B$7) -> 5.9301129 | E19: =E18*(1-$B$7) -> 7.2505514 | F19: =F18*(1-$B$7) -> 8.203481 | G19: =G18*(1-$B$7) -> 8.5797473 | H19: =H18*(1-$B$7) -> 8.964862 | I19: =I18*(1-$B$7) -> 9.3584317 | ... K19: =K18*(1-$B$7) -> 10.169108
A20: Residual income (ROTCE less cost of equity) x book | B20: =(B16-$B$8)*B17 -> 7.6972 | C20: =(C16-$B$8)*C17 -> 3.5231184 | D20: =(D16-$B$8)*D17 -> 2.4708804 | E20: =(E16-$B$8)*E17 -> 5.1789653 | F20: =(F16-$B$8)*F17 -> 6.8362341 | G20: =(G16-$B$8)*G17 -> 6.9565519 | H20: =(H16-$B$8)*H17 -> 7.0613639 | I20: =(I16-$B$8)*I17 -> 7.148802 | ... L20: =(L16-$B$8)*L17 -> 7.670413
A21: Discount factor | B21: =1/(1+$B$8)^B$12 -> 0.90909091 | C21: =1/(1+$B$8)^C$12 -> 0.82644628 | D21: =1/(1+$B$8)^D$12 -> 0.7513148 | E21: =1/(1+$B$8)^E$12 -> 0.68301346 | F21: =1/(1+$B$8)^F$12 -> 0.62092132 | G21: =1/(1+$B$8)^G$12 -> 0.56447393 | H21: =1/(1+$B$8)^H$12 -> 0.51315812 | I21: =1/(1+$B$8)^I$12 -> 0.46650738 | ... K21: =1/(1+$B$8)^K$12 -> 0.38554329
A22: PV of residual income | B22: =B20*B21 -> 6.9974545 | C22: =C20*C21 -> 2.9116681 | D22: =D20*D21 -> 1.856409 | E22: =E20*E21 -> 3.537303 | F22: =F20*F21 -> 4.2447635 | G22: =G20*G21 -> 3.9267922 | H22: =H20*H21 -> 3.6235962 | I22: =I20*I21 -> 3.3349689 | ... K22: =K20*K21 -> 2.800451
A23: Terminal growth (input) | B23: 0.035
A24: PV of terminal residual income | B24: =L20/($B$8-B23)/(1+$B$8)^$K$12 -> 45.496558
A25: Value per share (book + PV residual income) | B25: =$B$6+SUM(B22:K22)+B24 -> 191.75064
A26: Value vs share price | B26: =B25/$B$4-1 -> -0.42255958
A27: Base: ROTCE eases from 20% to 16%
A28: Return on tangible equity (ROTCE) | B28: 0.2 | C28: 0.19 | D28: 0.18 | E28: 0.17 | F28: 0.17 | G28: =$F28+($L28-$F28)*G$13/5 -> 0.168 | H28: =$F28+($L28-$F28)*H$13/5 -> 0.166 | I28: =$F28+($L28-$F28)*I$13/5 -> 0.164 | J28: =$F28+($L28-$F28)*J$13/5 -> 0.162 | K28: =$F28+($L28-$F28)*K$13/5 -> 0.16 | L28: 0.16
A29: Tangible book, start of year | B29: =$B$6 -> 109.96 | C29: =B29+B31 -> 118.7568 | D29: =C29+C31 -> 127.78232 | E29: =D29+D31 -> 136.98264 | F29: =E29+E31 -> 146.29746 | G29: =F29+F31 -> 156.24569 | H29: =G29+G31 -> 166.7454 | I29: =H29+H31 -> 177.8173 | J29: =I29+I31 -> 189.48211 | ... L29: =K29+K31 -> 214.67323
A30: Earnings | B30: =B28*B29 -> 21.992 | C30: =C28*C29 -> 22.563792 | D30: =D28*D29 -> 23.000817 | E30: =E28*E29 -> 23.287049 | F30: =F28*F29 -> 24.870569 | G30: =G28*G29 -> 26.249276 | H30: =H28*H29 -> 27.679737 | I30: =I28*I29 -> 29.162037 | ... K30: =K28*K29 -> 32.281688
A31: Retained earnings | B31: =B30*(1-$B$7) -> 8.7968 | C31: =C30*(1-$B$7) -> 9.0255168 | D31: =D30*(1-$B$7) -> 9.2003268 | E31: =E30*(1-$B$7) -> 9.3148198 | F31: =F30*(1-$B$7) -> 9.9482275 | G31: =G30*(1-$B$7) -> 10.49971 | H31: =H30*(1-$B$7) -> 11.071895 | I31: =I30*(1-$B$7) -> 11.664815 | ... K31: =K30*(1-$B$7) -> 12.912675
A32: Residual income (ROTCE less cost of equity) x book | B32: =(B28-$B$8)*B29 -> 10.996 | C32: =(C28-$B$8)*C29 -> 10.688112 | D32: =(D28-$B$8)*D29 -> 10.222585 | E32: =(E28-$B$8)*E29 -> 9.5887851 | F32: =(F28-$B$8)*F29 -> 10.240822 | G32: =(G28-$B$8)*G29 -> 10.624707 | H32: =(H28-$B$8)*H29 -> 11.005196 | I32: =(I28-$B$8)*I29 -> 11.380307 | ... L32: =(L28-$B$8)*L29 -> 12.880394
A33: Discount factor | B33: =1/(1+$B$8)^B$12 -> 0.90909091 | C33: =1/(1+$B$8)^C$12 -> 0.82644628 | D33: =1/(1+$B$8)^D$12 -> 0.7513148 | E33: =1/(1+$B$8)^E$12 -> 0.68301346 | F33: =1/(1+$B$8)^F$12 -> 0.62092132 | G33: =1/(1+$B$8)^G$12 -> 0.56447393 | H33: =1/(1+$B$8)^H$12 -> 0.51315812 | I33: =1/(1+$B$8)^I$12 -> 0.46650738 | ... K33: =1/(1+$B$8)^K$12 -> 0.38554329
A34: PV of residual income | B34: =B32*B33 -> 9.9963636 | C34: =C32*C33 -> 8.8331504 | D34: =D32*D33 -> 7.6803797 | E34: =E32*E33 -> 6.5492692 | F34: =F32*F33 -> 6.358745 | G34: =G32*G33 -> 5.9973701 | H34: =H32*H33 -> 5.6474059 | I34: =I32*I33 -> 5.3089972 | ... K34: =K32*K33 -> 4.6672456
A35: Terminal growth (input) | B35: 0.04
A36: PV of terminal residual income | B36: =L32/($B$8-B35)/(1+$B$8)^$K$12 -> 82.765822
A37: Value per share (book + PV residual income) | B37: =$B$6+SUM(B34:K34)+B36 -> 258.747
A38: Value vs share price | B38: =B37/$B$4-1 -> -0.22080585
A39: Bull: ROTCE stays near 20%
A40: Return on tangible equity (ROTCE) | B40: 0.21 | C40: 0.21 | D40: 0.2 | E40: 0.2 | F40: 0.19 | G40: =$F40+($L40-$F40)*G$13/5 -> 0.188 | H40: =$F40+($L40-$F40)*H$13/5 -> 0.186 | I40: =$F40+($L40-$F40)*I$13/5 -> 0.184 | J40: =$F40+($L40-$F40)*J$13/5 -> 0.182 | K40: =$F40+($L40-$F40)*K$13/5 -> 0.18 | L40: 0.18
A41: Tangible book, start of year | B41: =$B$6 -> 109.96 | C41: =B41+B43 -> 119.19664 | D41: =C41+C43 -> 129.20916 | E41: =D41+D43 -> 139.54589 | F41: =E41+E43 -> 150.70956 | G41: =F41+F43 -> 162.16349 | H41: =G41+G43 -> 174.35818 | I41: =H41+H43 -> 187.33043 | J41: =I41+I43 -> 201.11795 | ... L41: =K41+K43 -> 231.29401
A42: Earnings | B42: =B40*B41 -> 23.0916 | C42: =C40*C41 -> 25.031294 | D42: =D40*D41 -> 25.841832 | E42: =E40*E41 -> 27.909178 | F42: =F40*F41 -> 28.634817 | G42: =G40*G41 -> 30.486736 | H42: =H40*H41 -> 32.430622 | I42: =I40*I41 -> 34.468799 | ... K42: =K40*K41 -> 38.836681
A43: Retained earnings | B43: =B42*(1-$B$7) -> 9.23664 | C43: =C42*(1-$B$7) -> 10.012518 | D43: =D42*(1-$B$7) -> 10.336733 | E43: =E42*(1-$B$7) -> 11.163671 | F43: =F42*(1-$B$7) -> 11.453927 | G43: =G42*(1-$B$7) -> 12.194694 | H43: =H42*(1-$B$7) -> 12.972249 | I43: =I42*(1-$B$7) -> 13.78752 | ... K43: =K42*(1-$B$7) -> 15.534672
...

Sheet WACC
A1: Discount rates: calculated (CAPM) versus assumed
A2: Blue = input, black = formula, green = link. The yellow switches set the rate used on the model sheet. Banks use cost of equity only.
A5: Rate used in valuations (1 = Calculated, 2 = Assumed) | B5: 2 | C5: Switch. 2 reproduces the doc's figures
A6: Beta used (1 = Raw 5-year, 2 = Blume adjusted) | B6: 2 | C6: Blume adjusted = 0.67 x raw + 0.33
A7: Risk-free rate (10-year Treasury) | B7: 0.0531 | C7: FRED via MacroRadar, Oct 6, 2026 (same as earlier journal models)
A8: Equity risk premium | B8: 0.05 | C8: Analyst assumption
A9: Credit spread over risk-free (pre-tax cost of debt) | B9: 0.012 | C9: Analyst assumption: investment-grade spread
A33: Bank cost of equity | B33: JPM | C33: Source / note
A34: Raw beta (5-year) | B34: 1.02 | C34: Stock Analysis statistics, Oct 23, 2026
A35: Adjusted beta | B35: =0.67*B34+0.33 -> 1.0134 | C35: Blume
A36: Beta used | B36: =IF($B$6=1,B34,B35) -> 1.0134 | C36: Per switch in B6
A37: Calculated cost of equity (CAPM) | B37: =$B$7+B36*$B$8 -> 0.10377 | C37: Risk-free + beta x ERP
A38: Assumed cost of equity | B38: 0.1 | C38: Analyst assumption used in the doc
A39: Cost of equity used | B39: =IF($B$5=1,B37,B38) -> 0.1 | C39: Per switch in B5
A40: Link row read by bank sheets | B40: =B39 -> 0.1
