Workbook

Sheet Summary
A1: Coca-Cola (KO): valuation summary
A2: Values link to the model sheet (green). Switch the discount rate on the WACC tab.
A4: Company | B4: Method | C4: Share price | D4: Discount rate | E4: Bear value | F4: Base value | G4: Bull value | H4: Base vs price | I4: Implied return at price (base case) | J4: Base value (rounded)
A5: Coca-Cola (KO) | B5: 10-year DCF | C5: =KO!B4 -> 93.27 | D5: =KO!B10 -> 0.0722 | E5: =KO!B75 -> 56.741673 | F5: =KO!B76 -> 76.815039 | G5: =KO!B77 -> 99.394133 | H5: =F5/C5-1 -> -0.17642287 | I5: =KO!B86 -> 0.065520945 | J5: =IF(F5<10,ROUND(F5*4,0)/4,IF(F5<100,ROUND(F5,0),ROUND(F5/5,0)*5)) -> 77
A8: Exit plan on the positions page
A9: Base value (rounded) | C9: 72
A10: Trim above (bull value, rounded) | C10: 92
A11: Exit below (halfway, bear to base) | C11: 63
A12: Thesis-break signal | C12: Sell if organic growth is below 3% for two quarters in a row, or if North American volumes decline.

Sheet KO
A1: Coca-Cola (KO): 10-year scenario DCF
A2: Units: $ billions unless noted. Blue = input, black = formula, green = link, yellow = key lever. Years 6 to 10 fade growth, margin and reinvestment toward each scenario's terminal levels.
A4: Share price ($) | B4: 93.27 | C4: Oct 23, 2026 intraday (Yahoo Finance via the site's price feed)
A5: Price date | B5: Oct 23, 2026 | C5: Text
A6: Shares outstanding (billions) | B6: 4.3 | C6: Stock Analysis statistics, Oct 23, 2026
A7: Net cash, negative = net debt | B7: -27.89 | C7: Stock Analysis statistics, Oct 23, 2026: cash less total debt
A8: Other non-operating assets, less outside claims | B8: 20.78 | C8: Equity-method investments (bottlers) at book, $20.78B (10-Q, Jul 3, 2026); fair value likely higher
A9: Tax rate | B9: 0.19 | C9: Analyst assumption (normalized, near the reported effective rate)
A10: Discount rate (WACC), from WACC tab | B10: =WACC!B29 -> 0.0722 | C10: Calculated or assumed, per the switch in WACC!B5
A11: Working capital, % of revenue change | B11: 0 | C11: Analyst assumption
A12: Base-year revenue (2026E) | B12: 49.8 | C12: 2026E consensus $49.8B (Stock Analysis)
A13: Selected scenario (1 Bear, 2 Base, 3 Bull) | B13: 2 | C13: Lever
A15: Year | B15: 2027 | C15: 2028 | D15: 2029 | E15: 2030 | F15: 2031 | G15: 2032 | H15: 2033 | I15: 2034 | J15: 2035 | K15: 2036 | L15: Terminal
A16: Discount period (years, mid-year) | B16: 0.5 | C16: =B16+1 -> 1.5 | D16: =C16+1 -> 2.5 | E16: =D16+1 -> 3.5 | F16: =E16+1 -> 4.5 | G16: =F16+1 -> 5.5 | H16: =G16+1 -> 6.5 | I16: =H16+1 -> 7.5 | J16: =I16+1 -> 8.5 | K16: =J16+1 -> 9.5
A17: Fade step (years 6 to 10) | B17: 0 | C17: 0 | D17: 0 | E17: 0 | F17: 0 | G17: 1 | H17: 2 | I17: 3 | J17: 4 | K17: 5
A19: Bear: volumes stall, currency drag
A20: Revenue | B20: 51 | C20: 52.3 | D20: 53.6 | E20: 54.9 | F20: 56.2 | G20: =F20*(1+$F21+($L21-$F21)*G$17/5) -> 57.545627 | H20: =G20*(1+$F21+($L21-$F21)*H$17/5) -> 58.938671 | I20: =H20*(1+$F21+($L21-$F21)*I$17/5) -> 60.381004 | J20: =I20*(1+$F21+($L21-$F21)*J$17/5) -> 61.874582 | K20: =J20*(1+$F21+($L21-$F21)*K$17/5) -> 63.421446 | L20: =K20*(1+L21) -> 65.006983
A21: Revenue growth (terminal column = terminal growth, input) | B21: =B20/$B$12-1 -> 0.024096386 | C21: =C20/B20-1 -> 0.025490196 | D21: =D20/C20-1 -> 0.024856597 | E21: =E20/D20-1 -> 0.024253731 | F21: =F20/E20-1 -> 0.023679417 | G21: =G20/F20-1 -> 0.023943534 | H21: =H20/G20-1 -> 0.02420765 | I21: =I20/H20-1 -> 0.024471767 | J21: =J20/I20-1 -> 0.024735883 | K21: =K20/J20-1 -> 0.025 | L21: 0.025
A22: Operating margin | B22: 0.31 | C22: 0.31 | D22: 0.31 | E22: 0.31 | F22: 0.31 | G22: =$F22+($L22-$F22)*G$17/5 -> 0.308 | H22: =$F22+($L22-$F22)*H$17/5 -> 0.306 | I22: =$F22+($L22-$F22)*I$17/5 -> 0.304 | J22: =$F22+($L22-$F22)*J$17/5 -> 0.302 | K22: =$F22+($L22-$F22)*K$17/5 -> 0.3 | L22: 0.3
A23: Operating income | B23: =B20*B22 -> 15.81 | C23: =C20*C22 -> 16.213 | D23: =D20*D22 -> 16.616 | E23: =E20*E22 -> 17.019 | F23: =F20*F22 -> 17.422 | G23: =G20*G22 -> 17.724053 | H23: =H20*H22 -> 18.035233 | I23: =I20*I22 -> 18.355825 | ... L23: =L20*L22 -> 19.502095
A24: NOPAT | B24: =B23*(1-$B$9) -> 12.8061 | C24: =C23*(1-$B$9) -> 13.13253 | D24: =D23*(1-$B$9) -> 13.45896 | E24: =E23*(1-$B$9) -> 13.78539 | F24: =F23*(1-$B$9) -> 14.11182 | G24: =G23*(1-$B$9) -> 14.356483 | H24: =H23*(1-$B$9) -> 14.608539 | I24: =I23*(1-$B$9) -> 14.868219 | ... L24: =L23*(1-$B$9) -> 15.796697
A25: Net reinvestment, % of revenue | B25: 0.02 | C25: 0.02 | D25: 0.02 | E25: 0.02 | F25: 0.02 | G25: =$F25+($L25-$F25)*G$17/5 -> 0.02 | H25: =$F25+($L25-$F25)*H$17/5 -> 0.02 | I25: =$F25+($L25-$F25)*I$17/5 -> 0.02 | J25: =$F25+($L25-$F25)*J$17/5 -> 0.02 | K25: =$F25+($L25-$F25)*K$17/5 -> 0.02 | L25: 0.02
A26: Net reinvestment | B26: =B20*B25 -> 1.02 | C26: =C20*C25 -> 1.046 | D26: =D20*D25 -> 1.072 | E26: =E20*E25 -> 1.098 | F26: =F20*F25 -> 1.124 | G26: =G20*G25 -> 1.1509125 | H26: =H20*H25 -> 1.1787734 | I26: =I20*I25 -> 1.2076201 | ... L26: =L20*L25 -> 1.3001397
A27: Change in working capital | B27: =$B$11*(B20-$B$12) -> 0 | C27: =$B$11*(C20-B20) -> 0 | D27: =$B$11*(D20-C20) -> 0 | E27: =$B$11*(E20-D20) -> 0 | F27: =$B$11*(F20-E20) -> 0 | G27: =$B$11*(G20-F20) -> 0 | H27: =$B$11*(H20-G20) -> 0 | I27: =$B$11*(I20-H20) -> 0 | J27: =$B$11*(J20-I20) -> 0 | ... L27: =$B$11*(L20-K20) -> 0
A28: Free cash flow | B28: =B24-B26-B27 -> 11.7861 | C28: =C24-C26-C27 -> 12.08653 | D28: =D24-D26-D27 -> 12.38696 | E28: =E24-E26-E27 -> 12.68739 | F28: =F24-F26-F27 -> 12.98782 | G28: =G24-G26-G27 -> 13.20557 | H28: =H24-H26-H27 -> 13.429766 | I28: =I24-I26-I27 -> 13.660598 | ... L28: =L24-L26-L27 -> 14.496557
A29: Discount factor | B29: =1/(1+$B$10)^B$16 -> 0.96574418 | C29: =1/(1+$B$10)^C$16 -> 0.90071272 | D29: =1/(1+$B$10)^D$16 -> 0.84006036 | E29: =1/(1+$B$10)^E$16 -> 0.78349222 | F29: =1/(1+$B$10)^F$16 -> 0.73073328 | G29: =1/(1+$B$10)^G$16 -> 0.68152703 | H29: =1/(1+$B$10)^H$16 -> 0.63563424 | I29: =1/(1+$B$10)^I$16 -> 0.59283178 | ... K29: =1/(1+$B$10)^K$16 -> 0.51567951
A30: PV of free cash flow | B30: =B28*B29 -> 11.382357 | C30: =C28*C29 -> 10.886491 | D30: =D28*D29 -> 10.405794 | E30: =E28*E29 -> 9.9404714 | F30: =F28*F29 -> 9.4906323 | G30: =G28*G29 -> 8.9999531 | H30: =H28*H29 -> 8.5364188 | I30: =I28*I29 -> 8.0984369 | ... K30: =K28*K29 -> 7.2932463
A31: Terminal value | B31: =L28/($B$10-L21) -> 307.13045 | C31: =IF($B$10>L21,"","Discount rate must exceed terminal growth")
A32: PV of terminal value | B32: =B31/(1+$B$10)^$K$16 -> 158.38088
A33: Equity value (PV FCF + PV TV + net cash + other) | B33: =SUM(B30:K30)+B32+$B$7+$B$8 -> 243.98919
A34: Value per share ($) | B34: =B33/$B$6 -> 56.741673
A35: Value vs share price | B35: =B34/$B$4-1 -> -0.39164069
A37: Base: mid-single-digit organic growth
A38: Revenue | B38: 52.3 | C38: 54.9 | D38: 57.6 | E38: 60.3 | F38: 63.1 | G38: =F38*(1+$F39+($L39-$F39)*G$17/5) -> 65.822613 | H38: =G38*(1+$F39+($L39-$F39)*H$17/5) -> 68.446348 | I38: =H38*(1+$F39+($L39-$F39)*I$17/5) -> 70.949691 | J38: =I38*(1+$F39+($L39-$F39)*J$17/5) -> 73.311387 | K38: =J38*(1+$F39+($L39-$F39)*K$17/5) -> 75.510728 | L38: =K38*(1+L39) -> 77.77605
A39: Revenue growth (terminal column = terminal growth, input) | B39: =B38/$B$12-1 -> 0.050200803 | C39: =C38/B38-1 -> 0.049713193 | D39: =D38/C38-1 -> 0.049180328 | E39: =E38/D38-1 -> 0.046875 | F39: =F38/E38-1 -> 0.046434494 | G39: =G38/F38-1 -> 0.043147595 | H39: =H38/G38-1 -> 0.039860697 | I39: =I38/H38-1 -> 0.036573798 | J39: =J38/I38-1 -> 0.033286899 | K39: =K38/J38-1 -> 0.03 | L39: 0.03
A40: Operating margin | B40: 0.32 | C40: 0.325 | D40: 0.33 | E40: 0.33 | F40: 0.33 | G40: =$F40+($L40-$F40)*G$17/5 -> 0.328 | H40: =$F40+($L40-$F40)*H$17/5 -> 0.326 | I40: =$F40+($L40-$F40)*I$17/5 -> 0.324 | J40: =$F40+($L40-$F40)*J$17/5 -> 0.322 | K40: =$F40+($L40-$F40)*K$17/5 -> 0.32 | L40: 0.32
A41: Operating income | B41: =B38*B40 -> 16.736 | C41: =C38*C40 -> 17.8425 | D41: =D38*D40 -> 19.008 | E41: =E38*E40 -> 19.899 | F41: =F38*F40 -> 20.823 | G41: =G38*G40 -> 21.589817 | H41: =H38*H40 -> 22.31351 | I41: =I38*I40 -> 22.9877 | ... L41: =L38*L40 -> 24.888336
A42: NOPAT | B42: =B41*(1-$B$9) -> 13.55616 | C42: =C41*(1-$B$9) -> 14.452425 | D42: =D41*(1-$B$9) -> 15.39648 | E42: =E41*(1-$B$9) -> 16.11819 | F42: =F41*(1-$B$9) -> 16.86663 | G42: =G41*(1-$B$9) -> 17.487752 | H42: =H41*(1-$B$9) -> 18.073943 | I42: =I41*(1-$B$9) -> 18.620037 | ... L42: =L41*(1-$B$9) -> 20.159552
A43: Net reinvestment, % of revenue | B43: 0.02 | C43: 0.02 | D43: 0.02 | E43: 0.02 | F43: 0.02 | G43: =$F43+($L43-$F43)*G$17/5 -> 0.02 | H43: =$F43+($L43-$F43)*H$17/5 -> 0.02 | I43: =$F43+($L43-$F43)*I$17/5 -> 0.02 | J43: =$F43+($L43-$F43)*J$17/5 -> 0.02 | K43: =$F43+($L43-$F43)*K$17/5 -> 0.02 | L43: 0.02
A44: Net reinvestment | B44: =B38*B43 -> 1.046 | C44: =C38*C43 -> 1.098 | D44: =D38*D43 -> 1.152 | E44: =E38*E43 -> 1.206 | F44: =F38*F43 -> 1.262 | G44: =G38*G43 -> 1.3164523 | H44: =H38*H43 -> 1.368927 | I44: =I38*I43 -> 1.4189938 | ... L44: =L38*L43 -> 1.555521
...

Sheet WACC
A1: Discount rates: calculated (CAPM) versus assumed
A2: Blue = input, black = formula, green = link. The yellow switches set the rate used on the model sheet.
A5: Rate used in valuations (1 = Calculated, 2 = Assumed) | B5: 2 | C5: Switch. 2 reproduces the doc's figures
A6: Beta used (1 = Raw 5-year, 2 = Blume adjusted) | B6: 2 | C6: Blume adjusted = 0.67 x raw + 0.33
A7: Risk-free rate (10-year Treasury) | B7: 0.0503 | C7: 10-year Treasury yield at the close on 2026-10-28; assumed rates below move with it
A8: Equity risk premium | B8: 0.05 | C8: Analyst assumption
A9: Credit spread over risk-free (pre-tax cost of debt) | B9: 0.012 | C9: Analyst assumption: investment-grade spread
A12: Item | B12: KO | C12: Source / note
A13: Raw beta (5-year) | B13: 0.32 | C13: Stock Analysis statistics, Oct 23, 2026
A14: Beta override (blank = none) | C14: Cheniere's 0.06 raw beta reflects its own history, not its risk; 0.80 used instead
A15: Adjusted beta | B15: =0.67*IF(ISNUMBER(B14),B14,B13)+0.33 -> 0.5444 | C15: Blume: 0.67 x raw (or override) + 0.33
A16: Beta used | B16: =IF($B$6=1,IF(ISNUMBER(B14),B14,B13),B15) -> 0.5444 | C16: Per switch in B6
A17: Cost of equity | B17: =$B$7+B16*$B$8 -> 0.07752 | C17: Risk-free + beta x ERP
A18: Pre-tax cost of debt | B18: =$B$7+$B$9 -> 0.0623 | C18: Risk-free + spread
A19: Tax rate | B19: =KO!B9 -> 0.19 | C19: Linked from company sheet
A20: After-tax cost of debt | B20: =B18*(1-B19) -> 0.050463
A21: Market value of equity ($B) | B21: =KO!B4*KO!B6 -> 401.061 | C21: Price x shares
A22: Debt ($B) | B22: 44.26 | C22: Stock Analysis, total debt
A23: Equity weight | B23: =B21/(B21+B22) -> 0.90061102
A24: Debt weight | B24: =B22/(B21+B22) -> 0.09938898
A25: Calculated WACC (CAPM) | B25: =B23*B17+B24*B20 -> 0.074830832 | C25: Weighted cost of capital
A26: Assumed WACC | B26: 0.0722 | C26: Analyst assumption used in the doc
A27: WACC used | B27: =IF($B$5=1,B25,B26) -> 0.0722 | C27: Per switch in B5; feeds each sheet's B10
A28: Check: WACC above every terminal growth rate | B28: =IF(B27>MAX(KO!L21,KO!L39,KO!L57),"OK","WACC must exceed growth") -> OK
A29: Link row read by company sheets | B29: =B27 -> 0.0722 | C29: Same as WACC used
