Workbook

Sheet Summary
A1: ServiceNow (NOW): valuation summary
A2: Values link to the model sheet (green). Switch the discount rate on the WACC tab.
A4: Company | B4: Method | C4: Share price | D4: Discount rate | E4: Bear value | F4: Base value | G4: Bull value | H4: Base vs price | I4: Implied return at price (base case) | J4: Base value (rounded)
A5: ServiceNow (NOW) | B5: 10-year DCF | C5: =NOW!B4 -> 156.84 | D5: =NOW!B10 -> 0.095 | E5: =NOW!B75 -> 58.852825 | F5: =NOW!B76 -> 103.66052 | G5: =NOW!B77 -> 151.93398 | H5: =F5/C5-1 -> -0.33906836 | I5: =NOW!B86 -> 0.077975605 | J5: =IF(F5<10,ROUND(F5*4,0)/4,IF(F5<100,ROUND(F5,0),ROUND(F5/5,0)*5)) -> 105
A8: Exit plan on the positions page
A9: Base value (rounded) | C9: 105
A10: Trim above (bull value, rounded) | C10: 150
A11: Exit below (halfway, bear to base) | C11: 81
A12: Thesis-break signal | C12: Sell if subscription revenue or current remaining performance obligations grow less than 15%.

Sheet NOW
A1: ServiceNow (NOW): 10-year scenario DCF
A2: Units: $ billions unless noted. Blue = input, black = formula, green = link, yellow = key lever. Years 6 to 10 fade growth, margin and reinvestment toward each scenario's terminal levels.
A4: Share price ($) | B4: 156.84 | C4: Oct 23, 2026 intraday (Yahoo Finance via the site's price feed)
A5: Price date | B5: Oct 23, 2026 | C5: Text
A6: Shares outstanding (billions) | B6: 1.03 | C6: Stock Analysis statistics, Oct 23, 2026
A7: Net cash, negative = net debt | B7: -1.75 | C7: Stock Analysis statistics, Oct 23, 2026: cash less total debt
A8: Other non-operating assets, less outside claims | B8: 0 | C8: Long-term investments excluded (conservative)
A9: Tax rate | B9: 0.2 | C9: Analyst assumption (normalized, near the reported effective rate)
A10: Discount rate (WACC), from WACC tab | B10: =WACC!B29 -> 0.095 | C10: Calculated or assumed, per the switch in WACC!B5
A11: Working capital, % of revenue change | B11: -0.05 | C11: Analyst assumption
A12: Base-year revenue (2026E) | B12: 16.22 | C12: 2026E consensus $16.22B (Stock Analysis). Margins are after stock pay (GAAP-like), not the 31.5% non-GAAP figure
A13: Selected scenario (1 Bear, 2 Base, 3 Bull) | B13: 2 | C13: Lever
A15: Year | B15: 2027 | C15: 2028 | D15: 2029 | E15: 2030 | F15: 2031 | G15: 2032 | H15: 2033 | I15: 2034 | J15: 2035 | K15: 2036 | L15: Terminal
A16: Discount period (years, mid-year) | B16: 0.5 | C16: =B16+1 -> 1.5 | D16: =C16+1 -> 2.5 | E16: =D16+1 -> 3.5 | F16: =E16+1 -> 4.5 | G16: =F16+1 -> 5.5 | H16: =G16+1 -> 6.5 | I16: =H16+1 -> 7.5 | J16: =I16+1 -> 8.5 | K16: =J16+1 -> 9.5
A17: Fade step (years 6 to 10) | B17: 0 | C17: 0 | D17: 0 | E17: 0 | F17: 0 | G17: 1 | H17: 2 | I17: 3 | J17: 4 | K17: 5
A19: Bear: AI agents compress seat pricing
A20: Revenue | B20: 18.3 | C20: 20.3 | D20: 22.2 | E20: 24 | F20: 25.7 | G20: =F20*(1+$F21+($L21-$F21)*G$17/5) -> 27.336233 | H20: =G20*(1+$F21+($L21-$F21)*H$17/5) -> 28.880731 | I20: =H20*(1+$F21+($L21-$F21)*I$17/5) -> 30.305513 | J20: =I20*(1+$F21+($L21-$F21)*J$17/5) -> 31.583396 | K20: =J20*(1+$F21+($L21-$F21)*K$17/5) -> 32.688815 | L20: =K20*(1+L21) -> 33.832923
A21: Revenue growth (terminal column = terminal growth, input) | B21: =B20/$B$12-1 -> 0.12823674 | C21: =C20/B20-1 -> 0.10928962 | D21: =D20/C20-1 -> 0.093596059 | E21: =E20/D20-1 -> 0.081081081 | F21: =F20/E20-1 -> 0.070833333 | G21: =G20/F20-1 -> 0.063666667 | H21: =H20/G20-1 -> 0.0565 | I21: =I20/H20-1 -> 0.049333333 | J21: =J20/I20-1 -> 0.042166667 | K21: =K20/J20-1 -> 0.035 | L21: 0.035
A22: Operating margin | B22: 0.17 | C22: 0.18 | D22: 0.19 | E22: 0.2 | F22: 0.21 | G22: =$F22+($L22-$F22)*G$17/5 -> 0.214 | H22: =$F22+($L22-$F22)*H$17/5 -> 0.218 | I22: =$F22+($L22-$F22)*I$17/5 -> 0.222 | J22: =$F22+($L22-$F22)*J$17/5 -> 0.226 | K22: =$F22+($L22-$F22)*K$17/5 -> 0.23 | L22: 0.23
A23: Operating income | B23: =B20*B22 -> 3.111 | C23: =C20*C22 -> 3.654 | D23: =D20*D22 -> 4.218 | E23: =E20*E22 -> 4.8 | F23: =F20*F22 -> 5.397 | G23: =G20*G22 -> 5.8499539 | H23: =H20*H22 -> 6.2959993 | I23: =I20*I22 -> 6.7278239 | ... L23: =L20*L22 -> 7.7815723
A24: NOPAT | B24: =B23*(1-$B$9) -> 2.4888 | C24: =C23*(1-$B$9) -> 2.9232 | D24: =D23*(1-$B$9) -> 3.3744 | E24: =E23*(1-$B$9) -> 3.84 | F24: =F23*(1-$B$9) -> 4.3176 | G24: =G23*(1-$B$9) -> 4.6799631 | H24: =H23*(1-$B$9) -> 5.0367994 | I24: =I23*(1-$B$9) -> 5.3822591 | ... L24: =L23*(1-$B$9) -> 6.2252578
A25: Net reinvestment, % of revenue | B25: 0.03 | C25: 0.03 | D25: 0.03 | E25: 0.03 | F25: 0.03 | G25: =$F25+($L25-$F25)*G$17/5 -> 0.028 | H25: =$F25+($L25-$F25)*H$17/5 -> 0.026 | I25: =$F25+($L25-$F25)*I$17/5 -> 0.024 | J25: =$F25+($L25-$F25)*J$17/5 -> 0.022 | K25: =$F25+($L25-$F25)*K$17/5 -> 0.02 | L25: 0.02
A26: Net reinvestment | B26: =B20*B25 -> 0.549 | C26: =C20*C25 -> 0.609 | D26: =D20*D25 -> 0.666 | E26: =E20*E25 -> 0.72 | F26: =F20*F25 -> 0.771 | G26: =G20*G25 -> 0.76541453 | H26: =H20*H25 -> 0.75089899 | I26: =I20*I25 -> 0.72733232 | ... L26: =L20*L25 -> 0.67665846
A27: Change in working capital | B27: =$B$11*(B20-$B$12) -> -0.104 | C27: =$B$11*(C20-B20) -> -0.1 | D27: =$B$11*(D20-C20) -> -0.095 | E27: =$B$11*(E20-D20) -> -0.09 | F27: =$B$11*(F20-E20) -> -0.085 | G27: =$B$11*(G20-F20) -> -0.081811667 | H27: =$B$11*(H20-G20) -> -0.077224859 | I27: =$B$11*(I20-H20) -> -0.071239135 | J27: =$B$11*(J20-I20) -> -0.063894124 | ... L27: =$B$11*(L20-K20) -> -0.057205425
A28: Free cash flow | B28: =B24-B26-B27 -> 2.0438 | C28: =C24-C26-C27 -> 2.4142 | D28: =D24-D26-D27 -> 2.8034 | E28: =E24-E26-E27 -> 3.21 | F28: =F24-F26-F27 -> 3.6316 | G28: =G24-G26-G27 -> 3.9963603 | H28: =H24-H26-H27 -> 4.3631253 | I28: =I24-I26-I27 -> 4.726166 | ... L28: =L24-L26-L27 -> 5.6058048
A29: Discount factor | B29: =1/(1+$B$10)^B$16 -> 0.95563697 | C29: =1/(1+$B$10)^C$16 -> 0.87272782 | D29: =1/(1+$B$10)^D$16 -> 0.79701171 | E29: =1/(1+$B$10)^E$16 -> 0.72786458 | F29: =1/(1+$B$10)^F$16 -> 0.66471651 | G29: =1/(1+$B$10)^G$16 -> 0.60704704 | H29: =1/(1+$B$10)^H$16 -> 0.55438086 | I29: =1/(1+$B$10)^I$16 -> 0.50628389 | ... K29: =1/(1+$B$10)^K$16 -> 0.42224631
A30: PV of free cash flow | B30: =B28*B29 -> 1.9531308 | C30: =C28*C29 -> 2.1069395 | D30: =D28*D29 -> 2.2343426 | E30: =E28*E29 -> 2.3364453 | F30: =F28*F29 -> 2.4139845 | G30: =G28*G29 -> 2.4259787 | H30: =H28*H29 -> 2.4188331 | I30: =I28*I29 -> 2.3927817 | ... K30: =K28*K29 -> 2.2869859
A31: Terminal value | B31: =L28/($B$10-L21) -> 93.43008 | C31: =IF($B$10>L21,"","Discount rate must exceed terminal growth")
A32: PV of terminal value | B32: =B31/(1+$B$10)^$K$16 -> 39.450507
A33: Equity value (PV FCF + PV TV + net cash + other) | B33: =SUM(B30:K30)+B32+$B$7+$B$8 -> 60.61841
A34: Value per share ($) | B34: =B33/$B$6 -> 58.852825
A35: Value vs share price | B35: =B34/$B$4-1 -> -0.62475883
A37: Base: growth slows from 19% to 11%
A38: Revenue | B38: 19.2 | C38: 22.4 | D38: 25.8 | E38: 29.2 | F38: 32.6 | G38: =F38*(1+$F39+($L39-$F39)*G$17/5) -> 35.897512 | H38: =G38*(1+$F39+($L39-$F39)*H$17/5) -> 38.979781 | I38: =H38*(1+$F39+($L39-$F39)*I$17/5) -> 41.730792 | J38: =I38*(1+$F39+($L39-$F39)*J$17/5) -> 44.037991 | K38: =J38*(1+$F39+($L39-$F39)*K$17/5) -> 45.79951 | L38: =K38*(1+L39) -> 47.631491
A39: Revenue growth (terminal column = terminal growth, input) | B39: =B38/$B$12-1 -> 0.1837238 | C39: =C38/B38-1 -> 0.16666667 | D39: =D38/C38-1 -> 0.15178571 | E39: =E38/D38-1 -> 0.13178295 | F39: =F38/E38-1 -> 0.11643836 | G39: =G38/F38-1 -> 0.10115068 | H39: =H38/G38-1 -> 0.085863014 | I39: =I38/H38-1 -> 0.070575342 | J39: =J38/I38-1 -> 0.055287671 | K39: =K38/J38-1 -> 0.04 | L39: 0.04
A40: Operating margin | B40: 0.19 | C40: 0.21 | D40: 0.23 | E40: 0.245 | F40: 0.26 | G40: =$F40+($L40-$F40)*G$17/5 -> 0.262 | H40: =$F40+($L40-$F40)*H$17/5 -> 0.264 | I40: =$F40+($L40-$F40)*I$17/5 -> 0.266 | J40: =$F40+($L40-$F40)*J$17/5 -> 0.268 | K40: =$F40+($L40-$F40)*K$17/5 -> 0.27 | L40: 0.27
A41: Operating income | B41: =B38*B40 -> 3.648 | C41: =C38*C40 -> 4.704 | D41: =D38*D40 -> 5.934 | E41: =E38*E40 -> 7.154 | F41: =F38*F40 -> 8.476 | G41: =G38*G40 -> 9.4051482 | H41: =H38*H40 -> 10.290662 | I41: =I38*I40 -> 11.100391 | ... L41: =L38*L40 -> 12.860502
A42: NOPAT | B42: =B41*(1-$B$9) -> 2.9184 | C42: =C41*(1-$B$9) -> 3.7632 | D42: =D41*(1-$B$9) -> 4.7472 | E42: =E41*(1-$B$9) -> 5.7232 | F42: =F41*(1-$B$9) -> 6.7808 | G42: =G41*(1-$B$9) -> 7.5241186 | H42: =H41*(1-$B$9) -> 8.2325297 | I42: =I41*(1-$B$9) -> 8.8803126 | ... L42: =L41*(1-$B$9) -> 10.288402
A43: Net reinvestment, % of revenue | B43: 0.03 | C43: 0.03 | D43: 0.03 | E43: 0.03 | F43: 0.03 | G43: =$F43+($L43-$F43)*G$17/5 -> 0.028 | H43: =$F43+($L43-$F43)*H$17/5 -> 0.026 | I43: =$F43+($L43-$F43)*I$17/5 -> 0.024 | J43: =$F43+($L43-$F43)*J$17/5 -> 0.022 | K43: =$F43+($L43-$F43)*K$17/5 -> 0.02 | L43: 0.02
A44: Net reinvestment | B44: =B38*B43 -> 0.576 | C44: =C38*C43 -> 0.672 | D44: =D38*D43 -> 0.774 | E44: =E38*E43 -> 0.876 | F44: =F38*F43 -> 0.978 | G44: =G38*G43 -> 1.0051303 | H44: =H38*H43 -> 1.0134743 | I44: =I38*I43 -> 1.001539 | ... L44: =L38*L43 -> 0.95262981
...

Sheet WACC
A1: Discount rates: calculated (CAPM) versus assumed
A2: Blue = input, black = formula, green = link. The yellow switches set the rate used on the model sheet.
A5: Rate used in valuations (1 = Calculated, 2 = Assumed) | B5: 2 | C5: Switch. 2 reproduces the doc's figures
A6: Beta used (1 = Raw 5-year, 2 = Blume adjusted) | B6: 2 | C6: Blume adjusted = 0.67 x raw + 0.33
A7: Risk-free rate (10-year Treasury) | B7: 0.0531 | C7: FRED via MacroRadar, Oct 6, 2026 (same as earlier journal models)
A8: Equity risk premium | B8: 0.05 | C8: Analyst assumption
A9: Credit spread over risk-free (pre-tax cost of debt) | B9: 0.012 | C9: Analyst assumption: investment-grade spread
A12: Item | B12: NOW | C12: Source / note
A13: Raw beta (5-year) | B13: 0.99 | C13: Stock Analysis statistics, Oct 23, 2026
A14: Beta override (blank = none) | C14: Cheniere's 0.06 raw beta reflects its own history, not its risk; 0.80 used instead
A15: Adjusted beta | B15: =0.67*IF(ISNUMBER(B14),B14,B13)+0.33 -> 0.9933 | C15: Blume: 0.67 x raw (or override) + 0.33
A16: Beta used | B16: =IF($B$6=1,IF(ISNUMBER(B14),B14,B13),B15) -> 0.9933 | C16: Per switch in B6
A17: Cost of equity | B17: =$B$7+B16*$B$8 -> 0.102765 | C17: Risk-free + beta x ERP
A18: Pre-tax cost of debt | B18: =$B$7+$B$9 -> 0.0651 | C18: Risk-free + spread
A19: Tax rate | B19: =NOW!B9 -> 0.2 | C19: Linked from company sheet
A20: After-tax cost of debt | B20: =B18*(1-B19) -> 0.05208
A21: Market value of equity ($B) | B21: =NOW!B4*NOW!B6 -> 161.5452 | C21: Price x shares
A22: Debt ($B) | B22: 8.45 | C22: Stock Analysis, total debt
A23: Equity weight | B23: =B21/(B21+B22) -> 0.95029271
A24: Debt weight | B24: =B22/(B21+B22) -> 0.049707286
A25: Calculated WACC (CAPM) | B25: =B23*B17+B24*B20 -> 0.10024559 | C25: Weighted cost of capital
A26: Assumed WACC | B26: 0.095 | C26: Analyst assumption used in the doc
A27: WACC used | B27: =IF($B$5=1,B25,B26) -> 0.095 | C27: Per switch in B5; feeds each sheet's B10
A28: Check: WACC above every terminal growth rate | B28: =IF(B27>MAX(NOW!L21,NOW!L39,NOW!L57),"OK","WACC must exceed growth") -> OK
A29: Link row read by company sheets | B29: =B27 -> 0.095 | C29: Same as WACC used
