Workbook

Sheet Summary
A1: Current Holdings: scenario values for the 13 stocks (Celestica updated Oct 27, 2026)
A2: Values link to each company sheet (green). Switch the discount rate on the WACC tab. Funds (JCPI, HYBL, VGK, XBI) are excluded.
A4: Company | B4: Method | C4: Share price | D4: Discount rate | E4: Bear value | F4: Base value | G4: Bull value | H4: Base vs price | I4: Implied return at price (base case) | J4: Base target (rounded)
A5: Altria (MO) | B5: 10-year DCF | C5: =MO!B4 -> 74.96 | D5: =MO!B10 -> 0.08 | E5: =MO!B75 -> 41.980663 | F5: =MO!B76 -> 63.115403 | G5: =MO!B77 -> 82.727961 | H5: =F5/C5-1 -> -0.15801224 | I5: =MO!B86 -> 0.067476087 | J5: =IF(F5<10,ROUND(F5*4,0)/4,IF(F5<100,ROUND(F5,0),ROUND(F5/5,0)*5)) -> 63
A6: Coca-Cola (KO) | B6: 10-year DCF | C6: =KO!B4 -> 93.27 | D6: =KO!B10 -> 0.075 | E6: =KO!B75 -> 53.571974 | F6: =KO!B76 -> 71.997025 | G6: =KO!B77 -> 92.33369 | H6: =F6/C6-1 -> -0.2280795 | I6: =KO!B86 -> 0.065520945 | J6: =IF(F6<10,ROUND(F6*4,0)/4,IF(F6<100,ROUND(F6,0),ROUND(F6/5,0)*5)) -> 72
A7: Alphabet (GOOG) | B7: 10-year DCF | C7: =GOOG!B4 -> 320.47 | D7: =GOOG!B10 -> 0.095 | E7: =GOOG!B75 -> 141.94636 | F7: =GOOG!B76 -> 253.24152 | G7: =GOOG!B77 -> 325.68132 | H7: =F7/C7-1 -> -0.20978088 | I7: =GOOG!B86 -> 0.084327818 | J7: =IF(F7<10,ROUND(F7*4,0)/4,IF(F7<100,ROUND(F7,0),ROUND(F7/5,0)*5)) -> 255
A8: UnitedHealth (UNH) | B8: 10-year DCF | C8: =UNH!B4 -> 423.39 | D8: =UNH!B10 -> 0.09 | E8: =UNH!B75 -> 306.35245 | F8: =UNH!B76 -> 474.03446 | G8: =UNH!B77 -> 693.26088 | H8: =F8/C8-1 -> 0.11961656 | I8: =UNH!B86 -> 0.09583158 | J8: =IF(F8<10,ROUND(F8*4,0)/4,IF(F8<100,ROUND(F8,0),ROUND(F8/5,0)*5)) -> 475
A9: Cheniere Energy (LNG) | B9: 10-year DCF | C9: =LNG!B4 -> 297.605 | D9: =LNG!B10 -> 0.075 | E9: =LNG!B75 -> 135.17044 | F9: =LNG!B76 -> 305.06065 | G9: =LNG!B77 -> 441.02468 | H9: =F9/C9-1 -> 0.025052165 | I9: =LNG!B86 -> 0.076268867 | J9: =IF(F9<10,ROUND(F9*4,0)/4,IF(F9<100,ROUND(F9,0),ROUND(F9/5,0)*5)) -> 305
A10: ServiceNow (NOW) | B10: 10-year DCF | C10: =NOW!B4 -> 156.84 | D10: =NOW!B10 -> 0.095 | E10: =NOW!B75 -> 58.852825 | F10: =NOW!B76 -> 103.66052 | G10: =NOW!B77 -> 151.93398 | H10: =F10/C10-1 -> -0.33906836 | I10: =NOW!B86 -> 0.077975605 | J10: =IF(F10<10,ROUND(F10*4,0)/4,IF(F10<100,ROUND(F10,0),ROUND(F10/5,0)*5)) -> 105
A11: Celestica (CLS) | B11: 10-year DCF | C11: =CLS!B4 -> 246.65 | D11: =CLS!B10 -> 0.105 | E11: =CLS!B75 -> 126.07684 | F11: =CLS!B76 -> 198.69445 | G11: =CLS!B77 -> 316.91894 | H11: =F11/C11-1 -> -0.19442752 | I11: =CLS!B86 -> 0.089558686 | J11: =IF(F11<10,ROUND(F11*4,0)/4,IF(F11<100,ROUND(F11,0),ROUND(F11/5,0)*5)) -> 200
A12: Enterprise Products (EPD) | B12: 10-year DCF | C12: =EPD!B4 -> 37.405 | D12: =EPD!B10 -> 0.08 | E12: =EPD!B75 -> 20.134109 | F12: =EPD!B76 -> 34.881406 | G12: =EPD!B77 -> 47.806581 | H12: =F12/C12-1 -> -0.067466758 | I12: =EPD!B86 -> 0.077488214 | J12: =IF(F12<10,ROUND(F12*4,0)/4,IF(F12<100,ROUND(F12,0),ROUND(F12/5,0)*5)) -> 35
A13: Nvidia (NVDA) | B13: 10-year DCF | C13: =NVDA!B4 -> 212.28 | D13: =NVDA!B10 -> 0.11 | E13: =NVDA!B75 -> 94.547961 | F13: =NVDA!B76 -> 165.35934 | G13: =NVDA!B77 -> 235.2016 | H13: =F13/C13-1 -> -0.22103192 | I13: =NVDA!B86 -> 0.092900116 | J13: =IF(F13<10,ROUND(F13*4,0)/4,IF(F13<100,ROUND(F13,0),ROUND(F13/5,0)*5)) -> 165
A14: JPMorgan Chase (JPM) | B14: Residual income | C14: =JPM!B4 -> 332.07 | D14: =JPM!B8 -> 0.1 | E14: =JPM!B53 -> 191.75064 | F14: =JPM!B54 -> 258.747 | G14: =JPM!B55 -> 315.09112 | H14: =F14/C14-1 -> -0.22080585 | I14: =JPM!B65 -> 0.088038318 | J14: =IF(F14<10,ROUND(F14*4,0)/4,IF(F14<100,ROUND(F14,0),ROUND(F14/5,0)*5)) -> 260
A15: Bank of America (BAC) | B15: Residual income | C15: =BAC!B4 -> 50.795 | D15: =BAC!B8 -> 0.105 | E15: =BAC!B53 -> 35.555326 | F15: =BAC!B54 -> 54.44399 | G15: =BAC!B55 -> 63.196153 | H15: =F15/C15-1 -> 0.071837586 | I15: =BAC!B65 -> 0.10944483 | J15: =IF(F15<10,ROUND(F15*4,0)/4,IF(F15<100,ROUND(F15,0),ROUND(F15/5,0)*5)) -> 54
A16: First Solar (FSLR) | B16: 10-year DCF | C16: =FSLR!B4 -> 171.57 | D16: =FSLR!B10 -> 0.105 | E16: =FSLR!B75 -> 72.183385 | F16: =FSLR!B76 -> 125.46518 | G16: =FSLR!B77 -> 187.54415 | H16: =F16/C16-1 -> -0.26872311 | I16: =FSLR!B86 -> 0.075764103 | J16: =IF(F16<10,ROUND(F16*4,0)/4,IF(F16<100,ROUND(F16,0),ROUND(F16/5,0)*5)) -> 125
A17: TMC the metals company (TMC) | B17: Probability-weighted | C17: =TMC!B4 -> 2.43 | D17: =TMC!B9 -> 0.15 | E17: =TMC!B19 -> 0.19447637 | F17: =TMC!B20 -> 2.2137378 | G17: =TMC!B21 -> 7.9139609 | H17: =F17/C17-1 -> -0.088996784 | I17: n/a | J17: =IF(F17<10,ROUND(F17*4,0)/4,IF(F17<100,ROUND(F17,0),ROUND(F17/5,0)*5)) -> 2.25
A19: Notes
A20: Base value is what the business is worth if the base case plays out and you want to earn the discount rate. Implied return is what the base case earns at today's price.
A21: DCF: five explicit years, then five years fading growth, margin and reinvestment to terminal levels. FCF = operating income x (1 - tax) - net reinvestment - working capital x revenue change. Mid-year discounting from October 2026.
A22: Margins are after stock-based pay. For ServiceNow that is about 19% today, not the 31.5% non-GAAP figure, which is the main reason its value is lower than a multiple of adjusted earnings suggests.
A23: Banks: tangible book plus the present value of returns above the cost of equity (residual income). TMC: probability-weighted, from the company's 2025 study with analyst haircuts.
A24: Discount rates use a 5.31% risk-free rate and a 5% equity risk premium, the same as the earlier journal models. At these rates most quality stocks look fully priced; the implied return column shows by how much.
A25: Prices: Oct 23, 2026 intraday, except Celestica (Oct 26 close, model updated for its Q3 results on Oct 27). Company data: Stock Analysis, company filings and releases (see each sheet). Research for my own records, not investment advice.

Sheet WACC
A1: Discount rates: calculated (CAPM) versus assumed
A2: Blue = input, black = formula, green = link. The yellow switches apply to every company. Banks use cost of equity only (lower table). TMC uses its own risk rate on its sheet.
A5: Rate used in valuations (1 = Calculated, 2 = Assumed) | B5: 2 | C5: Switch. 2 reproduces the doc's figures
A6: Beta used (1 = Raw 5-year, 2 = Blume adjusted) | B6: 2 | C6: Blume adjusted = 0.67 x raw + 0.33
A7: Risk-free rate (10-year Treasury) | B7: 0.0531 | C7: FRED via MacroRadar, Oct 6, 2026 (same as earlier journal models)
A8: Equity risk premium | B8: 0.05 | C8: Analyst assumption
A9: Credit spread over risk-free (pre-tax cost of debt) | B9: 0.012 | C9: Analyst assumption: investment-grade spread
A12: Item | B12: MO | C12: KO | D12: GOOG | E12: UNH | F12: LNG | G12: NOW | H12: CLS | I12: EPD | J12: NVDA | K12: FSLR | L12: Source / note
A13: Raw beta (5-year) | B13: 0.46 | C13: 0.32 | D13: 1.21 | E13: 0.61 | F13: 0.06 | G13: 0.99 | H13: 1.32 | I13: 0.49 | J13: 2.22 | K13: 1.79 | L13: Stock Analysis statistics, Oct 23, 2026
A14: Beta override (blank = none) | F14: 0.8 | L14: Cheniere's 0.06 raw beta reflects its own history, not its risk; 0.80 used instead
A15: Adjusted beta | B15: =0.67*IF(ISNUMBER(B14),B14,B13)+0.33 -> 0.6382 | C15: =0.67*IF(ISNUMBER(C14),C14,C13)+0.33 -> 0.5444 | D15: =0.67*IF(ISNUMBER(D14),D14,D13)+0.33 -> 1.1407 | E15: =0.67*IF(ISNUMBER(E14),E14,E13)+0.33 -> 0.7387 | F15: =0.67*IF(ISNUMBER(F14),F14,F13)+0.33 -> 0.866 | G15: =0.67*IF(ISNUMBER(G14),G14,G13)+0.33 -> 0.9933 | H15: =0.67*IF(ISNUMBER(H14),H14,H13)+0.33 -> 1.2144 | I15: =0.67*IF(ISNUMBER(I14),I14,I13)+0.33 -> 0.6583 | ... K15: =0.67*IF(ISNUMBER(K14),K14,K13)+0.33 -> 1.5293 | L15: Blume: 0.67 x raw (or override) + 0.33
A16: Beta used | B16: =IF($B$6=1,IF(ISNUMBER(B14),B14,B13),B15) -> 0.6382 | C16: =IF($B$6=1,IF(ISNUMBER(C14),C14,C13),C15) -> 0.5444 | D16: =IF($B$6=1,IF(ISNUMBER(D14),D14,D13),D15) -> 1.1407 | E16: =IF($B$6=1,IF(ISNUMBER(E14),E14,E13),E15) -> 0.7387 | F16: =IF($B$6=1,IF(ISNUMBER(F14),F14,F13),F15) -> 0.866 | G16: =IF($B$6=1,IF(ISNUMBER(G14),G14,G13),G15) -> 0.9933 | H16: =IF($B$6=1,IF(ISNUMBER(H14),H14,H13),H15) -> 1.2144 | I16: =IF($B$6=1,IF(ISNUMBER(I14),I14,I13),I15) -> 0.6583 | ... K16: =IF($B$6=1,IF(ISNUMBER(K14),K14,K13),K15) -> 1.5293 | L16: Per switch in B6
A17: Cost of equity | B17: =$B$7+B16*$B$8 -> 0.08501 | C17: =$B$7+C16*$B$8 -> 0.08032 | D17: =$B$7+D16*$B$8 -> 0.110135 | E17: =$B$7+E16*$B$8 -> 0.090035 | F17: =$B$7+F16*$B$8 -> 0.0964 | G17: =$B$7+G16*$B$8 -> 0.102765 | H17: =$B$7+H16*$B$8 -> 0.11382 | I17: =$B$7+I16*$B$8 -> 0.086015 | ... K17: =$B$7+K16*$B$8 -> 0.129565 | L17: Risk-free + beta x ERP
A18: Pre-tax cost of debt | B18: =$B$7+$B$9 -> 0.0651 | C18: =$B$7+$B$9 -> 0.0651 | D18: =$B$7+$B$9 -> 0.0651 | E18: =$B$7+$B$9 -> 0.0651 | F18: =$B$7+$B$9 -> 0.0651 | G18: =$B$7+$B$9 -> 0.0651 | H18: =$B$7+$B$9 -> 0.0651 | I18: =$B$7+$B$9 -> 0.0651 | ... K18: =$B$7+$B$9 -> 0.0651 | L18: Risk-free + spread
A19: Tax rate | B19: =MO!B9 -> 0.235 | C19: =KO!B9 -> 0.19 | D19: =GOOG!B9 -> 0.17 | E19: =UNH!B9 -> 0.22 | F19: =LNG!B9 -> 0.18 | G19: =NOW!B9 -> 0.2 | H19: =CLS!B9 -> 0.21 | I19: =EPD!B9 -> 0 | J19: =NVDA!B9 -> 0.16 | K19: =FSLR!B9 -> 0.12 | L19: Linked from company sheet
A20: After-tax cost of debt | B20: =B18*(1-B19) -> 0.0498015 | C20: =C18*(1-C19) -> 0.052731 | D20: =D18*(1-D19) -> 0.054033 | E20: =E18*(1-E19) -> 0.050778 | F20: =F18*(1-F19) -> 0.053382 | G20: =G18*(1-G19) -> 0.05208 | H20: =H18*(1-H19) -> 0.051429 | I20: =I18*(1-I19) -> 0.0651 | ... K20: =K18*(1-K19) -> 0.057288
A21: Market value of equity ($B) | B21: =MO!B4*MO!B6 -> 125.1832 | C21: =KO!B4*KO!B6 -> 401.061 | D21: =GOOG!B4*GOOG!B6 -> 3919.3481 | E21: =UNH!B4*UNH!B6 -> 380.03063 | F21: =LNG!B4*LNG!B6 -> 61.464361 | G21: =NOW!B4*NOW!B6 -> 161.5452 | H21: =CLS!B4*CLS!B6 -> 31.102565 | I21: =EPD!B4*EPD!B6 -> 80.7948 | J21: =NVDA!B4*NVDA!B6 -> 5126.562 | K21: =FSLR!B4*FSLR!B6 -> 18.438628 | L21: Price x shares
A22: Debt ($B) | B22: 24.58 | C22: 44.26 | D22: 120.79 | E22: 74.33 | F22: 27.97 | G22: 8.45 | H22: 0.8188 | I22: 34.21 | J22: 38.86 | K22: 0.194 | L22: Stock Analysis, total debt
A23: Equity weight | B23: =B21/(B21+B22) -> 0.83587423 | C23: =C21/(C21+C22) -> 0.90061102 | D23: =D21/(D21+D22) -> 0.97010251 | E23: =E21/(E21+E22) -> 0.83640748 | F23: =F21/(F21+F22) -> 0.68725667 | G23: =G21/(G21+G22) -> 0.95029271 | H23: =H21/(H21+H22) -> 0.97434947 | I23: =I21/(I21+I22) -> 0.70253416 | ... K23: =K21/(K21+K22) -> 0.98958816
A24: Debt weight | B24: =B22/(B21+B22) -> 0.16412577 | C24: =C22/(C21+C22) -> 0.09938898 | D24: =D22/(D21+D22) -> 0.029897493 | E24: =E22/(E21+E22) -> 0.16359252 | F24: =F22/(F21+F22) -> 0.31274333 | G24: =G22/(G21+G22) -> 0.049707286 | H24: =H22/(H21+H22) -> 0.025650532 | I24: =I22/(I21+I22) -> 0.29746584 | ... K24: =K22/(K21+K22) -> 0.010411843
A25: Calculated WACC (CAPM) | B25: =B23*B17+B24*B20 -> 0.079231378 | C25: =C23*C17+C24*C20 -> 0.077577957 | D25: =D23*D17+D24*D20 -> 0.10845769 | E25: =E23*E17+E24*E20 -> 0.083612848 | F25: =F23*F17+F24*F20 -> 0.082946407 | G25: =G23*G17+G24*G20 -> 0.10024559 | H25: =H23*H17+H24*H20 -> 0.11221964 | I25: =I23*I17+I24*I20 -> 0.079793502 | ... K25: =K23*K17+K24*K20 -> 0.12881246 | L25: Weighted cost of capital
A26: Assumed WACC | B26: 0.08 | C26: 0.075 | D26: 0.095 | E26: 0.09 | F26: 0.075 | G26: 0.095 | H26: 0.105 | I26: 0.08 | J26: 0.11 | K26: 0.105 | L26: Analyst assumption used in the doc
A27: WACC used | B27: =IF($B$5=1,B25,B26) -> 0.08 | C27: =IF($B$5=1,C25,C26) -> 0.075 | D27: =IF($B$5=1,D25,D26) -> 0.095 | E27: =IF($B$5=1,E25,E26) -> 0.09 | F27: =IF($B$5=1,F25,F26) -> 0.075 | G27: =IF($B$5=1,G25,G26) -> 0.095 | H27: =IF($B$5=1,H25,H26) -> 0.105 | I27: =IF($B$5=1,I25,I26) -> 0.08 | ... K27: =IF($B$5=1,K25,K26) -> 0.105 | L27: Per switch in B5; feeds each sheet's B10
A28: Check: WACC above every terminal growth rate | B28: =IF(B27>MAX(MO!L21,MO!L39,MO!L57),"OK","WACC must exceed growth") -> OK | C28: =IF(C27>MAX(KO!L21,KO!L39,KO!L57),"OK","WACC must exceed growth") -> OK | D28: =IF(D27>MAX(GOOG!L21,GOOG!L39,GOOG!L57),"OK","WACC must exceed growth") -> OK | E28: =IF(E27>MAX(UNH!L21,UNH!L39,UNH!L57),"OK","WACC must exceed growth") -> OK | F28: =IF(F27>MAX(LNG!L21,LNG!L39,LNG!L57),"OK","WACC must exceed growth") -> OK | G28: =IF(G27>MAX(NOW!L21,NOW!L39,NOW!L57),"OK","WACC must exceed growth") -> OK | H28: =IF(H27>MAX(CLS!L21,CLS!L39,CLS!L57),"OK","WACC must exceed growth") -> OK | I28: =IF(I27>MAX(EPD!L21,EPD!L39,EPD!L57),"OK","WACC must exceed growth") -> OK | J28: =IF(J27>MAX(NVDA!L21,NVDA!L39,NVDA!L57),"OK","WACC must exceed growth") -> OK | K28: =IF(K27>MAX(FSLR!L21,FSLR!L39,FSLR!L57),"OK","WACC must exceed growth") -> OK
A29: Link row read by company sheets | B29: =B27 -> 0.08 | C29: =C27 -> 0.075 | D29: =D27 -> 0.095 | E29: =E27 -> 0.09 | F29: =F27 -> 0.075 | G29: =G27 -> 0.095 | H29: =H27 -> 0.105 | I29: =I27 -> 0.08 | ... K29: =K27 -> 0.105 | L29: Same as WACC used
A33: Bank cost of equity | B33: JPM | C33: BAC | D33: Source / note
A34: Raw beta (5-year) | B34: 1.02 | C34: 1.21 | D34: Stock Analysis statistics, Oct 23, 2026
A35: Adjusted beta | B35: =0.67*B34+0.33 -> 1.0134 | C35: =0.67*C34+0.33 -> 1.1407 | D35: Blume
A36: Beta used | B36: =IF($B$6=1,B34,B35) -> 1.0134 | C36: =IF($B$6=1,C34,C35) -> 1.1407 | D36: Per switch in B6
A37: Calculated cost of equity (CAPM) | B37: =$B$7+B36*$B$8 -> 0.10377 | C37: =$B$7+C36*$B$8 -> 0.110135 | D37: Risk-free + beta x ERP
A38: Assumed cost of equity | B38: 0.1 | C38: 0.105 | D38: Analyst assumption used in the doc
A39: Cost of equity used | B39: =IF($B$5=1,B37,B38) -> 0.1 | C39: =IF($B$5=1,C37,C38) -> 0.105 | D39: Per switch in B5
A40: Link row read by bank sheets | B40: =B39 -> 0.1 | C40: =C39 -> 0.105

Sheet MO
A1: Altria (MO): 10-year scenario DCF
A2: Units: $ billions unless noted. Blue = input, black = formula, green = link, yellow = key lever. Years 6 to 10 fade growth, margin and reinvestment toward each scenario's terminal levels.
A4: Share price ($) | B4: 74.96 | C4: Oct 23, 2026 intraday (Yahoo Finance via the site's price feed)
A5: Price date | B5: Oct 23, 2026 | C5: Text
A6: Shares outstanding (billions) | B6: 1.67 | C6: Stock Analysis statistics, Oct 23, 2026
A7: Net cash, negative = net debt | B7: -22.21 | C7: Stock Analysis statistics, Oct 23, 2026: cash less total debt
A8: Other non-operating assets, less outside claims | B8: 10.81 | C8: ABI stake: 159.1M shares (Schedule 13D/A, May 2026) x $84.93 (Oct 23, 2026), less 20% for tax on sale
A9: Tax rate | B9: 0.235 | C9: Analyst assumption (normalized, near the reported effective rate)
A10: Discount rate (WACC), from WACC tab | B10: =WACC!B29 -> 0.08 | C10: Calculated or assumed, per the switch in WACC!B5
A11: Working capital, % of revenue change | B11: 0 | C11: Analyst assumption
A12: Base-year revenue (2026E) | B12: 20.6 | C12: 2026E consensus $20.6B (Stock Analysis, revenue net of excise taxes)
A13: Selected scenario (1 Bear, 2 Base, 3 Bull) | B13: 2 | C13: Lever
A15: Year | B15: 2027 | C15: 2028 | D15: 2029 | E15: 2030 | F15: 2031 | G15: 2032 | H15: 2033 | I15: 2034 | J15: 2035 | K15: 2036 | L15: Terminal
A16: Discount period (years, mid-year) | B16: 0.5 | C16: =B16+1 -> 1.5 | D16: =C16+1 -> 2.5 | E16: =D16+1 -> 3.5 | F16: =E16+1 -> 4.5 | G16: =F16+1 -> 5.5 | H16: =G16+1 -> 6.5 | I16: =H16+1 -> 7.5 | J16: =I16+1 -> 8.5 | K16: =J16+1 -> 9.5
A17: Fade step (years 6 to 10) | B17: 0 | C17: 0 | D17: 0 | E17: 0 | F17: 0 | G17: 1 | H17: 2 | I17: 3 | J17: 4 | K17: 5
A19: Bear: volume decline speeds up, pricing power fades
A20: Revenue | B20: 20.2 | C20: 19.6 | D20: 19 | E20: 18.4 | F20: 17.8 | G20: =F20*(1+$F21+($L21-$F21)*G$17/5) -> 17.246652 | H20: =G20*(1+$F21+($L21-$F21)*H$17/5) -> 16.736751 | I20: =H20*(1+$F21+($L21-$F21)*I$17/5) -> 16.267394 | J20: =I20*(1+$F21+($L21-$F21)*J$17/5) -> 15.835955 | K20: =J20*(1+$F21+($L21-$F21)*K$17/5) -> 15.440056 | L20: =K20*(1+L21) -> 15.054055
A21: Revenue growth (terminal column = terminal growth, input) | B21: =B20/$B$12-1 -> -0.019417476 | C21: =C20/B20-1 -> -0.02970297 | D21: =D20/C20-1 -> -0.030612245 | E21: =E20/D20-1 -> -0.031578947 | F21: =F20/E20-1 -> -0.032608696 | G21: =G20/F20-1 -> -0.031086957 | H21: =H20/G20-1 -> -0.029565217 | I21: =I20/H20-1 -> -0.028043478 | J21: =J20/I20-1 -> -0.026521739 | K21: =K20/J20-1 -> -0.025 | L21: -0.025
A22: Operating margin | B22: 0.6 | C22: 0.59 | D22: 0.58 | E22: 0.57 | F22: 0.56 | G22: =$F22+($L22-$F22)*G$17/5 -> 0.554 | H22: =$F22+($L22-$F22)*H$17/5 -> 0.548 | I22: =$F22+($L22-$F22)*I$17/5 -> 0.542 | J22: =$F22+($L22-$F22)*J$17/5 -> 0.536 | K22: =$F22+($L22-$F22)*K$17/5 -> 0.53 | L22: 0.53
A23: Operating income | B23: =B20*B22 -> 12.12 | C23: =C20*C22 -> 11.564 | D23: =D20*D22 -> 11.02 | E23: =E20*E22 -> 10.488 | F23: =F20*F22 -> 9.968 | G23: =G20*G22 -> 9.5546453 | H23: =H20*H22 -> 9.1717396 | I23: =I20*I22 -> 8.8169278 | ... L23: =L20*L22 -> 7.9786489
A24: NOPAT | B24: =B23*(1-$B$9) -> 9.2718 | C24: =C23*(1-$B$9) -> 8.84646 | D24: =D23*(1-$B$9) -> 8.4303 | E24: =E23*(1-$B$9) -> 8.02332 | F24: =F23*(1-$B$9) -> 7.62552 | G24: =G23*(1-$B$9) -> 7.3093037 | H24: =H23*(1-$B$9) -> 7.0163808 | I24: =I23*(1-$B$9) -> 6.7449498 | ... L24: =L23*(1-$B$9) -> 6.1036664
A25: Net reinvestment, % of revenue | B25: 0.005 | C25: 0.005 | D25: 0.005 | E25: 0.005 | F25: 0.005 | G25: =$F25+($L25-$F25)*G$17/5 -> 0.005 | H25: =$F25+($L25-$F25)*H$17/5 -> 0.005 | I25: =$F25+($L25-$F25)*I$17/5 -> 0.005 | J25: =$F25+($L25-$F25)*J$17/5 -> 0.005 | K25: =$F25+($L25-$F25)*K$17/5 -> 0.005 | L25: 0.005
A26: Net reinvestment | B26: =B20*B25 -> 0.101 | C26: =C20*C25 -> 0.098 | D26: =D20*D25 -> 0.095 | E26: =E20*E25 -> 0.092 | F26: =F20*F25 -> 0.089 | G26: =G20*G25 -> 0.086233261 | H26: =H20*H25 -> 0.083683756 | I26: =I20*I25 -> 0.081336972 | ... L26: =L20*L25 -> 0.075270273
A27: Change in working capital | B27: =$B$11*(B20-$B$12) -> 0 | C27: =$B$11*(C20-B20) -> 0 | D27: =$B$11*(D20-C20) -> 0 | E27: =$B$11*(E20-D20) -> 0 | F27: =$B$11*(F20-E20) -> 0 | G27: =$B$11*(G20-F20) -> 0 | H27: =$B$11*(H20-G20) -> 0 | I27: =$B$11*(I20-H20) -> 0 | J27: =$B$11*(J20-I20) -> 0 | ... L27: =$B$11*(L20-K20) -> 0
A28: Free cash flow | B28: =B24-B26-B27 -> 9.1708 | C28: =C24-C26-C27 -> 8.74846 | D28: =D24-D26-D27 -> 8.3353 | E28: =E24-E26-E27 -> 7.93132 | F28: =F24-F26-F27 -> 7.53652 | G28: =G24-G26-G27 -> 7.2230704 | H28: =H24-H26-H27 -> 6.9326971 | I28: =I24-I26-I27 -> 6.6636128 | ... L28: =L24-L26-L27 -> 6.0283962
A29: Discount factor | B29: =1/(1+$B$10)^B$16 -> 0.96225045 | C29: =1/(1+$B$10)^C$16 -> 0.89097264 | D29: =1/(1+$B$10)^D$16 -> 0.82497466 | E29: =1/(1+$B$10)^E$16 -> 0.76386543 | F29: =1/(1+$B$10)^F$16 -> 0.70728281 | G29: =1/(1+$B$10)^G$16 -> 0.65489149 | H29: =1/(1+$B$10)^H$16 -> 0.60638101 | I29: =1/(1+$B$10)^I$16 -> 0.56146389 | ... K29: =1/(1+$B$10)^K$16 -> 0.48136479
A30: PV of free cash flow | B30: =B28*B29 -> 8.8246064 | C30: =C28*C29 -> 7.7946385 | D30: =D28*D29 -> 6.8764113 | E30: =E28*E29 -> 6.0584612 | F30: =F28*F29 -> 5.330451 | G30: =G28*G29 -> 4.7303273 | H30: =H28*H29 -> 4.2038558 | I30: =I28*I29 -> 3.741378 | ... K30: =K28*K29 -> 2.9762643
A31: Terminal value | B31: =L28/($B$10-L21) -> 57.413297 | C31: =IF($B$10>L21,"","Discount rate must exceed terminal growth")
A32: PV of terminal value | B32: =B31/(1+$B$10)^$K$16 -> 27.63674
A33: Equity value (PV FCF + PV TV + net cash + other) | B33: =SUM(B30:K30)+B32+$B$7+$B$8 -> 70.107707
A34: Value per share ($) | B34: =B33/$B$6 -> 41.980663
A35: Value vs share price | B35: =B34/$B$4-1 -> -0.43995914
A37: Base: price offsets volume, flat revenue
A38: Revenue | B38: 20.7 | C38: 20.7 | D38: 20.7 | E38: 20.6 | F38: 20.6 | G38: =F38*(1+$F39+($L39-$F39)*G$17/5) -> 20.5794 | H38: =G38*(1+$F39+($L39-$F39)*H$17/5) -> 20.538241 | I38: =H38*(1+$F39+($L39-$F39)*I$17/5) -> 20.476626 | J38: =I38*(1+$F39+($L39-$F39)*J$17/5) -> 20.39472 | K38: =J38*(1+$F39+($L39-$F39)*K$17/5) -> 20.292746 | L38: =K38*(1+L39) -> 20.191283
A39: Revenue growth (terminal column = terminal growth, input) | B39: =B38/$B$12-1 -> 0.0048543689 | C39: =C38/B38-1 -> 0 | D39: =D38/C38-1 -> 0 | E39: =E38/D38-1 -> -0.0048309179 | F39: =F38/E38-1 -> 0 | G39: =G38/F38-1 -> -0.001 | H39: =H38/G38-1 -> -0.002 | I39: =I38/H38-1 -> -0.003 | J39: =J38/I38-1 -> -0.004 | K39: =K38/J38-1 -> -0.005 | L39: -0.005
A40: Operating margin | B40: 0.61 | C40: 0.61 | D40: 0.61 | E40: 0.61 | F40: 0.61 | G40: =$F40+($L40-$F40)*G$17/5 -> 0.606 | H40: =$F40+($L40-$F40)*H$17/5 -> 0.602 | I40: =$F40+($L40-$F40)*I$17/5 -> 0.598 | J40: =$F40+($L40-$F40)*J$17/5 -> 0.594 | K40: =$F40+($L40-$F40)*K$17/5 -> 0.59 | L40: 0.59
A41: Operating income | B41: =B38*B40 -> 12.627 | C41: =C38*C40 -> 12.627 | D41: =D38*D40 -> 12.627 | E41: =E38*E40 -> 12.566 | F41: =F38*F40 -> 12.566 | G41: =G38*G40 -> 12.471116 | H41: =H38*H40 -> 12.364021 | I41: =I38*I40 -> 12.245023 | ... L41: =L38*L40 -> 11.912857
A42: NOPAT | B42: =B41*(1-$B$9) -> 9.659655 | C42: =C41*(1-$B$9) -> 9.659655 | D42: =D41*(1-$B$9) -> 9.659655 | E42: =E41*(1-$B$9) -> 9.61299 | F42: =F41*(1-$B$9) -> 9.61299 | G42: =G41*(1-$B$9) -> 9.540404 | H42: =H41*(1-$B$9) -> 9.4584762 | I42: =I41*(1-$B$9) -> 9.3674423 | ... L42: =L41*(1-$B$9) -> 9.1133354
A43: Net reinvestment, % of revenue | B43: 0.005 | C43: 0.005 | D43: 0.005 | E43: 0.005 | F43: 0.005 | G43: =$F43+($L43-$F43)*G$17/5 -> 0.005 | H43: =$F43+($L43-$F43)*H$17/5 -> 0.005 | I43: =$F43+($L43-$F43)*I$17/5 -> 0.005 | J43: =$F43+($L43-$F43)*J$17/5 -> 0.005 | K43: =$F43+($L43-$F43)*K$17/5 -> 0.005 | L43: 0.005
A44: Net reinvestment | B44: =B38*B43 -> 0.1035 | C44: =C38*C43 -> 0.1035 | D44: =D38*D43 -> 0.1035 | E44: =E38*E43 -> 0.103 | F44: =F38*F43 -> 0.103 | G44: =G38*G43 -> 0.102897 | H44: =H38*H43 -> 0.10269121 | I44: =I38*I43 -> 0.10238313 | ... L44: =L38*L43 -> 0.10095641
...

Sheet KO
A1: Coca-Cola (KO): 10-year scenario DCF
A2: Units: $ billions unless noted. Blue = input, black = formula, green = link, yellow = key lever. Years 6 to 10 fade growth, margin and reinvestment toward each scenario's terminal levels.
A4: Share price ($) | B4: 93.27 | C4: Oct 23, 2026 intraday (Yahoo Finance via the site's price feed)
A5: Price date | B5: Oct 23, 2026 | C5: Text
A6: Shares outstanding (billions) | B6: 4.3 | C6: Stock Analysis statistics, Oct 23, 2026
A7: Net cash, negative = net debt | B7: -27.89 | C7: Stock Analysis statistics, Oct 23, 2026: cash less total debt
A8: Other non-operating assets, less outside claims | B8: 20.78 | C8: Equity-method investments (bottlers) at book, $20.78B (10-Q, Jul 3, 2026); fair value likely higher
A9: Tax rate | B9: 0.19 | C9: Analyst assumption (normalized, near the reported effective rate)
A10: Discount rate (WACC), from WACC tab | B10: =WACC!C29 -> 0.075 | C10: Calculated or assumed, per the switch in WACC!B5
A11: Working capital, % of revenue change | B11: 0 | C11: Analyst assumption
A12: Base-year revenue (2026E) | B12: 49.8 | C12: 2026E consensus $49.8B (Stock Analysis)
A13: Selected scenario (1 Bear, 2 Base, 3 Bull) | B13: 2 | C13: Lever
A15: Year | B15: 2027 | C15: 2028 | D15: 2029 | E15: 2030 | F15: 2031 | G15: 2032 | H15: 2033 | I15: 2034 | J15: 2035 | K15: 2036 | L15: Terminal
A16: Discount period (years, mid-year) | B16: 0.5 | C16: =B16+1 -> 1.5 | D16: =C16+1 -> 2.5 | E16: =D16+1 -> 3.5 | F16: =E16+1 -> 4.5 | G16: =F16+1 -> 5.5 | H16: =G16+1 -> 6.5 | I16: =H16+1 -> 7.5 | J16: =I16+1 -> 8.5 | K16: =J16+1 -> 9.5
A17: Fade step (years 6 to 10) | B17: 0 | C17: 0 | D17: 0 | E17: 0 | F17: 0 | G17: 1 | H17: 2 | I17: 3 | J17: 4 | K17: 5
A19: Bear: volumes stall, currency drag
A20: Revenue | B20: 51 | C20: 52.3 | D20: 53.6 | E20: 54.9 | F20: 56.2 | G20: =F20*(1+$F21+($L21-$F21)*G$17/5) -> 57.545627 | H20: =G20*(1+$F21+($L21-$F21)*H$17/5) -> 58.938671 | I20: =H20*(1+$F21+($L21-$F21)*I$17/5) -> 60.381004 | J20: =I20*(1+$F21+($L21-$F21)*J$17/5) -> 61.874582 | K20: =J20*(1+$F21+($L21-$F21)*K$17/5) -> 63.421446 | L20: =K20*(1+L21) -> 65.006983
A21: Revenue growth (terminal column = terminal growth, input) | B21: =B20/$B$12-1 -> 0.024096386 | C21: =C20/B20-1 -> 0.025490196 | D21: =D20/C20-1 -> 0.024856597 | E21: =E20/D20-1 -> 0.024253731 | F21: =F20/E20-1 -> 0.023679417 | G21: =G20/F20-1 -> 0.023943534 | H21: =H20/G20-1 -> 0.02420765 | I21: =I20/H20-1 -> 0.024471767 | J21: =J20/I20-1 -> 0.024735883 | K21: =K20/J20-1 -> 0.025 | L21: 0.025
A22: Operating margin | B22: 0.31 | C22: 0.31 | D22: 0.31 | E22: 0.31 | F22: 0.31 | G22: =$F22+($L22-$F22)*G$17/5 -> 0.308 | H22: =$F22+($L22-$F22)*H$17/5 -> 0.306 | I22: =$F22+($L22-$F22)*I$17/5 -> 0.304 | J22: =$F22+($L22-$F22)*J$17/5 -> 0.302 | K22: =$F22+($L22-$F22)*K$17/5 -> 0.3 | L22: 0.3
A23: Operating income | B23: =B20*B22 -> 15.81 | C23: =C20*C22 -> 16.213 | D23: =D20*D22 -> 16.616 | E23: =E20*E22 -> 17.019 | F23: =F20*F22 -> 17.422 | G23: =G20*G22 -> 17.724053 | H23: =H20*H22 -> 18.035233 | I23: =I20*I22 -> 18.355825 | ... L23: =L20*L22 -> 19.502095
A24: NOPAT | B24: =B23*(1-$B$9) -> 12.8061 | C24: =C23*(1-$B$9) -> 13.13253 | D24: =D23*(1-$B$9) -> 13.45896 | E24: =E23*(1-$B$9) -> 13.78539 | F24: =F23*(1-$B$9) -> 14.11182 | G24: =G23*(1-$B$9) -> 14.356483 | H24: =H23*(1-$B$9) -> 14.608539 | I24: =I23*(1-$B$9) -> 14.868219 | ... L24: =L23*(1-$B$9) -> 15.796697
A25: Net reinvestment, % of revenue | B25: 0.02 | C25: 0.02 | D25: 0.02 | E25: 0.02 | F25: 0.02 | G25: =$F25+($L25-$F25)*G$17/5 -> 0.02 | H25: =$F25+($L25-$F25)*H$17/5 -> 0.02 | I25: =$F25+($L25-$F25)*I$17/5 -> 0.02 | J25: =$F25+($L25-$F25)*J$17/5 -> 0.02 | K25: =$F25+($L25-$F25)*K$17/5 -> 0.02 | L25: 0.02
A26: Net reinvestment | B26: =B20*B25 -> 1.02 | C26: =C20*C25 -> 1.046 | D26: =D20*D25 -> 1.072 | E26: =E20*E25 -> 1.098 | F26: =F20*F25 -> 1.124 | G26: =G20*G25 -> 1.1509125 | H26: =H20*H25 -> 1.1787734 | I26: =I20*I25 -> 1.2076201 | ... L26: =L20*L25 -> 1.3001397
A27: Change in working capital | B27: =$B$11*(B20-$B$12) -> 0 | C27: =$B$11*(C20-B20) -> 0 | D27: =$B$11*(D20-C20) -> 0 | E27: =$B$11*(E20-D20) -> 0 | F27: =$B$11*(F20-E20) -> 0 | G27: =$B$11*(G20-F20) -> 0 | H27: =$B$11*(H20-G20) -> 0 | I27: =$B$11*(I20-H20) -> 0 | J27: =$B$11*(J20-I20) -> 0 | ... L27: =$B$11*(L20-K20) -> 0
A28: Free cash flow | B28: =B24-B26-B27 -> 11.7861 | C28: =C24-C26-C27 -> 12.08653 | D28: =D24-D26-D27 -> 12.38696 | E28: =E24-E26-E27 -> 12.68739 | F28: =F24-F26-F27 -> 12.98782 | G28: =G24-G26-G27 -> 13.20557 | H28: =H24-H26-H27 -> 13.429766 | I28: =I24-I26-I27 -> 13.660598 | ... L28: =L24-L26-L27 -> 14.496557
A29: Discount factor | B29: =1/(1+$B$10)^B$16 -> 0.96448564 | C29: =1/(1+$B$10)^C$16 -> 0.89719595 | D29: =1/(1+$B$10)^D$16 -> 0.83460088 | E29: =1/(1+$B$10)^E$16 -> 0.77637291 | F29: =1/(1+$B$10)^F$16 -> 0.72220736 | G29: =1/(1+$B$10)^G$16 -> 0.6718208 | H29: =1/(1+$B$10)^H$16 -> 0.62494958 | I29: =1/(1+$B$10)^I$16 -> 0.58134845 | ... K29: =1/(1+$B$10)^K$16 -> 0.50305977
A30: PV of free cash flow | B30: =B28*B29 -> 11.367524 | C30: =C28*C29 -> 10.843986 | D30: =D28*D29 -> 10.338168 | E30: =E28*E29 -> 9.8501459 | F30: =F28*F29 -> 9.3798992 | G30: =G28*G29 -> 8.8717769 | H30: =H28*H29 -> 8.3929264 | I30: =I28*I29 -> 7.9415677 | ... K30: =K28*K29 -> 7.1147656
A31: Terminal value | B31: =L28/($B$10-L21) -> 289.93114 | C31: =IF($B$10>L21,"","Discount rate must exceed terminal growth")
A32: PV of terminal value | B32: =B31/(1+$B$10)^$K$16 -> 145.85269
A33: Equity value (PV FCF + PV TV + net cash + other) | B33: =SUM(B30:K30)+B32+$B$7+$B$8 -> 230.35949
A34: Value per share ($) | B34: =B33/$B$6 -> 53.571974
A35: Value vs share price | B35: =B34/$B$4-1 -> -0.42562481
A37: Base: mid-single-digit organic growth
A38: Revenue | B38: 52.3 | C38: 54.9 | D38: 57.6 | E38: 60.3 | F38: 63.1 | G38: =F38*(1+$F39+($L39-$F39)*G$17/5) -> 65.822613 | H38: =G38*(1+$F39+($L39-$F39)*H$17/5) -> 68.446348 | I38: =H38*(1+$F39+($L39-$F39)*I$17/5) -> 70.949691 | J38: =I38*(1+$F39+($L39-$F39)*J$17/5) -> 73.311387 | K38: =J38*(1+$F39+($L39-$F39)*K$17/5) -> 75.510728 | L38: =K38*(1+L39) -> 77.77605
A39: Revenue growth (terminal column = terminal growth, input) | B39: =B38/$B$12-1 -> 0.050200803 | C39: =C38/B38-1 -> 0.049713193 | D39: =D38/C38-1 -> 0.049180328 | E39: =E38/D38-1 -> 0.046875 | F39: =F38/E38-1 -> 0.046434494 | G39: =G38/F38-1 -> 0.043147595 | H39: =H38/G38-1 -> 0.039860697 | I39: =I38/H38-1 -> 0.036573798 | J39: =J38/I38-1 -> 0.033286899 | K39: =K38/J38-1 -> 0.03 | L39: 0.03
A40: Operating margin | B40: 0.32 | C40: 0.325 | D40: 0.33 | E40: 0.33 | F40: 0.33 | G40: =$F40+($L40-$F40)*G$17/5 -> 0.328 | H40: =$F40+($L40-$F40)*H$17/5 -> 0.326 | I40: =$F40+($L40-$F40)*I$17/5 -> 0.324 | J40: =$F40+($L40-$F40)*J$17/5 -> 0.322 | K40: =$F40+($L40-$F40)*K$17/5 -> 0.32 | L40: 0.32
A41: Operating income | B41: =B38*B40 -> 16.736 | C41: =C38*C40 -> 17.8425 | D41: =D38*D40 -> 19.008 | E41: =E38*E40 -> 19.899 | F41: =F38*F40 -> 20.823 | G41: =G38*G40 -> 21.589817 | H41: =H38*H40 -> 22.31351 | I41: =I38*I40 -> 22.9877 | ... L41: =L38*L40 -> 24.888336
A42: NOPAT | B42: =B41*(1-$B$9) -> 13.55616 | C42: =C41*(1-$B$9) -> 14.452425 | D42: =D41*(1-$B$9) -> 15.39648 | E42: =E41*(1-$B$9) -> 16.11819 | F42: =F41*(1-$B$9) -> 16.86663 | G42: =G41*(1-$B$9) -> 17.487752 | H42: =H41*(1-$B$9) -> 18.073943 | I42: =I41*(1-$B$9) -> 18.620037 | ... L42: =L41*(1-$B$9) -> 20.159552
A43: Net reinvestment, % of revenue | B43: 0.02 | C43: 0.02 | D43: 0.02 | E43: 0.02 | F43: 0.02 | G43: =$F43+($L43-$F43)*G$17/5 -> 0.02 | H43: =$F43+($L43-$F43)*H$17/5 -> 0.02 | I43: =$F43+($L43-$F43)*I$17/5 -> 0.02 | J43: =$F43+($L43-$F43)*J$17/5 -> 0.02 | K43: =$F43+($L43-$F43)*K$17/5 -> 0.02 | L43: 0.02
A44: Net reinvestment | B44: =B38*B43 -> 1.046 | C44: =C38*C43 -> 1.098 | D44: =D38*D43 -> 1.152 | E44: =E38*E43 -> 1.206 | F44: =F38*F43 -> 1.262 | G44: =G38*G43 -> 1.3164523 | H44: =H38*H43 -> 1.368927 | I44: =I38*I43 -> 1.4189938 | ... L44: =L38*L43 -> 1.555521
...

Sheet GOOG
A1: Alphabet (GOOG): 10-year scenario DCF
A2: Units: $ billions unless noted. Blue = input, black = formula, green = link, yellow = key lever. Years 6 to 10 fade growth, margin and reinvestment toward each scenario's terminal levels.
A4: Share price ($) | B4: 320.47 | C4: Oct 23, 2026 intraday (Yahoo Finance via the site's price feed)
A5: Price date | B5: Oct 23, 2026 | C5: Text
A6: Shares outstanding (billions) | B6: 12.23 | C6: Stock Analysis statistics, Oct 23, 2026
A7: Net cash, negative = net debt | B7: 121.68 | C7: Stock Analysis statistics, Oct 23, 2026: cash less total debt
A8: Other non-operating assets, less outside claims | B8: 0 | C8: Private stakes (SpaceX, Anthropic, others) excluded
A9: Tax rate | B9: 0.17 | C9: Analyst assumption (normalized, near the reported effective rate)
A10: Discount rate (WACC), from WACC tab | B10: =WACC!D29 -> 0.095 | C10: Calculated or assumed, per the switch in WACC!B5
A11: Working capital, % of revenue change | B11: 0 | C11: Analyst assumption
A12: Base-year revenue (2026E) | B12: 499.6 | C12: 2026E consensus $499.6B (Stock Analysis)
A13: Selected scenario (1 Bear, 2 Base, 3 Bull) | B13: 2 | C13: Lever
A15: Year | B15: 2027 | C15: 2028 | D15: 2029 | E15: 2030 | F15: 2031 | G15: 2032 | H15: 2033 | I15: 2034 | J15: 2035 | K15: 2036 | L15: Terminal
A16: Discount period (years, mid-year) | B16: 0.5 | C16: =B16+1 -> 1.5 | D16: =C16+1 -> 2.5 | E16: =D16+1 -> 3.5 | F16: =E16+1 -> 4.5 | G16: =F16+1 -> 5.5 | H16: =G16+1 -> 6.5 | I16: =H16+1 -> 7.5 | J16: =I16+1 -> 8.5 | K16: =J16+1 -> 9.5
A17: Fade step (years 6 to 10) | B17: 0 | C17: 0 | D17: 0 | E17: 0 | F17: 0 | G17: 1 | H17: 2 | I17: 3 | J17: 4 | K17: 5
A19: Bear: search share loss, AI capex earns little
A20: Revenue | B20: 565 | C20: 610 | D20: 650 | E20: 690 | F20: 725 | G20: =F20*(1+$F21+($L21-$F21)*G$17/5) -> 759.49529 | H20: =G20*(1+$F21+($L21-$F21)*H$17/5) -> 793.2433 | I20: =H20*(1+$F21+($L21-$F21)*I$17/5) -> 825.9962 | J20: =I20*(1+$F21+($L21-$F21)*J$17/5) -> 857.50376 | K20: =J20*(1+$F21+($L21-$F21)*K$17/5) -> 887.5164 | L20: =K20*(1+L21) -> 918.57947
A21: Revenue growth (terminal column = terminal growth, input) | B21: =B20/$B$12-1 -> 0.13090472 | C21: =C20/B20-1 -> 0.079646018 | D21: =D20/C20-1 -> 0.06557377 | E21: =E20/D20-1 -> 0.061538462 | F21: =F20/E20-1 -> 0.050724638 | G21: =G20/F20-1 -> 0.04757971 | H21: =H20/G20-1 -> 0.044434783 | I21: =I20/H20-1 -> 0.041289855 | J21: =J20/I20-1 -> 0.038144928 | K21: =K20/J20-1 -> 0.035 | L21: 0.035
A22: Operating margin | B22: 0.3 | C22: 0.29 | D22: 0.29 | E22: 0.29 | F22: 0.29 | G22: =$F22+($L22-$F22)*G$17/5 -> 0.286 | H22: =$F22+($L22-$F22)*H$17/5 -> 0.282 | I22: =$F22+($L22-$F22)*I$17/5 -> 0.278 | J22: =$F22+($L22-$F22)*J$17/5 -> 0.274 | K22: =$F22+($L22-$F22)*K$17/5 -> 0.27 | L22: 0.27
A23: Operating income | B23: =B20*B22 -> 169.5 | C23: =C20*C22 -> 176.9 | D23: =D20*D22 -> 188.5 | E23: =E20*E22 -> 200.1 | F23: =F20*F22 -> 210.25 | G23: =G20*G22 -> 217.21565 | H23: =H20*H22 -> 223.69461 | I23: =I20*I22 -> 229.62694 | ... L23: =L20*L22 -> 248.01646
A24: NOPAT | B24: =B23*(1-$B$9) -> 140.685 | C24: =C23*(1-$B$9) -> 146.827 | D24: =D23*(1-$B$9) -> 156.455 | E24: =E23*(1-$B$9) -> 166.083 | F24: =F23*(1-$B$9) -> 174.5075 | G24: =G23*(1-$B$9) -> 180.28899 | H24: =H23*(1-$B$9) -> 185.66653 | I24: =I23*(1-$B$9) -> 190.59036 | ... L24: =L23*(1-$B$9) -> 205.85366
A25: Net reinvestment, % of revenue | B25: 0.24 | C25: 0.19 | D25: 0.14 | E25: 0.11 | F25: 0.09 | G25: =$F25+($L25-$F25)*G$17/5 -> 0.084 | H25: =$F25+($L25-$F25)*H$17/5 -> 0.078 | I25: =$F25+($L25-$F25)*I$17/5 -> 0.072 | J25: =$F25+($L25-$F25)*J$17/5 -> 0.066 | K25: =$F25+($L25-$F25)*K$17/5 -> 0.06 | L25: 0.06
A26: Net reinvestment | B26: =B20*B25 -> 135.6 | C26: =C20*C25 -> 115.9 | D26: =D20*D25 -> 91 | E26: =E20*E25 -> 75.9 | F26: =F20*F25 -> 65.25 | G26: =G20*G25 -> 63.797604 | H26: =H20*H25 -> 61.872977 | I26: =I20*I25 -> 59.471726 | ... L26: =L20*L25 -> 55.114768
A27: Change in working capital | B27: =$B$11*(B20-$B$12) -> 0 | C27: =$B$11*(C20-B20) -> 0 | D27: =$B$11*(D20-C20) -> 0 | E27: =$B$11*(E20-D20) -> 0 | F27: =$B$11*(F20-E20) -> 0 | G27: =$B$11*(G20-F20) -> 0 | H27: =$B$11*(H20-G20) -> 0 | I27: =$B$11*(I20-H20) -> 0 | J27: =$B$11*(J20-I20) -> 0 | ... L27: =$B$11*(L20-K20) -> 0
A28: Free cash flow | B28: =B24-B26-B27 -> 5.085 | C28: =C24-C26-C27 -> 30.927 | D28: =D24-D26-D27 -> 65.455 | E28: =E24-E26-E27 -> 90.183 | F28: =F24-F26-F27 -> 109.2575 | G28: =G24-G26-G27 -> 116.49139 | H28: =H24-H26-H27 -> 123.79355 | I28: =I24-I26-I27 -> 131.11864 | ... L28: =L24-L26-L27 -> 150.73889
A29: Discount factor | B29: =1/(1+$B$10)^B$16 -> 0.95563697 | C29: =1/(1+$B$10)^C$16 -> 0.87272782 | D29: =1/(1+$B$10)^D$16 -> 0.79701171 | E29: =1/(1+$B$10)^E$16 -> 0.72786458 | F29: =1/(1+$B$10)^F$16 -> 0.66471651 | G29: =1/(1+$B$10)^G$16 -> 0.60704704 | H29: =1/(1+$B$10)^H$16 -> 0.55438086 | I29: =1/(1+$B$10)^I$16 -> 0.50628389 | ... K29: =1/(1+$B$10)^K$16 -> 0.42224631
A30: PV of free cash flow | B30: =B28*B29 -> 4.859414 | C30: =C28*C29 -> 26.990853 | D30: =D28*D29 -> 52.168401 | E30: =E28*E29 -> 65.641011 | F30: =F28*F29 -> 72.625264 | G30: =G28*G29 -> 70.715752 | H30: =H28*H29 -> 68.628774 | I30: =I28*I29 -> 66.383253 | ... K30: =K28*K29 -> 61.496562
A31: Terminal value | B31: =L28/($B$10-L21) -> 2512.3148 | C31: =IF($B$10>L21,"","Discount rate must exceed terminal growth")
A32: PV of terminal value | B32: =B31/(1+$B$10)^$K$16 -> 1060.8157
A33: Equity value (PV FCF + PV TV + net cash + other) | B33: =SUM(B30:K30)+B32+$B$7+$B$8 -> 1736.004
A34: Value per share ($) | B34: =B33/$B$6 -> 141.94636
A35: Value vs share price | B35: =B34/$B$4-1 -> -0.55706818
A37: Base: Cloud and Search grow, capex peaks 2027
A38: Revenue | B38: 600 | C38: 690 | D38: 770 | E38: 845 | F38: 915 | G38: =F38*(1+$F39+($L39-$F39)*G$17/5) -> 982.95905 | H38: =G38*(1+$F39+($L39-$F39)*H$17/5) -> 1047.5435 | I38: =H38*(1+$F39+($L39-$F39)*I$17/5) -> 1107.3961 | J38: =I38*(1+$F39+($L39-$F39)*J$17/5) -> 1161.1801 | K38: =J38*(1+$F39+($L39-$F39)*K$17/5) -> 1207.6274 | L38: =K38*(1+L39) -> 1255.9324
A39: Revenue growth (terminal column = terminal growth, input) | B39: =B38/$B$12-1 -> 0.20096077 | C39: =C38/B38-1 -> 0.15 | D39: =D38/C38-1 -> 0.11594203 | E39: =E38/D38-1 -> 0.097402597 | F39: =F38/E38-1 -> 0.082840237 | G39: =G38/F38-1 -> 0.074272189 | H39: =H38/G38-1 -> 0.065704142 | I39: =I38/H38-1 -> 0.057136095 | J39: =J38/I38-1 -> 0.048568047 | K39: =K38/J38-1 -> 0.04 | L39: 0.04
A40: Operating margin | B40: 0.33 | C40: 0.335 | D40: 0.34 | E40: 0.34 | F40: 0.34 | G40: =$F40+($L40-$F40)*G$17/5 -> 0.336 | H40: =$F40+($L40-$F40)*H$17/5 -> 0.332 | I40: =$F40+($L40-$F40)*I$17/5 -> 0.328 | J40: =$F40+($L40-$F40)*J$17/5 -> 0.324 | K40: =$F40+($L40-$F40)*K$17/5 -> 0.32 | L40: 0.32
A41: Operating income | B41: =B38*B40 -> 198 | C41: =C38*C40 -> 231.15 | D41: =D38*D40 -> 261.8 | E41: =E38*E40 -> 287.3 | F41: =F38*F40 -> 311.1 | G41: =G38*G40 -> 330.27424 | H41: =H38*H40 -> 347.78445 | I41: =I38*I40 -> 363.22591 | ... L41: =L38*L40 -> 401.89838
A42: NOPAT | B42: =B41*(1-$B$9) -> 164.34 | C42: =C41*(1-$B$9) -> 191.8545 | D42: =D41*(1-$B$9) -> 217.294 | E42: =E41*(1-$B$9) -> 238.459 | F42: =F41*(1-$B$9) -> 258.213 | G42: =G41*(1-$B$9) -> 274.12762 | H42: =H41*(1-$B$9) -> 288.6611 | I42: =I41*(1-$B$9) -> 301.47751 | ... L42: =L41*(1-$B$9) -> 333.57566
A43: Net reinvestment, % of revenue | B43: 0.22 | C43: 0.17 | D43: 0.13 | E43: 0.1 | F43: 0.08 | G43: =$F43+($L43-$F43)*G$17/5 -> 0.076 | H43: =$F43+($L43-$F43)*H$17/5 -> 0.072 | I43: =$F43+($L43-$F43)*I$17/5 -> 0.068 | J43: =$F43+($L43-$F43)*J$17/5 -> 0.064 | K43: =$F43+($L43-$F43)*K$17/5 -> 0.06 | L43: 0.06
A44: Net reinvestment | B44: =B38*B43 -> 132 | C44: =C38*C43 -> 117.3 | D44: =D38*D43 -> 100.1 | E44: =E38*E43 -> 84.5 | F44: =F38*F43 -> 73.2 | G44: =G38*G43 -> 74.704888 | H44: =H38*H43 -> 75.423134 | I44: =I38*I43 -> 75.302934 | ... L44: =L38*L43 -> 75.355947
...

Sheet UNH
A1: UnitedHealth (UNH): 10-year scenario DCF
A2: Units: $ billions unless noted. Blue = input, black = formula, green = link, yellow = key lever. Years 6 to 10 fade growth, margin and reinvestment toward each scenario's terminal levels.
A4: Share price ($) | B4: 423.39 | C4: Oct 23, 2026 intraday (Yahoo Finance via the site's price feed)
A5: Price date | B5: Oct 23, 2026 | C5: Text
A6: Shares outstanding (billions) | B6: 0.89759 | C6: Stock Analysis statistics, Oct 23, 2026
A7: Net cash, negative = net debt | B7: -48.49 | C7: Stock Analysis statistics, Oct 23, 2026: cash less total debt
A8: Other non-operating assets, less outside claims | B8: 0 | C8: None
A9: Tax rate | B9: 0.22 | C9: Analyst assumption (normalized, near the reported effective rate)
A10: Discount rate (WACC), from WACC tab | B10: =WACC!E29 -> 0.09 | C10: Calculated or assumed, per the switch in WACC!B5
A11: Working capital, % of revenue change | B11: 0 | C11: Analyst assumption
A12: Base-year revenue (2026E) | B12: 448.7 | C12: 2026E consensus $448.7B (Stock Analysis)
A13: Selected scenario (1 Bear, 2 Base, 3 Bull) | B13: 2 | C13: Lever
A15: Year | B15: 2027 | C15: 2028 | D15: 2029 | E15: 2030 | F15: 2031 | G15: 2032 | H15: 2033 | I15: 2034 | J15: 2035 | K15: 2036 | L15: Terminal
A16: Discount period (years, mid-year) | B16: 0.5 | C16: =B16+1 -> 1.5 | D16: =C16+1 -> 2.5 | E16: =D16+1 -> 3.5 | F16: =E16+1 -> 4.5 | G16: =F16+1 -> 5.5 | H16: =G16+1 -> 6.5 | I16: =H16+1 -> 7.5 | J16: =I16+1 -> 8.5 | K16: =J16+1 -> 9.5
A17: Fade step (years 6 to 10) | B17: 0 | C17: 0 | D17: 0 | E17: 0 | F17: 0 | G17: 1 | H17: 2 | I17: 3 | J17: 4 | K17: 5
A19: Bear: margins stay near trough, policy pressure
A20: Revenue | B20: 455 | C20: 470 | D20: 488 | E20: 506 | F20: 525 | G20: =F20*(1+$F21+($L21-$F21)*G$17/5) -> 543.92075 | H20: =G20*(1+$F21+($L21-$F21)*H$17/5) -> 562.70214 | I20: =H20*(1+$F21+($L21-$F21)*I$17/5) -> 581.28243 | J20: =I20*(1+$F21+($L21-$F21)*J$17/5) -> 599.59857 | K20: =J20*(1+$F21+($L21-$F21)*K$17/5) -> 617.58653 | L20: =K20*(1+L21) -> 636.11413
A21: Revenue growth (terminal column = terminal growth, input) | B21: =B20/$B$12-1 -> 0.014040562 | C21: =C20/B20-1 -> 0.032967033 | D21: =D20/C20-1 -> 0.038297872 | E21: =E20/D20-1 -> 0.036885246 | F21: =F20/E20-1 -> 0.037549407 | G21: =G20/F20-1 -> 0.036039526 | H21: =H20/G20-1 -> 0.034529644 | I21: =I20/H20-1 -> 0.033019763 | J21: =J20/I20-1 -> 0.031509881 | K21: =K20/J20-1 -> 0.03 | L21: 0.03
A22: Operating margin | B22: 0.054 | C22: 0.054 | D22: 0.055 | E22: 0.056 | F22: 0.057 | G22: =$F22+($L22-$F22)*G$17/5 -> 0.0568 | H22: =$F22+($L22-$F22)*H$17/5 -> 0.0566 | I22: =$F22+($L22-$F22)*I$17/5 -> 0.0564 | J22: =$F22+($L22-$F22)*J$17/5 -> 0.0562 | K22: =$F22+($L22-$F22)*K$17/5 -> 0.056 | L22: 0.056
A23: Operating income | B23: =B20*B22 -> 24.57 | C23: =C20*C22 -> 25.38 | D23: =D20*D22 -> 26.84 | E23: =E20*E22 -> 28.336 | F23: =F20*F22 -> 29.925 | G23: =G20*G22 -> 30.894699 | H23: =H20*H22 -> 31.848941 | I23: =I20*I22 -> 32.784329 | ... L23: =L20*L22 -> 35.622391
A24: NOPAT | B24: =B23*(1-$B$9) -> 19.1646 | C24: =C23*(1-$B$9) -> 19.7964 | D24: =D23*(1-$B$9) -> 20.9352 | E24: =E23*(1-$B$9) -> 22.10208 | F24: =F23*(1-$B$9) -> 23.3415 | G24: =G23*(1-$B$9) -> 24.097865 | H24: =H23*(1-$B$9) -> 24.842174 | I24: =I23*(1-$B$9) -> 25.571777 | ... L24: =L23*(1-$B$9) -> 27.785465
A25: Net reinvestment, % of revenue | B25: 0.004 | C25: 0.004 | D25: 0.004 | E25: 0.004 | F25: 0.004 | G25: =$F25+($L25-$F25)*G$17/5 -> 0.004 | H25: =$F25+($L25-$F25)*H$17/5 -> 0.004 | I25: =$F25+($L25-$F25)*I$17/5 -> 0.004 | J25: =$F25+($L25-$F25)*J$17/5 -> 0.004 | K25: =$F25+($L25-$F25)*K$17/5 -> 0.004 | L25: 0.004
A26: Net reinvestment | B26: =B20*B25 -> 1.82 | C26: =C20*C25 -> 1.88 | D26: =D20*D25 -> 1.952 | E26: =E20*E25 -> 2.024 | F26: =F20*F25 -> 2.1 | G26: =G20*G25 -> 2.175683 | H26: =H20*H25 -> 2.2508086 | I26: =I20*I25 -> 2.3251297 | ... L26: =L20*L25 -> 2.5444565
A27: Change in working capital | B27: =$B$11*(B20-$B$12) -> 0 | C27: =$B$11*(C20-B20) -> 0 | D27: =$B$11*(D20-C20) -> 0 | E27: =$B$11*(E20-D20) -> 0 | F27: =$B$11*(F20-E20) -> 0 | G27: =$B$11*(G20-F20) -> 0 | H27: =$B$11*(H20-G20) -> 0 | I27: =$B$11*(I20-H20) -> 0 | J27: =$B$11*(J20-I20) -> 0 | ... L27: =$B$11*(L20-K20) -> 0
A28: Free cash flow | B28: =B24-B26-B27 -> 17.3446 | C28: =C24-C26-C27 -> 17.9164 | D28: =D24-D26-D27 -> 18.9832 | E28: =E24-E26-E27 -> 20.07808 | F28: =F24-F26-F27 -> 21.2415 | G28: =G24-G26-G27 -> 21.922182 | H28: =H24-H26-H27 -> 22.591366 | I28: =I24-I26-I27 -> 23.246647 | ... L28: =L24-L26-L27 -> 25.241009
A29: Discount factor | B29: =1/(1+$B$10)^B$16 -> 0.95782629 | C29: =1/(1+$B$10)^C$16 -> 0.87873971 | D29: =1/(1+$B$10)^D$16 -> 0.80618322 | E29: =1/(1+$B$10)^E$16 -> 0.73961763 | F29: =1/(1+$B$10)^F$16 -> 0.67854829 | G29: =1/(1+$B$10)^G$16 -> 0.62252137 | H29: =1/(1+$B$10)^H$16 -> 0.57112052 | I29: =1/(1+$B$10)^I$16 -> 0.52396378 | ... K29: =1/(1+$B$10)^K$16 -> 0.44100983
A30: PV of free cash flow | B30: =B28*B29 -> 16.613114 | C30: =C28*C29 -> 15.743852 | D30: =D28*D29 -> 15.303937 | E30: =E28*E29 -> 14.850102 | F30: =F28*F29 -> 14.413383 | G30: =G28*G29 -> 13.647027 | H30: =H28*H29 -> 12.902392 | I30: =I28*I29 -> 12.180401 | ... K30: =K28*K29 -> 10.807313
A31: Terminal value | B31: =L28/($B$10-L21) -> 420.68348 | C31: =IF($B$10>L21,"","Discount rate must exceed terminal growth")
A32: PV of terminal value | B32: =B31/(1+$B$10)^$K$16 -> 185.52555
A33: Equity value (PV FCF + PV TV + net cash + other) | B33: =SUM(B30:K30)+B32+$B$7+$B$8 -> 274.9789
A34: Value per share ($) | B34: =B33/$B$6 -> 306.35245
A35: Value vs share price | B35: =B34/$B$4-1 -> -0.27642964
A37: Base: margins repair partway, to about 6.5%
A38: Revenue | B38: 463 | C38: 485 | D38: 510 | E38: 536 | F38: 563 | G38: =F38*(1+$F39+($L39-$F39)*G$17/5) -> 590.19206 | H38: =G38*(1+$F39+($L39-$F39)*H$17/5) -> 617.47303 | I38: =H38*(1+$F39+($L39-$F39)*I$17/5) -> 644.734 | J38: =I38*(1+$F39+($L39-$F39)*J$17/5) -> 671.86094 | K38: =J38*(1+$F39+($L39-$F39)*K$17/5) -> 698.73538 | L38: =K38*(1+L39) -> 726.6848
A39: Revenue growth (terminal column = terminal growth, input) | B39: =B38/$B$12-1 -> 0.031869846 | C39: =C38/B38-1 -> 0.047516199 | D39: =D38/C38-1 -> 0.051546392 | E39: =E38/D38-1 -> 0.050980392 | F39: =F38/E38-1 -> 0.050373134 | G39: =G38/F38-1 -> 0.048298507 | H39: =H38/G38-1 -> 0.046223881 | I39: =I38/H38-1 -> 0.044149254 | J39: =J38/I38-1 -> 0.042074627 | K39: =K38/J38-1 -> 0.04 | L39: 0.04
A40: Operating margin | B40: 0.06 | C40: 0.063 | D40: 0.065 | E40: 0.066 | F40: 0.067 | G40: =$F40+($L40-$F40)*G$17/5 -> 0.0666 | H40: =$F40+($L40-$F40)*H$17/5 -> 0.0662 | I40: =$F40+($L40-$F40)*I$17/5 -> 0.0658 | J40: =$F40+($L40-$F40)*J$17/5 -> 0.0654 | K40: =$F40+($L40-$F40)*K$17/5 -> 0.065 | L40: 0.065
A41: Operating income | B41: =B38*B40 -> 27.78 | C41: =C38*C40 -> 30.555 | D41: =D38*D40 -> 33.15 | E41: =E38*E40 -> 35.376 | F41: =F38*F40 -> 37.721 | G41: =G38*G40 -> 39.306791 | H41: =H38*H40 -> 40.876714 | I41: =I38*I40 -> 42.423497 | ... L41: =L38*L40 -> 47.234512
A42: NOPAT | B42: =B41*(1-$B$9) -> 21.6684 | C42: =C41*(1-$B$9) -> 23.8329 | D42: =D41*(1-$B$9) -> 25.857 | E42: =E41*(1-$B$9) -> 27.59328 | F42: =F41*(1-$B$9) -> 29.42238 | G42: =G41*(1-$B$9) -> 30.659297 | H42: =H41*(1-$B$9) -> 31.883837 | I42: =I41*(1-$B$9) -> 33.090328 | ... L42: =L41*(1-$B$9) -> 36.842919
A43: Net reinvestment, % of revenue | B43: 0.004 | C43: 0.004 | D43: 0.004 | E43: 0.004 | F43: 0.004 | G43: =$F43+($L43-$F43)*G$17/5 -> 0.004 | H43: =$F43+($L43-$F43)*H$17/5 -> 0.004 | I43: =$F43+($L43-$F43)*I$17/5 -> 0.004 | J43: =$F43+($L43-$F43)*J$17/5 -> 0.004 | K43: =$F43+($L43-$F43)*K$17/5 -> 0.004 | L43: 0.004
A44: Net reinvestment | B44: =B38*B43 -> 1.852 | C44: =C38*C43 -> 1.94 | D44: =D38*D43 -> 2.04 | E44: =E38*E43 -> 2.144 | F44: =F38*F43 -> 2.252 | G44: =G38*G43 -> 2.3607682 | H44: =H38*H43 -> 2.4698921 | I44: =I38*I43 -> 2.578936 | ... L44: =L38*L43 -> 2.9067392
...

Sheet LNG
A1: Cheniere Energy (LNG): 10-year scenario DCF
A2: Units: $ billions unless noted. Blue = input, black = formula, green = link, yellow = key lever. Years 6 to 10 fade growth, margin and reinvestment toward each scenario's terminal levels.
A4: Share price ($) | B4: 297.605 | C4: Oct 23, 2026 intraday (Yahoo Finance via the site's price feed)
A5: Price date | B5: Oct 23, 2026 | C5: Text
A6: Shares outstanding (billions) | B6: 0.20653 | C6: Stock Analysis statistics, Oct 23, 2026
A7: Net cash, negative = net debt | B7: -26.85 | C7: Stock Analysis statistics, Oct 23, 2026: cash less total debt
A8: Other non-operating assets, less outside claims | B8: -15.82 | C8: Less public share of CQP: about 51.4% of CQP market cap $30.77B (Stock Analysis, Oct 16, 2026)
A9: Tax rate | B9: 0.18 | C9: Analyst assumption (normalized, near the reported effective rate)
A10: Discount rate (WACC), from WACC tab | B10: =WACC!F29 -> 0.075 | C10: Calculated or assumed, per the switch in WACC!B5
A11: Working capital, % of revenue change | B11: 0 | C11: Analyst assumption
A12: Base-year revenue (2026E) | B12: 22.6 | C12: 2026E consensus $22.6B (Stock Analysis). Revenue swings with gas prices; margin is the lever
A13: Selected scenario (1 Bear, 2 Base, 3 Bull) | B13: 2 | C13: Lever
A15: Year | B15: 2027 | C15: 2028 | D15: 2029 | E15: 2030 | F15: 2031 | G15: 2032 | H15: 2033 | I15: 2034 | J15: 2035 | K15: 2036 | L15: Terminal
A16: Discount period (years, mid-year) | B16: 0.5 | C16: =B16+1 -> 1.5 | D16: =C16+1 -> 2.5 | E16: =D16+1 -> 3.5 | F16: =E16+1 -> 4.5 | G16: =F16+1 -> 5.5 | H16: =G16+1 -> 6.5 | I16: =H16+1 -> 7.5 | J16: =I16+1 -> 8.5 | K16: =J16+1 -> 9.5
A17: Fade step (years 6 to 10) | B17: 0 | C17: 0 | D17: 0 | E17: 0 | F17: 0 | G17: 1 | H17: 2 | I17: 3 | J17: 4 | K17: 5
A19: Bear: LNG glut from 2027, weaker spot margins
A20: Revenue | B20: 21 | C20: 20.5 | D20: 21.5 | E20: 22.5 | F20: 23.5 | G20: =F20*(1+$F21+($L21-$F21)*G$17/5) -> 24.359056 | H20: =G20*(1+$F21+($L21-$F21)*H$17/5) -> 25.057348 | I20: =H20*(1+$F21+($L21-$F21)*I$17/5) -> 25.577984 | J20: =I20*(1+$F21+($L21-$F21)*J$17/5) -> 25.907656 | K20: =J20*(1+$F21+($L21-$F21)*K$17/5) -> 26.037195 | L20: =K20*(1+L21) -> 26.167381
A21: Revenue growth (terminal column = terminal growth, input) | B21: =B20/$B$12-1 -> -0.07079646 | C21: =C20/B20-1 -> -0.023809524 | D21: =D20/C20-1 -> 0.048780488 | E21: =E20/D20-1 -> 0.046511628 | F21: =F20/E20-1 -> 0.044444444 | G21: =G20/F20-1 -> 0.036555556 | H21: =H20/G20-1 -> 0.028666667 | I21: =I20/H20-1 -> 0.020777778 | J21: =J20/I20-1 -> 0.012888889 | K21: =K20/J20-1 -> 0.005 | L21: 0.005
A22: Operating margin | B22: 0.29 | C22: 0.28 | D22: 0.28 | E22: 0.28 | F22: 0.28 | G22: =$F22+($L22-$F22)*G$17/5 -> 0.278 | H22: =$F22+($L22-$F22)*H$17/5 -> 0.276 | I22: =$F22+($L22-$F22)*I$17/5 -> 0.274 | J22: =$F22+($L22-$F22)*J$17/5 -> 0.272 | K22: =$F22+($L22-$F22)*K$17/5 -> 0.27 | L22: 0.27
A23: Operating income | B23: =B20*B22 -> 6.09 | C23: =C20*C22 -> 5.74 | D23: =D20*D22 -> 6.02 | E23: =E20*E22 -> 6.3 | F23: =F20*F22 -> 6.58 | G23: =G20*G22 -> 6.7718174 | H23: =H20*H22 -> 6.9158282 | I23: =I20*I22 -> 7.0083678 | ... L23: =L20*L22 -> 7.0651927
A24: NOPAT | B24: =B23*(1-$B$9) -> 4.9938 | C24: =C23*(1-$B$9) -> 4.7068 | D24: =D23*(1-$B$9) -> 4.9364 | E24: =E23*(1-$B$9) -> 5.166 | F24: =F23*(1-$B$9) -> 5.3956 | G24: =G23*(1-$B$9) -> 5.5528903 | H24: =H23*(1-$B$9) -> 5.6709791 | I24: =I23*(1-$B$9) -> 5.7468616 | ... L24: =L23*(1-$B$9) -> 5.7934581
A25: Net reinvestment, % of revenue | B25: 0.08 | C25: 0.07 | D25: 0.05 | E25: 0.03 | F25: 0.02 | G25: =$F25+($L25-$F25)*G$17/5 -> 0.019 | H25: =$F25+($L25-$F25)*H$17/5 -> 0.018 | I25: =$F25+($L25-$F25)*I$17/5 -> 0.017 | J25: =$F25+($L25-$F25)*J$17/5 -> 0.016 | K25: =$F25+($L25-$F25)*K$17/5 -> 0.015 | L25: 0.015
A26: Net reinvestment | B26: =B20*B25 -> 1.68 | C26: =C20*C25 -> 1.435 | D26: =D20*D25 -> 1.075 | E26: =E20*E25 -> 0.675 | F26: =F20*F25 -> 0.47 | G26: =G20*G25 -> 0.46282206 | H26: =H20*H25 -> 0.45103227 | I26: =I20*I25 -> 0.43482574 | ... L26: =L20*L25 -> 0.39251071
A27: Change in working capital | B27: =$B$11*(B20-$B$12) -> 0 | C27: =$B$11*(C20-B20) -> 0 | D27: =$B$11*(D20-C20) -> 0 | E27: =$B$11*(E20-D20) -> 0 | F27: =$B$11*(F20-E20) -> 0 | G27: =$B$11*(G20-F20) -> 0 | H27: =$B$11*(H20-G20) -> 0 | I27: =$B$11*(I20-H20) -> 0 | J27: =$B$11*(J20-I20) -> 0 | ... L27: =$B$11*(L20-K20) -> 0
A28: Free cash flow | B28: =B24-B26-B27 -> 3.3138 | C28: =C24-C26-C27 -> 3.2718 | D28: =D24-D26-D27 -> 3.8614 | E28: =E24-E26-E27 -> 4.491 | F28: =F24-F26-F27 -> 4.9256 | G28: =G24-G26-G27 -> 5.0900682 | H28: =H24-H26-H27 -> 5.2199468 | I28: =I24-I26-I27 -> 5.3120358 | ... L28: =L24-L26-L27 -> 5.4009473
A29: Discount factor | B29: =1/(1+$B$10)^B$16 -> 0.96448564 | C29: =1/(1+$B$10)^C$16 -> 0.89719595 | D29: =1/(1+$B$10)^D$16 -> 0.83460088 | E29: =1/(1+$B$10)^E$16 -> 0.77637291 | F29: =1/(1+$B$10)^F$16 -> 0.72220736 | G29: =1/(1+$B$10)^G$16 -> 0.6718208 | H29: =1/(1+$B$10)^H$16 -> 0.62494958 | I29: =1/(1+$B$10)^I$16 -> 0.58134845 | ... K29: =1/(1+$B$10)^K$16 -> 0.50305977
A30: PV of free cash flow | B30: =B28*B29 -> 3.1961125 | C30: =C28*C29 -> 2.9354457 | D30: =D28*D29 -> 3.2227278 | E30: =E28*E29 -> 3.4866908 | F30: =F28*F29 -> 3.5573046 | G30: =G28*G29 -> 3.4196137 | H30: =H28*H29 -> 3.2622036 | I30: =I28*I29 -> 3.0881438 | ... K30: =K28*K29 -> 2.7034819
A31: Terminal value | B31: =L28/($B$10-L21) -> 77.156391 | C31: =IF($B$10>L21,"","Discount rate must exceed terminal growth")
A32: PV of terminal value | B32: =B31/(1+$B$10)^$K$16 -> 38.814276
A33: Equity value (PV FCF + PV TV + net cash + other) | B33: =SUM(B30:K30)+B32+$B$7+$B$8 -> 27.916752
A34: Value per share ($) | B34: =B33/$B$6 -> 135.17044
A35: Value vs share price | B35: =B34/$B$4-1 -> -0.54580587
A37: Base: expansions come online, contracts hold
A38: Revenue | B38: 23.4 | C38: 24.6 | D38: 25.8 | E38: 27.2 | F38: 28.6 | G38: =F38*(1+$F39+($L39-$F39)*G$17/5) -> 29.863447 | H38: =G38*(1+$F39+($L39-$F39)*H$17/5) -> 30.964881 | I38: =H38*(1+$F39+($L39-$F39)*I$17/5) -> 31.881077 | J38: =I38*(1+$F39+($L39-$F39)*J$17/5) -> 32.591838 | K38: =J38*(1+$F39+($L39-$F39)*K$17/5) -> 33.080716 | L38: =K38*(1+L39) -> 33.576926
A39: Revenue growth (terminal column = terminal growth, input) | B39: =B38/$B$12-1 -> 0.03539823 | C39: =C38/B38-1 -> 0.051282051 | D39: =D38/C38-1 -> 0.048780488 | E39: =E38/D38-1 -> 0.054263566 | F39: =F38/E38-1 -> 0.051470588 | G39: =G38/F38-1 -> 0.044176471 | H39: =H38/G38-1 -> 0.036882353 | I39: =I38/H38-1 -> 0.029588235 | J39: =J38/I38-1 -> 0.022294118 | K39: =K38/J38-1 -> 0.015 | L39: 0.015
A40: Operating margin | B40: 0.31 | C40: 0.31 | D40: 0.31 | E40: 0.31 | F40: 0.31 | G40: =$F40+($L40-$F40)*G$17/5 -> 0.306 | H40: =$F40+($L40-$F40)*H$17/5 -> 0.302 | I40: =$F40+($L40-$F40)*I$17/5 -> 0.298 | J40: =$F40+($L40-$F40)*J$17/5 -> 0.294 | K40: =$F40+($L40-$F40)*K$17/5 -> 0.29 | L40: 0.29
A41: Operating income | B41: =B38*B40 -> 7.254 | C41: =C38*C40 -> 7.626 | D41: =D38*D40 -> 7.998 | E41: =E38*E40 -> 8.432 | F41: =F38*F40 -> 8.866 | G41: =G38*G40 -> 9.1382148 | H41: =H38*H40 -> 9.3513941 | I41: =I38*I40 -> 9.5005611 | ... L41: =L38*L40 -> 9.7373086
A42: NOPAT | B42: =B41*(1-$B$9) -> 5.94828 | C42: =C41*(1-$B$9) -> 6.25332 | D42: =D41*(1-$B$9) -> 6.55836 | E42: =E41*(1-$B$9) -> 6.91424 | F42: =F41*(1-$B$9) -> 7.27012 | G42: =G41*(1-$B$9) -> 7.4933361 | H42: =H41*(1-$B$9) -> 7.6681432 | I42: =I41*(1-$B$9) -> 7.7904601 | ... L42: =L41*(1-$B$9) -> 7.9845931
A43: Net reinvestment, % of revenue | B43: 0.08 | C43: 0.07 | D43: 0.05 | E43: 0.03 | F43: 0.02 | G43: =$F43+($L43-$F43)*G$17/5 -> 0.019 | H43: =$F43+($L43-$F43)*H$17/5 -> 0.018 | I43: =$F43+($L43-$F43)*I$17/5 -> 0.017 | J43: =$F43+($L43-$F43)*J$17/5 -> 0.016 | K43: =$F43+($L43-$F43)*K$17/5 -> 0.015 | L43: 0.015
A44: Net reinvestment | B44: =B38*B43 -> 1.872 | C44: =C38*C43 -> 1.722 | D44: =D38*D43 -> 1.29 | E44: =E38*E43 -> 0.816 | F44: =F38*F43 -> 0.572 | G44: =G38*G43 -> 0.56740549 | H44: =H38*H43 -> 0.55736786 | I44: =I38*I43 -> 0.54197832 | ... L44: =L38*L43 -> 0.50365389
...

Sheet NOW
A1: ServiceNow (NOW): 10-year scenario DCF
A2: Units: $ billions unless noted. Blue = input, black = formula, green = link, yellow = key lever. Years 6 to 10 fade growth, margin and reinvestment toward each scenario's terminal levels.
A4: Share price ($) | B4: 156.84 | C4: Oct 23, 2026 intraday (Yahoo Finance via the site's price feed)
A5: Price date | B5: Oct 23, 2026 | C5: Text
A6: Shares outstanding (billions) | B6: 1.03 | C6: Stock Analysis statistics, Oct 23, 2026
A7: Net cash, negative = net debt | B7: -1.75 | C7: Stock Analysis statistics, Oct 23, 2026: cash less total debt
A8: Other non-operating assets, less outside claims | B8: 0 | C8: Long-term investments excluded (conservative)
A9: Tax rate | B9: 0.2 | C9: Analyst assumption (normalized, near the reported effective rate)
A10: Discount rate (WACC), from WACC tab | B10: =WACC!G29 -> 0.095 | C10: Calculated or assumed, per the switch in WACC!B5
A11: Working capital, % of revenue change | B11: -0.05 | C11: Analyst assumption
A12: Base-year revenue (2026E) | B12: 16.22 | C12: 2026E consensus $16.22B (Stock Analysis). Margins are after stock pay (GAAP-like), not the 31.5% non-GAAP figure
A13: Selected scenario (1 Bear, 2 Base, 3 Bull) | B13: 2 | C13: Lever
A15: Year | B15: 2027 | C15: 2028 | D15: 2029 | E15: 2030 | F15: 2031 | G15: 2032 | H15: 2033 | I15: 2034 | J15: 2035 | K15: 2036 | L15: Terminal
A16: Discount period (years, mid-year) | B16: 0.5 | C16: =B16+1 -> 1.5 | D16: =C16+1 -> 2.5 | E16: =D16+1 -> 3.5 | F16: =E16+1 -> 4.5 | G16: =F16+1 -> 5.5 | H16: =G16+1 -> 6.5 | I16: =H16+1 -> 7.5 | J16: =I16+1 -> 8.5 | K16: =J16+1 -> 9.5
A17: Fade step (years 6 to 10) | B17: 0 | C17: 0 | D17: 0 | E17: 0 | F17: 0 | G17: 1 | H17: 2 | I17: 3 | J17: 4 | K17: 5
A19: Bear: AI agents compress seat pricing
A20: Revenue | B20: 18.3 | C20: 20.3 | D20: 22.2 | E20: 24 | F20: 25.7 | G20: =F20*(1+$F21+($L21-$F21)*G$17/5) -> 27.336233 | H20: =G20*(1+$F21+($L21-$F21)*H$17/5) -> 28.880731 | I20: =H20*(1+$F21+($L21-$F21)*I$17/5) -> 30.305513 | J20: =I20*(1+$F21+($L21-$F21)*J$17/5) -> 31.583396 | K20: =J20*(1+$F21+($L21-$F21)*K$17/5) -> 32.688815 | L20: =K20*(1+L21) -> 33.832923
A21: Revenue growth (terminal column = terminal growth, input) | B21: =B20/$B$12-1 -> 0.12823674 | C21: =C20/B20-1 -> 0.10928962 | D21: =D20/C20-1 -> 0.093596059 | E21: =E20/D20-1 -> 0.081081081 | F21: =F20/E20-1 -> 0.070833333 | G21: =G20/F20-1 -> 0.063666667 | H21: =H20/G20-1 -> 0.0565 | I21: =I20/H20-1 -> 0.049333333 | J21: =J20/I20-1 -> 0.042166667 | K21: =K20/J20-1 -> 0.035 | L21: 0.035
A22: Operating margin | B22: 0.17 | C22: 0.18 | D22: 0.19 | E22: 0.2 | F22: 0.21 | G22: =$F22+($L22-$F22)*G$17/5 -> 0.214 | H22: =$F22+($L22-$F22)*H$17/5 -> 0.218 | I22: =$F22+($L22-$F22)*I$17/5 -> 0.222 | J22: =$F22+($L22-$F22)*J$17/5 -> 0.226 | K22: =$F22+($L22-$F22)*K$17/5 -> 0.23 | L22: 0.23
A23: Operating income | B23: =B20*B22 -> 3.111 | C23: =C20*C22 -> 3.654 | D23: =D20*D22 -> 4.218 | E23: =E20*E22 -> 4.8 | F23: =F20*F22 -> 5.397 | G23: =G20*G22 -> 5.8499539 | H23: =H20*H22 -> 6.2959993 | I23: =I20*I22 -> 6.7278239 | ... L23: =L20*L22 -> 7.7815723
A24: NOPAT | B24: =B23*(1-$B$9) -> 2.4888 | C24: =C23*(1-$B$9) -> 2.9232 | D24: =D23*(1-$B$9) -> 3.3744 | E24: =E23*(1-$B$9) -> 3.84 | F24: =F23*(1-$B$9) -> 4.3176 | G24: =G23*(1-$B$9) -> 4.6799631 | H24: =H23*(1-$B$9) -> 5.0367994 | I24: =I23*(1-$B$9) -> 5.3822591 | ... L24: =L23*(1-$B$9) -> 6.2252578
A25: Net reinvestment, % of revenue | B25: 0.03 | C25: 0.03 | D25: 0.03 | E25: 0.03 | F25: 0.03 | G25: =$F25+($L25-$F25)*G$17/5 -> 0.028 | H25: =$F25+($L25-$F25)*H$17/5 -> 0.026 | I25: =$F25+($L25-$F25)*I$17/5 -> 0.024 | J25: =$F25+($L25-$F25)*J$17/5 -> 0.022 | K25: =$F25+($L25-$F25)*K$17/5 -> 0.02 | L25: 0.02
A26: Net reinvestment | B26: =B20*B25 -> 0.549 | C26: =C20*C25 -> 0.609 | D26: =D20*D25 -> 0.666 | E26: =E20*E25 -> 0.72 | F26: =F20*F25 -> 0.771 | G26: =G20*G25 -> 0.76541453 | H26: =H20*H25 -> 0.75089899 | I26: =I20*I25 -> 0.72733232 | ... L26: =L20*L25 -> 0.67665846
A27: Change in working capital | B27: =$B$11*(B20-$B$12) -> -0.104 | C27: =$B$11*(C20-B20) -> -0.1 | D27: =$B$11*(D20-C20) -> -0.095 | E27: =$B$11*(E20-D20) -> -0.09 | F27: =$B$11*(F20-E20) -> -0.085 | G27: =$B$11*(G20-F20) -> -0.081811667 | H27: =$B$11*(H20-G20) -> -0.077224859 | I27: =$B$11*(I20-H20) -> -0.071239135 | J27: =$B$11*(J20-I20) -> -0.063894124 | ... L27: =$B$11*(L20-K20) -> -0.057205425
A28: Free cash flow | B28: =B24-B26-B27 -> 2.0438 | C28: =C24-C26-C27 -> 2.4142 | D28: =D24-D26-D27 -> 2.8034 | E28: =E24-E26-E27 -> 3.21 | F28: =F24-F26-F27 -> 3.6316 | G28: =G24-G26-G27 -> 3.9963603 | H28: =H24-H26-H27 -> 4.3631253 | I28: =I24-I26-I27 -> 4.726166 | ... L28: =L24-L26-L27 -> 5.6058048
A29: Discount factor | B29: =1/(1+$B$10)^B$16 -> 0.95563697 | C29: =1/(1+$B$10)^C$16 -> 0.87272782 | D29: =1/(1+$B$10)^D$16 -> 0.79701171 | E29: =1/(1+$B$10)^E$16 -> 0.72786458 | F29: =1/(1+$B$10)^F$16 -> 0.66471651 | G29: =1/(1+$B$10)^G$16 -> 0.60704704 | H29: =1/(1+$B$10)^H$16 -> 0.55438086 | I29: =1/(1+$B$10)^I$16 -> 0.50628389 | ... K29: =1/(1+$B$10)^K$16 -> 0.42224631
A30: PV of free cash flow | B30: =B28*B29 -> 1.9531308 | C30: =C28*C29 -> 2.1069395 | D30: =D28*D29 -> 2.2343426 | E30: =E28*E29 -> 2.3364453 | F30: =F28*F29 -> 2.4139845 | G30: =G28*G29 -> 2.4259787 | H30: =H28*H29 -> 2.4188331 | I30: =I28*I29 -> 2.3927817 | ... K30: =K28*K29 -> 2.2869859
A31: Terminal value | B31: =L28/($B$10-L21) -> 93.43008 | C31: =IF($B$10>L21,"","Discount rate must exceed terminal growth")
A32: PV of terminal value | B32: =B31/(1+$B$10)^$K$16 -> 39.450507
A33: Equity value (PV FCF + PV TV + net cash + other) | B33: =SUM(B30:K30)+B32+$B$7+$B$8 -> 60.61841
A34: Value per share ($) | B34: =B33/$B$6 -> 58.852825
A35: Value vs share price | B35: =B34/$B$4-1 -> -0.62475883
A37: Base: growth slows from 19% to 11%
A38: Revenue | B38: 19.2 | C38: 22.4 | D38: 25.8 | E38: 29.2 | F38: 32.6 | G38: =F38*(1+$F39+($L39-$F39)*G$17/5) -> 35.897512 | H38: =G38*(1+$F39+($L39-$F39)*H$17/5) -> 38.979781 | I38: =H38*(1+$F39+($L39-$F39)*I$17/5) -> 41.730792 | J38: =I38*(1+$F39+($L39-$F39)*J$17/5) -> 44.037991 | K38: =J38*(1+$F39+($L39-$F39)*K$17/5) -> 45.79951 | L38: =K38*(1+L39) -> 47.631491
