Workbook

Sheet Summary
A1: Optical Networking Company Pass: scenario values
A2: Values link to each company sheet (green). Switch the discount rate on the WACC tab.
A4: Company | B4: Share price | C4: Discount rate used | D4: Bear value | E4: Base value | F4: Bull value | G4: Bear vs price | H4: Base vs price | I4: Bull vs price | J4: Buy below
A5: Coherent (COHR) | B5: =COHR!B4 -> 234.86 | C5: =COHR!B9 -> 0.115 | D5: =COHR!B77 -> 38.400215 | E5: =COHR!B78 -> 111.67202 | F5: =COHR!B79 -> 182.04673 | G5: =D5/B5-1 -> -0.83649742 | H5: =E5/B5-1 -> -0.52451664 | I5: =F5/B5-1 -> -0.22487128 | J5: =COHR!B81 -> 111.67202
A6: Fabrinet (FN) | B6: =FN!B4 -> 355.48 | C6: =FN!B9 -> 0.1 | D6: =FN!B77 -> 169.40052 | E6: =FN!B78 -> 279.13684 | F6: =FN!B79 -> 387.98926 | G6: =D6/B6-1 -> -0.52345978 | H6: =E6/B6-1 -> -0.21476077 | I6: =F6/B6-1 -> 0.091451713 | J6: =FN!B81 -> 279.13684
A13: Notes
A14: Ten-year free cash flow DCF: five explicit years, then five years fading growth, margin and reinvestment toward terminal levels; not a three-statement model.
A15: FCF = operating income x (1 - tax) - net reinvestment (capex above depreciation) - working capital x revenue change. Mid-year discounting from October 2026.
A16: Scenario paths, margins, reinvestment, discount rates and terminal assumptions are analyst judgments. Bear cases assume an AI capex slowdown in 2027 to 2028.
A17: Implied returns quoted in the journal entry were solved outside the workbook; the rate sensitivity row on each sheet shows where base value crosses the price.
A18: Prices: Stock Analysis, Coherent Oct 21, 2026; Fabrinet Oct 20 close. Research for discussion, not investment advice.

Sheet WACC
A1: WACC build: calculated (CAPM) versus assumed
A2: Blue = input, black = formula, green = link. The yellow switches apply to both companies.
A5: WACC used in valuations (1 = Calculated, 2 = Assumed) | B5: 2 | C5: Switch. 2 reproduces the journal entry's figures
A6: Beta used (1 = Raw 5-year, 2 = Blume adjusted) | B6: 2 | C6: Blume adjusted = 0.67 x raw + 0.33
A7: Risk-free rate (10-year Treasury) | B7: 0.0531 | C7: FRED via MacroRadar, Oct 6, 2026
A8: Equity risk premium | B8: 0.05 | C8: Analyst assumption
A9: Credit spread over risk-free (pre-tax cost of debt) | B9: 0.012 | C9: Analyst assumption: investment-grade spread
A11: Item | B11: COHR | C11: FN | D11: Source / note
A12: Raw beta (5-year) | B12: 2.11 | C12: 1.22 | D12: Stock Analysis statistics, Oct 2026
A13: Adjusted beta | B13: =0.67*B12+0.33 -> 1.7437 | C13: =0.67*C12+0.33 -> 1.1474 | D13: Blume: 0.67 x raw + 0.33
A14: Beta used | B14: =IF($B$6=1,B12,B13) -> 1.7437 | C14: =IF($B$6=1,C12,C13) -> 1.1474 | D14: Per switch in B6
A15: Country risk premium | B15: 0 | C15: 0 | D15: Analyst assumption
A16: Cost of equity | B16: =$B$7+B14*$B$8+B15 -> 0.140285 | C16: =$B$7+C14*$B$8+C15 -> 0.11047 | D16: Risk-free + beta x ERP + country premium
A17: Pre-tax cost of debt | B17: =$B$7+$B$9+B15 -> 0.0651 | C17: =$B$7+$B$9+C15 -> 0.0651 | D17: Risk-free + spread + country premium
A18: Tax rate | B18: =COHR!B8 -> 0.15 | C18: =FN!B8 -> 0.08 | D18: Linked from company sheet
A19: After-tax cost of debt | B19: =B17*(1-B18) -> 0.055335 | C19: =C17*(1-C18) -> 0.059892
A20: Market value of equity (company units) | B20: =COHR!B4*COHR!B6/COHR!B13 -> 46.25098 | C20: =FN!B4*FN!B6/FN!B13 -> 12.903924 | D20: Price x shares
A21: Debt (company units) | B21: 3.55 | C21: 0.004 | D21: Stock Analysis, total debt
A22: Equity weight | B22: =B20/(B20+B21) -> 0.92871626 | C22: =C20/(C20+C21) -> 0.99969011
A23: Debt weight | B23: =B21/(B20+B21) -> 0.071283738 | C23: =C21/(C20+C21) -> 0.00030988717
A24: Calculated WACC (CAPM) | B24: =B22*B16+B23*B19 -> 0.13422945 | C24: =C22*C16+C23*C19 -> 0.11045433 | D24: Weighted cost of capital
A25: Assumed WACC | B25: 0.115 | C25: 0.1 | D25: Analyst assumption used in the journal entry
A26: WACC used | B26: =IF($B$5=1,B24,B25) -> 0.115 | C26: =IF($B$5=1,C24,C25) -> 0.1 | D26: Per switch in B5; feeds each sheet's B9
A27: Check: WACC above terminal growth | B27: =IF(B26>COHR!B10,"OK","WACC must exceed growth") -> OK | C27: =IF(C26>FN!B10,"OK","WACC must exceed growth") -> OK

Sheet COHR
A1: Coherent (COHR): 10-year scenario DCF
A2: Units: $B unless noted. Blue = input, black = formula, green = link, yellow = key lever. Years 6 to 10 fade growth, margin and reinvestment toward terminal levels.
A4: Share price | B4: 234.86 | C4: Source: Stock Analysis, Oct 21, 2026 11:34 ET
A5: Price date | B5: Oct 21, 2026 11:34 ET | C5: Text
A6: Shares outstanding (billions) | B6: 0.19693 | C6: Source: Stock Analysis, https://stockanalysis.com
A7: Net cash, negative = net debt ($B) | B7: -1.56 | C7: Stock Analysis: cash $1.99B less debt $3.55B
A8: Tax rate | B8: 0.15 | C8: Analyst assumption
A9: Discount rate (WACC), from WACC tab | B9: =WACC!B26 -> 0.115 | C9: Calculated or assumed, per switch in WACC!B5
A10: Terminal growth | B10: 0.04 | C10: Analyst assumption
A11: Working capital, % of revenue change | B11: 0.15 | C11: Analyst assumption
A12: Base-year revenue ($B) | B12: 7.118 | C12: FY26 (Jun 2026) revenue, Stock Analysis annual income statement. Margins about 2 pts below non-GAAP
A13: Per-share multiplier | B13: 1 | C13: Units conversion (1 here)
A14: Selected scenario (1 Bear, 2 Base, 3 Bull) | B14: 2 | C14: Lever
A16: Year | B16: FY27 | C16: FY28 | D16: FY29 | E16: FY30 | F16: FY31 | G16: FY32 | H16: FY33 | I16: FY34 | J16: FY35 | K16: FY36 | L16: Terminal
A17: Discount period (years, mid-year) | B17: 0.5 | C17: =B17+1 -> 1.5 | D17: =C17+1 -> 2.5 | E17: =D17+1 -> 3.5 | F17: =E17+1 -> 4.5 | G17: =F17+1 -> 5.5 | H17: =G17+1 -> 6.5 | I17: =H17+1 -> 7.5 | J17: =I17+1 -> 8.5 | K17: =J17+1 -> 9.5
A18: Fade step (years 6 to 10) | B18: 0 | C18: 0 | D18: 0 | E18: 0 | F18: 0 | G18: 1 | H18: 2 | I18: 3 | J18: 4 | K18: 5
A20: Bear: AI optics orders fall in FY28
A21: Revenue | B21: 9.2 | C21: 8 | D21: 8.3 | E21: 9 | F21: 9.8 | G21: =F21*(1+$F22+($B$10-$F22)*G$18/5) -> 10.575289 | H21: =G21*(1+$F22+($B$10-$F22)*H$18/5) -> 11.308509 | I21: =H21*(1+$F22+($B$10-$F22)*I$18/5) -> 11.981993 | J21: =I21*(1+$F22+($B$10-$F22)*J$18/5) -> 12.57843 | K21: =J21*(1+$F22+($B$10-$F22)*K$18/5) -> 13.081568 | L21: =K21*(1+$B$10) -> 13.60483
A22: Revenue growth | B22: =B21/$B$12-1 -> 0.29249789 | C22: =C21/B21-1 -> -0.13043478 | D22: =D21/C21-1 -> 0.0375 | E22: =E21/D21-1 -> 0.084337349 | F22: =F21/E21-1 -> 0.088888889 | G22: =G21/F21-1 -> 0.079111111 | H22: =H21/G21-1 -> 0.069333333 | I22: =I21/H21-1 -> 0.059555556 | J22: =J21/I21-1 -> 0.049777778 | ... L22: =L21/K21-1 -> 0.04
A23: Operating margin | B23: 0.18 | C23: 0.12 | D23: 0.12 | E23: 0.14 | F23: 0.15 | G23: =$F23+($L23-$F23)*G$18/5 -> 0.148 | H23: =$F23+($L23-$F23)*H$18/5 -> 0.146 | I23: =$F23+($L23-$F23)*I$18/5 -> 0.144 | J23: =$F23+($L23-$F23)*J$18/5 -> 0.142 | K23: =$F23+($L23-$F23)*K$18/5 -> 0.14 | L23: 0.14
A24: Operating income | B24: =B21*B23 -> 1.656 | C24: =C21*C23 -> 0.96 | D24: =D21*D23 -> 0.996 | E24: =E21*E23 -> 1.26 | F24: =F21*F23 -> 1.47 | G24: =G21*G23 -> 1.5651428 | H24: =H21*H23 -> 1.6510423 | I24: =I21*I23 -> 1.7254071 | ... L24: =L21*L23 -> 1.9046763
A25: NOPAT | B25: =B24*(1-$B$8) -> 1.4076 | C25: =C24*(1-$B$8) -> 0.816 | D25: =D24*(1-$B$8) -> 0.8466 | E25: =E24*(1-$B$8) -> 1.071 | F25: =F24*(1-$B$8) -> 1.2495 | G25: =G24*(1-$B$8) -> 1.3303713 | H25: =H24*(1-$B$8) -> 1.403386 | I25: =I24*(1-$B$8) -> 1.466596 | ... L25: =L24*(1-$B$8) -> 1.6189748
A26: Net reinvestment, % of revenue | B26: 0.12 | C26: 0.06 | D26: 0.04 | E26: 0.04 | F26: 0.04 | G26: =$F26+($L26-$F26)*G$18/5 -> 0.038 | H26: =$F26+($L26-$F26)*H$18/5 -> 0.036 | I26: =$F26+($L26-$F26)*I$18/5 -> 0.034 | J26: =$F26+($L26-$F26)*J$18/5 -> 0.032 | K26: =$F26+($L26-$F26)*K$18/5 -> 0.03 | L26: 0.03
A27: Net reinvestment | B27: =B21*B26 -> 1.104 | C27: =C21*C26 -> 0.48 | D27: =D21*D26 -> 0.332 | E27: =E21*E26 -> 0.36 | F27: =F21*F26 -> 0.392 | G27: =G21*G26 -> 0.40186098 | H27: =H21*H26 -> 0.40710632 | I27: =I21*I26 -> 0.40738778 | ... L27: =L21*L26 -> 0.40814491
A28: Change in working capital | B28: =$B$11*(B21-$B$12) -> 0.3123 | C28: =$B$11*(C21-B21) -> -0.18 | D28: =$B$11*(D21-C21) -> 0.045 | E28: =$B$11*(E21-D21) -> 0.105 | F28: =$B$11*(F21-E21) -> 0.12 | G28: =$B$11*(G21-F21) -> 0.11629333 | H28: =$B$11*(H21-G21) -> 0.109983 | I28: =$B$11*(I21-H21) -> 0.10102268 | J28: =$B$11*(J21-I21) -> 0.089465551 | ... L28: =$B$11*(L21-K21) -> 0.078489406
A29: Free cash flow | B29: =B25-B27-B28 -> -0.0087 | C29: =C25-C27-C28 -> 0.516 | D29: =D25-D27-D28 -> 0.4696 | E29: =E25-E27-E28 -> 0.606 | F29: =F25-F27-F28 -> 0.7375 | G29: =G25-G27-G28 -> 0.81221703 | H29: =H25-H27-H28 -> 0.88629663 | I29: =I25-I27-I28 -> 0.95818554 | ... L29: =L25-L27-L28 -> 1.1323405
A30: Discount factor | B30: =1/(1+$B$9)^B$17 -> 0.94702745 | C30: =1/(1+$B$9)^C$17 -> 0.84935197 | D30: =1/(1+$B$9)^D$17 -> 0.76175065 | E30: =1/(1+$B$9)^E$17 -> 0.68318444 | F30: =1/(1+$B$9)^F$17 -> 0.61272147 | G30: =1/(1+$B$9)^G$17 -> 0.54952598 | H30: =1/(1+$B$9)^H$17 -> 0.49284841 | I30: =1/(1+$B$9)^I$17 -> 0.44201651 | ... K30: =1/(1+$B$9)^K$17 -> 0.35554024
A31: PV of free cash flow | B31: =B29*B30 -> -0.0082391388 | C31: =C29*C30 -> 0.43826562 | D31: =D29*D30 -> 0.3577181 | E31: =E29*E30 -> 0.41400977 | F31: =F29*F30 -> 0.45188208 | G31: =G29*G30 -> 0.44633436 | H31: =H29*H30 -> 0.43680989 | I31: =I29*I30 -> 0.42353383 | ... K31: =K29*K30 -> 0.38710828
A32: Terminal value | B32: =L29/($B$9-$B$10) -> 15.097873
A33: PV of terminal value | B33: =B32/(1+$B$9)^$K$17 -> 5.3679015
A34: Equity value (PV FCF + PV TV + net cash) | B34: =SUM(B31:K31)+B33+$B$7 -> 7.5621544
A35: Value per share | B35: =B34/$B$6*$B$13 -> 38.400215
A36: Value vs share price | B36: =B35/$B$4-1 -> -0.83649742
A38: Base: near the $3B quarterly target, then slower
A39: Revenue | B39: 10.2 | C39: 12.5 | D39: 13 | E39: 14.5 | F39: 16 | G39: =F39*(1+$F40+($B$10-$F40)*G$18/5) -> 17.452138 | H39: =G39*(1+$F40+($B$10-$F40)*H$18/5) -> 18.814608 | I39: =H39*(1+$F40+($B$10-$F40)*I$18/5) -> 20.044694 | J39: =I39*(1+$F40+($B$10-$F40)*J$18/5) -> 21.100842 | K39: =J39*(1+$F40+($B$10-$F40)*K$18/5) -> 21.944876 | L39: =K39*(1+$B$10) -> 22.822671
A40: Revenue growth | B40: =B39/$B$12-1 -> 0.43298679 | C40: =C39/B39-1 -> 0.2254902 | D40: =D39/C39-1 -> 0.04 | E40: =E39/D39-1 -> 0.11538462 | F40: =F39/E39-1 -> 0.10344828 | G40: =G39/F39-1 -> 0.090758621 | H40: =H39/G39-1 -> 0.078068966 | I40: =I39/H39-1 -> 0.06537931 | J40: =J39/I39-1 -> 0.052689655 | ... L40: =L39/K39-1 -> 0.04
A41: Operating margin | B41: 0.2 | C41: 0.22 | D41: 0.2 | E41: 0.21 | F41: 0.21 | G41: =$F41+($L41-$F41)*G$18/5 -> 0.206 | H41: =$F41+($L41-$F41)*H$18/5 -> 0.202 | I41: =$F41+($L41-$F41)*I$18/5 -> 0.198 | J41: =$F41+($L41-$F41)*J$18/5 -> 0.194 | K41: =$F41+($L41-$F41)*K$18/5 -> 0.19 | L41: 0.19
A42: Operating income | B42: =B39*B41 -> 2.04 | C42: =C39*C41 -> 2.75 | D42: =D39*D41 -> 2.6 | E42: =E39*E41 -> 3.045 | F42: =F39*F41 -> 3.36 | G42: =G39*G41 -> 3.5951404 | H42: =H39*H41 -> 3.8005509 | I42: =I39*I41 -> 3.9688495 | ... L42: =L39*L41 -> 4.3363075
A43: NOPAT | B43: =B42*(1-$B$8) -> 1.734 | C43: =C42*(1-$B$8) -> 2.3375 | D43: =D42*(1-$B$8) -> 2.21 | E43: =E42*(1-$B$8) -> 2.58825 | F43: =F42*(1-$B$8) -> 2.856 | G43: =G42*(1-$B$8) -> 3.0558694 | H43: =H42*(1-$B$8) -> 3.2304682 | I43: =I42*(1-$B$8) -> 3.3735221 | ... L43: =L42*(1-$B$8) -> 3.6858614
A44: Net reinvestment, % of revenue | B44: 0.12 | C44: 0.08 | D44: 0.05 | E44: 0.04 | F44: 0.04 | G44: =$F44+($L44-$F44)*G$18/5 -> 0.038 | H44: =$F44+($L44-$F44)*H$18/5 -> 0.036 | I44: =$F44+($L44-$F44)*I$18/5 -> 0.034 | J44: =$F44+($L44-$F44)*J$18/5 -> 0.032 | K44: =$F44+($L44-$F44)*K$18/5 -> 0.03 | L44: 0.03
...

Sheet FN
A1: Fabrinet (FN): 10-year scenario DCF
A2: Units: $B unless noted. Blue = input, black = formula, green = link, yellow = key lever. Years 6 to 10 fade growth, margin and reinvestment toward terminal levels.
A4: Share price | B4: 355.48 | C4: Source: Stock Analysis, Oct 20, 2026 close
A5: Price date | B5: Oct 20, 2026 close | C5: Text
A6: Shares outstanding (billions) | B6: 0.0363 | C6: Diluted shares guided for FQ1 FY27 (Fabrinet 8-K, Aug 2026)
A7: Net cash, negative = net debt ($B) | B7: 0.871 | C7: Fabrinet 8-K: cash and short-term investments $875M; debt $4M (Stock Analysis)
A8: Tax rate | B8: 0.08 | C8: Analyst assumption
A9: Discount rate (WACC), from WACC tab | B9: =WACC!C26 -> 0.1 | C9: Calculated or assumed, per switch in WACC!B5
A10: Terminal growth | B10: 0.04 | C10: Analyst assumption
A11: Working capital, % of revenue change | B11: 0.15 | C11: Analyst assumption
A12: Base-year revenue ($B) | B12: 4.641 | C12: FY26 (Jun 2026) revenue, Stock Analysis annual income statement
A13: Per-share multiplier | B13: 1 | C13: Units conversion (1 here)
A14: Selected scenario (1 Bear, 2 Base, 3 Bull) | B14: 2 | C14: Lever
A16: Year | B16: FY27 | C16: FY28 | D16: FY29 | E16: FY30 | F16: FY31 | G16: FY32 | H16: FY33 | I16: FY34 | J16: FY35 | K16: FY36 | L16: Terminal
A17: Discount period (years, mid-year) | B17: 0.5 | C17: =B17+1 -> 1.5 | D17: =C17+1 -> 2.5 | E17: =D17+1 -> 3.5 | F17: =E17+1 -> 4.5 | G17: =F17+1 -> 5.5 | H17: =G17+1 -> 6.5 | I17: =H17+1 -> 7.5 | J17: =I17+1 -> 8.5 | K17: =J17+1 -> 9.5
A18: Fade step (years 6 to 10) | B18: 0 | C18: 0 | D18: 0 | E18: 0 | F18: 0 | G18: 1 | H18: 2 | I18: 3 | J18: 4 | K18: 5
A20: Bear: a top customer program lost plus AI slowdown
A21: Revenue | B21: 5.6 | C21: 4.8 | D21: 5 | E21: 5.5 | F21: 6 | G21: =F21*(1+$F22+($B$10-$F22)*G$18/5) -> 6.4843636 | H21: =G21*(1+$F22+($B$10-$F22)*H$18/5) -> 6.941806 | I21: =H21*(1+$F22+($B$10-$F22)*I$18/5) -> 7.3608387 | J21: =I21*(1+$F22+($B$10-$F22)*J$18/5) -> 7.7302189 | K21: =J21*(1+$F22+($B$10-$F22)*K$18/5) -> 8.0394277 | L21: =K21*(1+$B$10) -> 8.3610048
A22: Revenue growth | B22: =B21/$B$12-1 -> 0.2066365 | C22: =C21/B21-1 -> -0.14285714 | D22: =D21/C21-1 -> 0.041666667 | E22: =E21/D21-1 -> 0.1 | F22: =F21/E21-1 -> 0.090909091 | G22: =G21/F21-1 -> 0.080727273 | H22: =H21/G21-1 -> 0.070545455 | I22: =I21/H21-1 -> 0.060363636 | J22: =J21/I21-1 -> 0.050181818 | ... L22: =L21/K21-1 -> 0.04
A23: Operating margin | B23: 0.1 | C23: 0.085 | D23: 0.09 | E23: 0.095 | F23: 0.095 | G23: =$F23+($L23-$F23)*G$18/5 -> 0.094 | H23: =$F23+($L23-$F23)*H$18/5 -> 0.093 | I23: =$F23+($L23-$F23)*I$18/5 -> 0.092 | J23: =$F23+($L23-$F23)*J$18/5 -> 0.091 | K23: =$F23+($L23-$F23)*K$18/5 -> 0.09 | L23: 0.09
A24: Operating income | B24: =B21*B23 -> 0.56 | C24: =C21*C23 -> 0.408 | D24: =D21*D23 -> 0.45 | E24: =E21*E23 -> 0.5225 | F24: =F21*F23 -> 0.57 | G24: =G21*G23 -> 0.60953018 | H24: =H21*H23 -> 0.64558796 | I24: =I21*I23 -> 0.67719716 | ... L24: =L21*L23 -> 0.75249043
A25: NOPAT | B25: =B24*(1-$B$8) -> 0.5152 | C25: =C24*(1-$B$8) -> 0.37536 | D25: =D24*(1-$B$8) -> 0.414 | E25: =E24*(1-$B$8) -> 0.4807 | F25: =F24*(1-$B$8) -> 0.5244 | G25: =G24*(1-$B$8) -> 0.56076777 | H25: =H24*(1-$B$8) -> 0.59394092 | I25: =I24*(1-$B$8) -> 0.62302139 | ... L25: =L24*(1-$B$8) -> 0.6922912
A26: Net reinvestment, % of revenue | B26: 0.05 | C26: 0.025 | D26: 0.02 | E26: 0.02 | F26: 0.02 | G26: =$F26+($L26-$F26)*G$18/5 -> 0.02 | H26: =$F26+($L26-$F26)*H$18/5 -> 0.02 | I26: =$F26+($L26-$F26)*I$18/5 -> 0.02 | J26: =$F26+($L26-$F26)*J$18/5 -> 0.02 | K26: =$F26+($L26-$F26)*K$18/5 -> 0.02 | L26: 0.02
A27: Net reinvestment | B27: =B21*B26 -> 0.28 | C27: =C21*C26 -> 0.12 | D27: =D21*D26 -> 0.1 | E27: =E21*E26 -> 0.11 | F27: =F21*F26 -> 0.12 | G27: =G21*G26 -> 0.12968727 | H27: =H21*H26 -> 0.13883612 | I27: =I21*I26 -> 0.14721677 | ... L27: =L21*L26 -> 0.1672201
A28: Change in working capital | B28: =$B$11*(B21-$B$12) -> 0.14385 | C28: =$B$11*(C21-B21) -> -0.12 | D28: =$B$11*(D21-C21) -> 0.03 | E28: =$B$11*(E21-D21) -> 0.075 | F28: =$B$11*(F21-E21) -> 0.075 | G28: =$B$11*(G21-F21) -> 0.072654545 | H28: =$B$11*(H21-G21) -> 0.068616357 | I28: =$B$11*(I21-H21) -> 0.062854898 | J28: =$B$11*(J21-I21) -> 0.05540704 | ... L28: =$B$11*(L21-K21) -> 0.048236566
A29: Free cash flow | B29: =B25-B27-B28 -> 0.09135 | C29: =C25-C27-C28 -> 0.37536 | D29: =D25-D27-D28 -> 0.284 | E29: =E25-E27-E28 -> 0.2957 | F29: =F25-F27-F28 -> 0.3294 | G29: =G25-G27-G28 -> 0.35842595 | H29: =H25-H27-H28 -> 0.38648845 | I29: =I25-I27-I28 -> 0.41294971 | ... L29: =L25-L27-L28 -> 0.47683454
A30: Discount factor | B30: =1/(1+$B$9)^B$17 -> 0.95346259 | C30: =1/(1+$B$9)^C$17 -> 0.86678417 | D30: =1/(1+$B$9)^D$17 -> 0.78798561 | E30: =1/(1+$B$9)^E$17 -> 0.71635056 | F30: =1/(1+$B$9)^F$17 -> 0.65122778 | G30: =1/(1+$B$9)^G$17 -> 0.59202525 | H30: =1/(1+$B$9)^H$17 -> 0.53820477 | I30: =1/(1+$B$9)^I$17 -> 0.48927707 | ... K30: =1/(1+$B$9)^K$17 -> 0.40436121
A31: PV of free cash flow | B31: =B29*B30 -> 0.087098808 | C31: =C29*C30 -> 0.32535611 | D31: =D29*D30 -> 0.22378791 | E31: =E29*E30 -> 0.21182486 | F31: =F29*F30 -> 0.21451443 | G31: =G29*G30 -> 0.21219721 | H31: =H29*H30 -> 0.20800993 | I31: =I29*I30 -> 0.20204683 | ... K31: =K29*K30 -> 0.18539749
A32: Terminal value | B32: =L29/($B$9-$B$10) -> 7.9472423
A33: PV of terminal value | B33: =B32/(1+$B$9)^$K$17 -> 3.2135565
A34: Equity value (PV FCF + PV TV + net cash) | B34: =SUM(B31:K31)+B33+$B$7 -> 6.1492388
A35: Value per share | B35: =B34/$B$6*$B$13 -> 169.40052
A36: Value vs share price | B36: =B35/$B$4-1 -> -0.52345978
A38: Base: Building 10 fills, growth slows after FY28
A39: Revenue | B39: 6.2 | C39: 7.8 | D39: 8.2 | E39: 9.2 | F39: 10.2 | G39: =F39*(1+$F40+($B$10-$F40)*G$18/5) -> 11.168557 | H39: =G39*(1+$F40+($B$10-$F40)*H$18/5) -> 12.075638 | I39: =H39*(1+$F40+($B$10-$F40)*I$18/5) -> 12.890481 | J39: =I39*(1+$F40+($B$10-$F40)*J$18/5) -> 13.583204 | K39: =J39*(1+$F40+($B$10-$F40)*K$18/5) -> 14.126532 | L39: =K39*(1+$B$10) -> 14.691593
A40: Revenue growth | B40: =B39/$B$12-1 -> 0.33591898 | C40: =C39/B39-1 -> 0.25806452 | D40: =D39/C39-1 -> 0.051282051 | E40: =E39/D39-1 -> 0.12195122 | F40: =F39/E39-1 -> 0.10869565 | G40: =G39/F39-1 -> 0.094956522 | H40: =H39/G39-1 -> 0.081217391 | I40: =I39/H39-1 -> 0.067478261 | J40: =J39/I39-1 -> 0.05373913 | ... L40: =L39/K39-1 -> 0.04
A41: Operating margin | B41: 0.105 | C41: 0.105 | D41: 0.1 | E41: 0.1 | F41: 0.1 | G41: =$F41+($L41-$F41)*G$18/5 -> 0.099 | H41: =$F41+($L41-$F41)*H$18/5 -> 0.098 | I41: =$F41+($L41-$F41)*I$18/5 -> 0.097 | J41: =$F41+($L41-$F41)*J$18/5 -> 0.096 | K41: =$F41+($L41-$F41)*K$18/5 -> 0.095 | L41: 0.095
A42: Operating income | B42: =B39*B41 -> 0.651 | C42: =C39*C41 -> 0.819 | D42: =D39*D41 -> 0.82 | E42: =E39*E41 -> 0.92 | F42: =F39*F41 -> 1.02 | G42: =G39*G41 -> 1.1056871 | H42: =H39*H41 -> 1.1834125 | I42: =I39*I41 -> 1.2503766 | ... L42: =L39*L41 -> 1.3957014
A43: NOPAT | B43: =B42*(1-$B$8) -> 0.59892 | C43: =C42*(1-$B$8) -> 0.75348 | D43: =D42*(1-$B$8) -> 0.7544 | E43: =E42*(1-$B$8) -> 0.8464 | F43: =F42*(1-$B$8) -> 0.9384 | G43: =G42*(1-$B$8) -> 1.0172321 | H43: =H42*(1-$B$8) -> 1.0887395 | I43: =I42*(1-$B$8) -> 1.1503465 | ... L43: =L42*(1-$B$8) -> 1.2840452
A44: Net reinvestment, % of revenue | B44: 0.05 | C44: 0.03 | D44: 0.025 | E44: 0.025 | F44: 0.025 | G44: =$F44+($L44-$F44)*G$18/5 -> 0.024 | H44: =$F44+($L44-$F44)*H$18/5 -> 0.023 | I44: =$F44+($L44-$F44)*I$18/5 -> 0.022 | J44: =$F44+($L44-$F44)*J$18/5 -> 0.021 | K44: =$F44+($L44-$F44)*K$18/5 -> 0.02 | L44: 0.02
...
