Workbook

Sheet Summary
A1: Power and Chip Equipment Company Pass: scenario values
A2: Values link to each company sheet (green). Switch the discount rate on the WACC tab.
A4: Company | B4: Share price | C4: Discount rate used | D4: Bear value | E4: Base value | F4: Bull value | G4: Bear vs price | H4: Base vs price | I4: Bull vs price | J4: Buy below
A5: TSMC (TSM ADR) | B5: =TSM!B4 -> 426.65 | C5: =TSM!B9 -> 0.11 | D5: =TSM!B77 -> 200.82566 | E5: =TSM!B78 -> 344.06862 | F5: =TSM!B79 -> 494.06243 | G5: =D5/B5-1 -> -0.52929647 | H5: =E5/B5-1 -> -0.19355767 | I5: =F5/B5-1 -> 0.15800405 | J5: =TSM!B81 -> 344.06862
A6: ASML Holding (ASML) | B6: =ASML!B4 -> 1677.89 | C6: =ASML!B9 -> 0.1 | D6: =ASML!B77 -> 641.29162 | E6: =ASML!B78 -> 1084.5071 | F6: =ASML!B79 -> 1464.7729 | G6: =D6/B6-1 -> -0.61779877 | H6: =E6/B6-1 -> -0.3536483 | I6: =F6/B6-1 -> -0.12701494 | J6: =ASML!B81 -> 1084.5071
A7: Applied Materials (AMAT) | B7: =AMAT!B4 -> 410.41 | C7: =AMAT!B9 -> 0.105 | D7: =AMAT!B77 -> 143.37911 | E7: =AMAT!B78 -> 227.45954 | F7: =AMAT!B79 -> 293.0873 | G7: =D7/B7-1 -> -0.6506442 | H7: =E7/B7-1 -> -0.44577485 | I7: =F7/B7-1 -> -0.28586706 | J7: =AMAT!B81 -> 227.45954
A8: Vertiv (VRT) | B8: =VRT!B4 -> 211.54 | C8: =VRT!B9 -> 0.11 | D8: =VRT!B77 -> 74.232714 | E8: =VRT!B78 -> 145.36229 | F8: =VRT!B79 -> 203.89239 | G8: =D8/B8-1 -> -0.64908427 | H8: =E8/B8-1 -> -0.3128378 | I8: =F8/B8-1 -> -0.036152055 | J8: =VRT!B81 -> 145.36229
A9: Siemens Energy (ETR: ENR) | B9: =ENR!B4 -> 133 | C9: =ENR!B9 -> 0.11 | D9: =ENR!B77 -> 40.202837 | E9: =ENR!B78 -> 79.918233 | F9: =ENR!B79 -> 110.57131 | G9: =D9/B9-1 -> -0.69772303 | H9: =E9/B9-1 -> -0.39911103 | I9: =F9/B9-1 -> -0.16863675 | J9: =ENR!B81 -> 79.918233
A10: nVent Electric (NVT) | B10: =NVT!B4 -> 139.78 | C10: =NVT!B9 -> 0.1 | D10: =NVT!B77 -> 64.287012 | E10: =NVT!B78 -> 111.33274 | F10: =NVT!B79 -> 156.93696 | G10: =D10/B10-1 -> -0.54008433 | H10: =E10/B10-1 -> -0.20351456 | I10: =F10/B10-1 -> 0.1227426 | J10: =NVT!B81 -> 111.33274
A13: Notes
A14: Ten-year free cash flow DCF: five explicit years, then five years fading growth, margin and reinvestment toward terminal levels; not a three-statement model.
A15: FCF = operating income x (1 - tax) - net reinvestment (capex above depreciation) - working capital x revenue change. Mid-year discounting from October 2026.
A16: Scenario paths, margins, reinvestment, discount rates and terminal assumptions are analyst judgments. Bear cases assume an AI capex slowdown in 2027 to 2028.
A17: Implied returns quoted in the journal entry were solved outside the workbook; the rate sensitivity row on each sheet shows where base value crosses the price.
A18: Prices: Stock Analysis, Oct 21, 2026 (nVent Oct 20 close; Siemens Energy in EUR). Research for discussion, not investment advice.

Sheet WACC
A1: WACC build: calculated (CAPM) versus assumed
A2: Blue = input, black = formula, green = link. The yellow switches apply to all six companies.
A5: WACC used in valuations (1 = Calculated, 2 = Assumed) | B5: 2 | C5: Switch. 2 reproduces the journal entry's figures
A6: Beta used (1 = Raw 5-year, 2 = Blume adjusted) | B6: 2 | C6: Blume adjusted = 0.67 x raw + 0.33
A7: Risk-free rate (10-year Treasury) | B7: 0.0531 | C7: FRED via MacroRadar, Oct 6, 2026
A8: Equity risk premium | B8: 0.05 | C8: Analyst assumption
A9: Credit spread over risk-free (pre-tax cost of debt) | B9: 0.012 | C9: Analyst assumption: investment-grade spread
A11: Item | B11: TSM | C11: ASML | D11: AMAT | E11: VRT | F11: ENR | G11: NVT | H11: Source / note
A12: Raw beta (5-year) | B12: 1.24 | C12: 1.3 | D12: 1.59 | E12: 2.05 | F12: 1.85 | G12: 1.34 | H12: Stock Analysis statistics, Oct 2026
A13: Adjusted beta | B13: =0.67*B12+0.33 -> 1.1608 | C13: =0.67*C12+0.33 -> 1.201 | D13: =0.67*D12+0.33 -> 1.3953 | E13: =0.67*E12+0.33 -> 1.7035 | F13: =0.67*F12+0.33 -> 1.5695 | G13: =0.67*G12+0.33 -> 1.2278 | H13: Blume: 0.67 x raw + 0.33
A14: Beta used | B14: =IF($B$6=1,B12,B13) -> 1.1608 | C14: =IF($B$6=1,C12,C13) -> 1.201 | D14: =IF($B$6=1,D12,D13) -> 1.3953 | E14: =IF($B$6=1,E12,E13) -> 1.7035 | F14: =IF($B$6=1,F12,F13) -> 1.5695 | G14: =IF($B$6=1,G12,G13) -> 1.2278 | H14: Per switch in B6
A15: Country risk premium | B15: 0.01 | C15: 0 | D15: 0 | E15: 0 | F15: 0 | G15: 0 | H15: Analyst assumption (Taiwan for TSMC)
A16: Cost of equity | B16: =$B$7+B14*$B$8+B15 -> 0.12114 | C16: =$B$7+C14*$B$8+C15 -> 0.11315 | D16: =$B$7+D14*$B$8+D15 -> 0.122865 | E16: =$B$7+E14*$B$8+E15 -> 0.138275 | F16: =$B$7+F14*$B$8+F15 -> 0.131575 | G16: =$B$7+G14*$B$8+G15 -> 0.11449 | H16: Risk-free + beta x ERP + country premium
A17: Pre-tax cost of debt | B17: =$B$7+$B$9+B15 -> 0.0751 | C17: =$B$7+$B$9+C15 -> 0.0651 | D17: =$B$7+$B$9+D15 -> 0.0651 | E17: =$B$7+$B$9+E15 -> 0.0651 | F17: =$B$7+$B$9+F15 -> 0.0651 | G17: =$B$7+$B$9+G15 -> 0.0651 | H17: Risk-free + spread + country premium
A18: Tax rate | B18: =TSM!B8 -> 0.15 | C18: =ASML!B8 -> 0.16 | D18: =AMAT!B8 -> 0.13 | E18: =VRT!B8 -> 0.21 | F18: =ENR!B8 -> 0.28 | G18: =NVT!B8 -> 0.21 | H18: Linked from company sheet
A19: After-tax cost of debt | B19: =B17*(1-B18) -> 0.063835 | C19: =C17*(1-C18) -> 0.054684 | D19: =D17*(1-D18) -> 0.056637 | E19: =E17*(1-E18) -> 0.051429 | F19: =F17*(1-F18) -> 0.046872 | G19: =G17*(1-G18) -> 0.051429
A20: Market value of equity (company units) | B20: =TSM!B4*TSM!B6/TSM!B13 -> 2212.6069 | C20: =ASML!B4*ASML!B6/ASML!B13 -> 642.79966 | D20: =AMAT!B4*AMAT!B6/AMAT!B13 -> 325.70138 | E20: =VRT!B4*VRT!B6/VRT!B13 -> 81.440785 | F20: =ENR!B4*ENR!B6/ENR!B13 -> 113.76022 | G20: =NVT!B4*NVT!B6/NVT!B13 -> 22.624791 | H20: Price x shares
A21: Debt (company units) | B21: 25.68 | C21: 2.24 | D21: 7.35 | E21: 3.34 | F21: 2.96 | G21: 1.63 | H21: Stock Analysis, total debt
A22: Equity weight | B22: =B20/(B20+B21) -> 0.98852694 | C22: =C20/(C20+C21) -> 0.99652735 | D22: =D20/(D20+D21) -> 0.97793133 | E22: =E20/(E20+E21) -> 0.96060428 | F22: =F20/(F20+F21) -> 0.97464021 | G22: =G20/(G20+G21) -> 0.93279678
A23: Debt weight | B23: =B21/(B20+B21) -> 0.01147306 | C23: =C21/(C20+C21) -> 0.0034726547 | D23: =D21/(D20+D21) -> 0.022068667 | E23: =E21/(E20+E21) -> 0.039395719 | F23: =F21/(F20+F21) -> 0.025359788 | G23: =G21/(G20+G21) -> 0.067203218
A24: Calculated WACC (CAPM) | B24: =B22*B16+B23*B19 -> 0.12048254 | C24: =C22*C16+C23*C19 -> 0.11294697 | D24: =D22*D16+D23*D19 -> 0.12140344 | E24: =E22*E16+E23*E19 -> 0.13485364 | F24: =F22*F16+F23*F19 -> 0.12942695 | G24: =G22*G16+G23*G19 -> 0.1102521 | H24: Weighted cost of capital
A25: Assumed WACC | B25: 0.11 | C25: 0.1 | D25: 0.105 | E25: 0.11 | F25: 0.11 | G25: 0.1 | H25: Analyst assumption used in the journal entry
A26: WACC used | B26: =IF($B$5=1,B24,B25) -> 0.11 | C26: =IF($B$5=1,C24,C25) -> 0.1 | D26: =IF($B$5=1,D24,D25) -> 0.105 | E26: =IF($B$5=1,E24,E25) -> 0.11 | F26: =IF($B$5=1,F24,F25) -> 0.11 | G26: =IF($B$5=1,G24,G25) -> 0.1 | H26: Per switch in B5; feeds each sheet's B9
A27: Check: WACC above terminal growth | B27: =IF(B26>TSM!B10,"OK","WACC must exceed growth") -> OK | C27: =IF(C26>ASML!B10,"OK","WACC must exceed growth") -> OK | D27: =IF(D26>AMAT!B10,"OK","WACC must exceed growth") -> OK | E27: =IF(E26>VRT!B10,"OK","WACC must exceed growth") -> OK | F27: =IF(F26>ENR!B10,"OK","WACC must exceed growth") -> OK | G27: =IF(G26>NVT!B10,"OK","WACC must exceed growth") -> OK

Sheet TSM
A1: TSMC (TSM ADR): 10-year scenario DCF
A2: Units: $B unless noted. Blue = input, black = formula, green = link, yellow = key lever. Years 6 to 10 fade growth, margin and reinvestment toward terminal levels.
A4: Share price | B4: 426.65 | C4: Source: Stock Analysis, Oct 21, 2026 11:34 ET
A5: Price date | B5: Oct 21, 2026 11:34 ET | C5: Text
A6: Shares outstanding (billions) | B6: 5.186 | C6: ADR-equivalent units: 25.93B ordinary shares / 5 per ADR (Stock Analysis)
A7: Net cash, negative = net debt ($B) | B7: 100.36 | C7: Stock Analysis: cash $126.04B less debt $25.68B
A8: Tax rate | B8: 0.15 | C8: Analyst assumption
A9: Discount rate (WACC), from WACC tab | B9: =WACC!B26 -> 0.11 | C9: Calculated or assumed, per switch in WACC!B5
A10: Terminal growth | B10: 0.035 | C10: Analyst assumption
A11: Working capital, % of revenue change | B11: 0.05 | C11: Analyst assumption
A12: Base-year revenue ($B) | B12: 176 | C12: 2026E: three reported quarters plus Q4 guide midpoint $53.3B (TSMC 6-K, Oct 2026); analyst estimate
A13: Per-share multiplier | B13: 1 | C13: Units conversion (1 here)
A14: Selected scenario (1 Bear, 2 Base, 3 Bull) | B14: 2 | C14: Lever
A16: Year | B16: 2027 | C16: 2028 | D16: 2029 | E16: 2030 | F16: 2031 | G16: 2032 | H16: 2033 | I16: 2034 | J16: 2035 | K16: 2036 | L16: Terminal
A17: Discount period (years, mid-year) | B17: 0.5 | C17: =B17+1 -> 1.5 | D17: =C17+1 -> 2.5 | E17: =D17+1 -> 3.5 | F17: =E17+1 -> 4.5 | G17: =F17+1 -> 5.5 | H17: =G17+1 -> 6.5 | I17: =H17+1 -> 7.5 | J17: =I17+1 -> 8.5 | K17: =J17+1 -> 9.5
A18: Fade step (years 6 to 10) | B18: 0 | C18: 0 | D18: 0 | E18: 0 | F18: 0 | G18: 1 | H18: 2 | I18: 3 | J18: 4 | K18: 5
A20: Bear: AI capex slows in 2027 to 2028
A21: Revenue | B21: 205 | C21: 195 | D21: 215 | E21: 240 | F21: 260 | G21: =F21*(1+$F22+($B$10-$F22)*G$18/5) -> 279.15333 | H21: =G21*(1+$F22+($B$10-$F22)*H$18/5) -> 297.01915 | I21: =H21*(1+$F22+($B$10-$F22)*I$18/5) -> 313.15719 | J21: =I21*(1+$F22+($B$10-$F22)*J$18/5) -> 327.14487 | K21: =J21*(1+$F22+($B$10-$F22)*K$18/5) -> 338.59495 | L21: =K21*(1+$B$10) -> 350.44577
A22: Revenue growth | B22: =B21/$B$12-1 -> 0.16477273 | C22: =C21/B21-1 -> -0.048780488 | D22: =D21/C21-1 -> 0.1025641 | E22: =E21/D21-1 -> 0.11627907 | F22: =F21/E21-1 -> 0.083333333 | G22: =G21/F21-1 -> 0.073666667 | H22: =H21/G21-1 -> 0.064 | I22: =I21/H21-1 -> 0.054333333 | J22: =J21/I21-1 -> 0.044666667 | ... L22: =L21/K21-1 -> 0.035
A23: Operating margin | B23: 0.54 | C23: 0.46 | D23: 0.46 | E23: 0.47 | F23: 0.47 | G23: =$F23+($L23-$F23)*G$18/5 -> 0.46 | H23: =$F23+($L23-$F23)*H$18/5 -> 0.45 | I23: =$F23+($L23-$F23)*I$18/5 -> 0.44 | J23: =$F23+($L23-$F23)*J$18/5 -> 0.43 | K23: =$F23+($L23-$F23)*K$18/5 -> 0.42 | L23: 0.42
A24: Operating income | B24: =B21*B23 -> 110.7 | C24: =C21*C23 -> 89.7 | D24: =D21*D23 -> 98.9 | E24: =E21*E23 -> 112.8 | F24: =F21*F23 -> 122.2 | G24: =G21*G23 -> 128.41053 | H24: =H21*H23 -> 133.65862 | I24: =I21*I23 -> 137.78916 | ... L24: =L21*L23 -> 147.18722
A25: NOPAT | B25: =B24*(1-$B$8) -> 94.095 | C25: =C24*(1-$B$8) -> 76.245 | D25: =D24*(1-$B$8) -> 84.065 | E25: =E24*(1-$B$8) -> 95.88 | F25: =F24*(1-$B$8) -> 103.87 | G25: =G24*(1-$B$8) -> 109.14895 | H25: =H24*(1-$B$8) -> 113.60982 | I25: =I24*(1-$B$8) -> 117.12079 | ... L25: =L24*(1-$B$8) -> 125.10914
A26: Net reinvestment, % of revenue | B26: 0.15 | C26: 0.1 | D26: 0.08 | E26: 0.09 | F26: 0.09 | G26: =$F26+($L26-$F26)*G$18/5 -> 0.088 | H26: =$F26+($L26-$F26)*H$18/5 -> 0.086 | I26: =$F26+($L26-$F26)*I$18/5 -> 0.084 | J26: =$F26+($L26-$F26)*J$18/5 -> 0.082 | K26: =$F26+($L26-$F26)*K$18/5 -> 0.08 | L26: 0.08
A27: Net reinvestment | B27: =B21*B26 -> 30.75 | C27: =C21*C26 -> 19.5 | D27: =D21*D26 -> 17.2 | E27: =E21*E26 -> 21.6 | F27: =F21*F26 -> 23.4 | G27: =G21*G26 -> 24.565493 | H27: =H21*H26 -> 25.543647 | I27: =I21*I26 -> 26.305204 | ... L27: =L21*L26 -> 28.035661
A28: Change in working capital | B28: =$B$11*(B21-$B$12) -> 1.45 | C28: =$B$11*(C21-B21) -> -0.5 | D28: =$B$11*(D21-C21) -> 1 | E28: =$B$11*(E21-D21) -> 1.25 | F28: =$B$11*(F21-E21) -> 1 | G28: =$B$11*(G21-F21) -> 0.95766667 | H28: =$B$11*(H21-G21) -> 0.89329067 | I28: =$B$11*(I21-H21) -> 0.80690202 | J28: =$B$11*(J21-I21) -> 0.69938438 | ... L28: =$B$11*(L21-K21) -> 0.59254115
A29: Free cash flow | B29: =B25-B27-B28 -> 61.895 | C29: =C25-C27-C28 -> 57.245 | D29: =D25-D27-D28 -> 65.865 | E29: =E25-E27-E28 -> 73.03 | F29: =F25-F27-F28 -> 79.47 | G29: =G25-G27-G28 -> 83.625793 | H29: =H25-H27-H28 -> 87.172886 | I29: =I25-I27-I28 -> 90.008682 | ... L29: =L25-L27-L28 -> 96.480937
A30: Discount factor | B30: =1/(1+$B$9)^B$17 -> 0.949158 | C30: =1/(1+$B$9)^C$17 -> 0.85509729 | D30: =1/(1+$B$9)^D$17 -> 0.77035792 | E30: =1/(1+$B$9)^E$17 -> 0.69401615 | F30: =1/(1+$B$9)^F$17 -> 0.62523977 | G30: =1/(1+$B$9)^G$17 -> 0.56327907 | H30: =1/(1+$B$9)^H$17 -> 0.50745862 | I30: =1/(1+$B$9)^I$17 -> 0.45716993 | ... K30: =1/(1+$B$9)^K$17 -> 0.37104937
A31: PV of free cash flow | B31: =B29*B30 -> 58.748134 | C31: =C29*C30 -> 48.950045 | D31: =D29*D30 -> 50.739625 | E31: =E29*E30 -> 50.683999 | F31: =F29*F30 -> 49.687805 | G31: =G29*G30 -> 47.104659 | H31: =H29*H30 -> 44.236633 | I31: =I29*I30 -> 41.149263 | ... K31: =K29*K30 -> 34.58859
A32: Terminal value | B32: =L29/($B$9-$B$10) -> 1286.4125
A33: PV of terminal value | B33: =B32/(1+$B$9)^$K$17 -> 477.32255
A34: Equity value (PV FCF + PV TV + net cash) | B34: =SUM(B31:K31)+B33+$B$7 -> 1041.4819
A35: Value per share | B35: =B34/$B$6*$B$13 -> 200.82566
A36: Value vs share price | B36: =B35/$B$4-1 -> -0.52929647
A38: Base: AI growth continues, slower after 2028
A39: Revenue | B39: 230 | C39: 280 | D39: 320 | E39: 355 | F39: 390 | G39: =F39*(1+$F40+($B$10-$F40)*G$18/5) -> 423.49056 | H39: =G39*(1+$F40+($B$10-$F40)*H$18/5) -> 454.47099 | I39: =H39*(1+$F40+($B$10-$F40)*I$18/5) -> 481.93768 | J39: =I39*(1+$F40+($B$10-$F40)*J$18/5) -> 504.93493 | K39: =J39*(1+$F40+($B$10-$F40)*K$18/5) -> 522.60765 | L39: =K39*(1+$B$10) -> 540.89892
A40: Revenue growth | B40: =B39/$B$12-1 -> 0.30681818 | C40: =C39/B39-1 -> 0.2173913 | D40: =D39/C39-1 -> 0.14285714 | E40: =E39/D39-1 -> 0.109375 | F40: =F39/E39-1 -> 0.098591549 | G40: =G39/F39-1 -> 0.085873239 | H40: =H39/G39-1 -> 0.07315493 | I40: =I39/H39-1 -> 0.06043662 | J40: =J39/I39-1 -> 0.04771831 | ... L40: =L39/K39-1 -> 0.035
A41: Operating margin | B41: 0.58 | C41: 0.57 | D41: 0.55 | E41: 0.54 | F41: 0.53 | G41: =$F41+($L41-$F41)*G$18/5 -> 0.524 | H41: =$F41+($L41-$F41)*H$18/5 -> 0.518 | I41: =$F41+($L41-$F41)*I$18/5 -> 0.512 | J41: =$F41+($L41-$F41)*J$18/5 -> 0.506 | K41: =$F41+($L41-$F41)*K$18/5 -> 0.5 | L41: 0.5
A42: Operating income | B42: =B39*B41 -> 133.4 | C42: =C39*C41 -> 159.6 | D42: =D39*D41 -> 176 | E42: =E39*E41 -> 191.7 | F42: =F39*F41 -> 206.7 | G42: =G39*G41 -> 221.90906 | H42: =H39*H41 -> 235.41597 | I42: =I39*I41 -> 246.75209 | ... L42: =L39*L41 -> 270.44946
A43: NOPAT | B43: =B42*(1-$B$8) -> 113.39 | C43: =C42*(1-$B$8) -> 135.66 | D43: =D42*(1-$B$8) -> 149.6 | E43: =E42*(1-$B$8) -> 162.945 | F43: =F42*(1-$B$8) -> 175.695 | G43: =G42*(1-$B$8) -> 188.6227 | H43: =H42*(1-$B$8) -> 200.10358 | I43: =I42*(1-$B$8) -> 209.73928 | ... L43: =L42*(1-$B$8) -> 229.88204
A44: Net reinvestment, % of revenue | B44: 0.16 | C44: 0.15 | D44: 0.13 | E44: 0.12 | F44: 0.11 | G44: =$F44+($L44-$F44)*G$18/5 -> 0.104 | H44: =$F44+($L44-$F44)*H$18/5 -> 0.098 | I44: =$F44+($L44-$F44)*I$18/5 -> 0.092 | J44: =$F44+($L44-$F44)*J$18/5 -> 0.086 | K44: =$F44+($L44-$F44)*K$18/5 -> 0.08 | L44: 0.08
...

Sheet ASML
A1: ASML Holding (ASML): 10-year scenario DCF
A2: Units: $B unless noted. Blue = input, black = formula, green = link, yellow = key lever. Years 6 to 10 fade growth, margin and reinvestment toward terminal levels.
A4: Share price | B4: 1677.89 | C4: Source: Stock Analysis, Oct 21, 2026 11:39 ET
A5: Price date | B5: Oct 21, 2026 11:39 ET | C5: Text
A6: Shares outstanding (billions) | B6: 0.3831 | C6: Source: Stock Analysis, https://stockanalysis.com
A7: Net cash, negative = net debt ($B) | B7: 12.27 | C7: Stock Analysis: cash $14.51B less debt $2.24B
A8: Tax rate | B8: 0.16 | C8: Analyst assumption
A9: Discount rate (WACC), from WACC tab | B9: =WACC!C26 -> 0.1 | C9: Calculated or assumed, per switch in WACC!B5
A10: Terminal growth | B10: 0.035 | C10: Analyst assumption
A11: Working capital, % of revenue change | B11: 0.05 | C11: Analyst assumption
A12: Base-year revenue ($B) | B12: 50.1 | C12: 2026 outlook midpoint EUR 44.5B (ASML 6-K, Oct 14, 2026) at $1.1259/EUR (FRED via MacroRadar, Oct 5)
A13: Per-share multiplier | B13: 1 | C13: Units conversion (1 here)
A14: Selected scenario (1 Bear, 2 Base, 3 Bull) | B14: 2 | C14: Lever
A16: Year | B16: 2027 | C16: 2028 | D16: 2029 | E16: 2030 | F16: 2031 | G16: 2032 | H16: 2033 | I16: 2034 | J16: 2035 | K16: 2036 | L16: Terminal
A17: Discount period (years, mid-year) | B17: 0.5 | C17: =B17+1 -> 1.5 | D17: =C17+1 -> 2.5 | E17: =D17+1 -> 3.5 | F17: =E17+1 -> 4.5 | G17: =F17+1 -> 5.5 | H17: =G17+1 -> 6.5 | I17: =H17+1 -> 7.5 | J17: =I17+1 -> 8.5 | K17: =J17+1 -> 9.5
A18: Fade step (years 6 to 10) | B18: 0 | C18: 0 | D18: 0 | E18: 0 | F18: 0 | G18: 1 | H18: 2 | I18: 3 | J18: 4 | K18: 5
A20: Bear: tool orders fall in 2028
A21: Revenue | B21: 54 | C21: 46 | D21: 50 | E21: 56 | F21: 62 | G21: =F21*(1+$F22+($B$10-$F22)*G$18/5) -> 67.748286 | H21: =G21*(1+$F22+($B$10-$F22)*H$18/5) -> 73.052009 | I21: =H21*(1+$F22+($B$10-$F22)*I$18/5) -> 77.716901 | J21: =I21*(1+$F22+($B$10-$F22)*J$18/5) -> 81.558337 | K21: =J21*(1+$F22+($B$10-$F22)*K$18/5) -> 84.412878 | L21: =K21*(1+$B$10) -> 87.367329
A22: Revenue growth | B22: =B21/$B$12-1 -> 0.077844311 | C22: =C21/B21-1 -> -0.14814815 | D22: =D21/C21-1 -> 0.086956522 | E22: =E21/D21-1 -> 0.12 | F22: =F21/E21-1 -> 0.10714286 | G22: =G21/F21-1 -> 0.092714286 | H22: =H21/G21-1 -> 0.078285714 | I22: =I21/H21-1 -> 0.063857143 | J22: =J21/I21-1 -> 0.049428571 | ... L22: =L21/K21-1 -> 0.035
A23: Operating margin | B23: 0.36 | C23: 0.3 | D23: 0.32 | E23: 0.34 | F23: 0.35 | G23: =$F23+($L23-$F23)*G$18/5 -> 0.346 | H23: =$F23+($L23-$F23)*H$18/5 -> 0.342 | I23: =$F23+($L23-$F23)*I$18/5 -> 0.338 | J23: =$F23+($L23-$F23)*J$18/5 -> 0.334 | K23: =$F23+($L23-$F23)*K$18/5 -> 0.33 | L23: 0.33
A24: Operating income | B24: =B21*B23 -> 19.44 | C24: =C21*C23 -> 13.8 | D24: =D21*D23 -> 16 | E24: =E21*E23 -> 19.04 | F24: =F21*F23 -> 21.7 | G24: =G21*G23 -> 23.440907 | H24: =H21*H23 -> 24.983787 | I24: =I21*I23 -> 26.268313 | ... L24: =L21*L23 -> 28.831219
A25: NOPAT | B25: =B24*(1-$B$8) -> 16.3296 | C25: =C24*(1-$B$8) -> 11.592 | D25: =D24*(1-$B$8) -> 13.44 | E25: =E24*(1-$B$8) -> 15.9936 | F25: =F24*(1-$B$8) -> 18.228 | G25: =G24*(1-$B$8) -> 19.690362 | H25: =H24*(1-$B$8) -> 20.986381 | I25: =I24*(1-$B$8) -> 22.065383 | ... L25: =L24*(1-$B$8) -> 24.218224
A26: Net reinvestment, % of revenue | B26: 0.03 | C26: 0.03 | D26: 0.03 | E26: 0.03 | F26: 0.03 | G26: =$F26+($L26-$F26)*G$18/5 -> 0.03 | H26: =$F26+($L26-$F26)*H$18/5 -> 0.03 | I26: =$F26+($L26-$F26)*I$18/5 -> 0.03 | J26: =$F26+($L26-$F26)*J$18/5 -> 0.03 | K26: =$F26+($L26-$F26)*K$18/5 -> 0.03 | L26: 0.03
A27: Net reinvestment | B27: =B21*B26 -> 1.62 | C27: =C21*C26 -> 1.38 | D27: =D21*D26 -> 1.5 | E27: =E21*E26 -> 1.68 | F27: =F21*F26 -> 1.86 | G27: =G21*G26 -> 2.0324486 | H27: =H21*H26 -> 2.1915603 | I27: =I21*I26 -> 2.331507 | ... L27: =L21*L26 -> 2.6210199
A28: Change in working capital | B28: =$B$11*(B21-$B$12) -> 0.195 | C28: =$B$11*(C21-B21) -> -0.4 | D28: =$B$11*(D21-C21) -> 0.2 | E28: =$B$11*(E21-D21) -> 0.3 | F28: =$B$11*(F21-E21) -> 0.3 | G28: =$B$11*(G21-F21) -> 0.28741429 | H28: =$B$11*(H21-G21) -> 0.26518615 | I28: =$B$11*(I21-H21) -> 0.23324463 | J28: =$B$11*(J21-I21) -> 0.19207177 | ... L28: =$B$11*(L21-K21) -> 0.14772254
A29: Free cash flow | B29: =B25-B27-B28 -> 14.5146 | C29: =C25-C27-C28 -> 10.612 | D29: =D25-D27-D28 -> 11.74 | E29: =E25-E27-E28 -> 14.0136 | F29: =F25-F27-F28 -> 16.068 | G29: =G25-G27-G28 -> 17.370499 | H29: =H25-H27-H28 -> 18.529635 | I29: =I25-I27-I28 -> 19.500631 | ... L29: =L25-L27-L28 -> 21.449481
A30: Discount factor | B30: =1/(1+$B$9)^B$17 -> 0.95346259 | C30: =1/(1+$B$9)^C$17 -> 0.86678417 | D30: =1/(1+$B$9)^D$17 -> 0.78798561 | E30: =1/(1+$B$9)^E$17 -> 0.71635056 | F30: =1/(1+$B$9)^F$17 -> 0.65122778 | G30: =1/(1+$B$9)^G$17 -> 0.59202525 | H30: =1/(1+$B$9)^H$17 -> 0.53820477 | I30: =1/(1+$B$9)^I$17 -> 0.48927707 | ... K30: =1/(1+$B$9)^K$17 -> 0.40436121
A31: PV of free cash flow | B31: =B29*B30 -> 13.839128 | C31: =C29*C30 -> 9.1983136 | D31: =D29*D30 -> 9.2509511 | E31: =E29*E30 -> 10.03865 | F31: =F29*F30 -> 10.463928 | G31: =G29*G30 -> 10.283774 | H31: =H29*H30 -> 9.9727378 | I31: =I29*I30 -> 9.5412115 | ... K31: =K29*K30 -> 8.380037
A32: Terminal value | B32: =L29/($B$9-$B$10) -> 329.99202
A33: PV of terminal value | B33: =B32/(1+$B$9)^$K$17 -> 133.43597
A34: Equity value (PV FCF + PV TV + net cash) | B34: =SUM(B31:K31)+B33+$B$7 -> 245.67882
A35: Value per share | B35: =B34/$B$6*$B$13 -> 641.29162
A36: Value vs share price | B36: =B35/$B$4-1 -> -0.61779877
A38: Base: capacity-limited growth
A39: Revenue | B39: 63 | C39: 73 | D39: 72 | E39: 80 | F39: 88 | G39: =F39*(1+$F40+($B$10-$F40)*G$18/5) -> 95.656 | H39: =G39*(1+$F40+($B$10-$F40)*H$18/5) -> 102.73454 | I39: =H39*(1+$F40+($B$10-$F40)*I$18/5) -> 109.00135 | J39: =I39*(1+$F40+($B$10-$F40)*J$18/5) -> 114.23342 | K39: =J39*(1+$F40+($B$10-$F40)*K$18/5) -> 118.23159 | L39: =K39*(1+$B$10) -> 122.36969
A40: Revenue growth | B40: =B39/$B$12-1 -> 0.25748503 | C40: =C39/B39-1 -> 0.15873016 | D40: =D39/C39-1 -> -0.01369863 | E40: =E39/D39-1 -> 0.11111111 | F40: =F39/E39-1 -> 0.1 | G40: =G39/F39-1 -> 0.087 | H40: =H39/G39-1 -> 0.074 | I40: =I39/H39-1 -> 0.061 | J40: =J39/I39-1 -> 0.048 | ... L40: =L39/K39-1 -> 0.035
A41: Operating margin | B41: 0.4 | C41: 0.42 | D41: 0.4 | E41: 0.41 | F41: 0.41 | G41: =$F41+($L41-$F41)*G$18/5 -> 0.408 | H41: =$F41+($L41-$F41)*H$18/5 -> 0.406 | I41: =$F41+($L41-$F41)*I$18/5 -> 0.404 | J41: =$F41+($L41-$F41)*J$18/5 -> 0.402 | K41: =$F41+($L41-$F41)*K$18/5 -> 0.4 | L41: 0.4
A42: Operating income | B42: =B39*B41 -> 25.2 | C42: =C39*C41 -> 30.66 | D42: =D39*D41 -> 28.8 | E42: =E39*E41 -> 32.8 | F42: =F39*F41 -> 36.08 | G42: =G39*G41 -> 39.027648 | H42: =H39*H41 -> 41.710225 | I42: =I39*I41 -> 44.036546 | ... L42: =L39*L41 -> 48.947876
A43: NOPAT | B43: =B42*(1-$B$8) -> 21.168 | C43: =C42*(1-$B$8) -> 25.7544 | D43: =D42*(1-$B$8) -> 24.192 | E43: =E42*(1-$B$8) -> 27.552 | F43: =F42*(1-$B$8) -> 30.3072 | G43: =G42*(1-$B$8) -> 32.783224 | H43: =H42*(1-$B$8) -> 35.036589 | I43: =I42*(1-$B$8) -> 36.990699 | ... L43: =L42*(1-$B$8) -> 41.116216
A44: Net reinvestment, % of revenue | B44: 0.03 | C44: 0.03 | D44: 0.03 | E44: 0.03 | F44: 0.03 | G44: =$F44+($L44-$F44)*G$18/5 -> 0.03 | H44: =$F44+($L44-$F44)*H$18/5 -> 0.03 | I44: =$F44+($L44-$F44)*I$18/5 -> 0.03 | J44: =$F44+($L44-$F44)*J$18/5 -> 0.03 | K44: =$F44+($L44-$F44)*K$18/5 -> 0.03 | L44: 0.03
...

Sheet AMAT
A1: Applied Materials (AMAT): 10-year scenario DCF
A2: Units: $B unless noted. Blue = input, black = formula, green = link, yellow = key lever. Years 6 to 10 fade growth, margin and reinvestment toward terminal levels.
A4: Share price | B4: 410.41 | C4: Source: Stock Analysis, Oct 21, 2026 11:33 ET
A5: Price date | B5: Oct 21, 2026 11:33 ET | C5: Text
A6: Shares outstanding (billions) | B6: 0.7936 | C6: Source: Stock Analysis, https://stockanalysis.com
A7: Net cash, negative = net debt ($B) | B7: 1.88 | C7: Stock Analysis: cash $9.23B less debt $7.35B
A8: Tax rate | B8: 0.13 | C8: Analyst assumption
A9: Discount rate (WACC), from WACC tab | B9: =WACC!D26 -> 0.105 | C9: Calculated or assumed, per switch in WACC!B5
A10: Terminal growth | B10: 0.035 | C10: Analyst assumption
A11: Working capital, % of revenue change | B11: 0.15 | C11: Analyst assumption
A12: Base-year revenue ($B) | B12: 34.3 | C12: FY26E: TTM $30.84B (to Jul 2026) less FQ4 FY25 (~$6.8B) plus FQ4 guide $10.25B; analyst estimate
A13: Per-share multiplier | B13: 1 | C13: Units conversion (1 here)
A14: Selected scenario (1 Bear, 2 Base, 3 Bull) | B14: 2 | C14: Lever
A16: Year | B16: FY27 | C16: FY28 | D16: FY29 | E16: FY30 | F16: FY31 | G16: FY32 | H16: FY33 | I16: FY34 | J16: FY35 | K16: FY36 | L16: Terminal
A17: Discount period (years, mid-year) | B17: 0.5 | C17: =B17+1 -> 1.5 | D17: =C17+1 -> 2.5 | E17: =D17+1 -> 3.5 | F17: =E17+1 -> 4.5 | G17: =F17+1 -> 5.5 | H17: =G17+1 -> 6.5 | I17: =H17+1 -> 7.5 | J17: =I17+1 -> 8.5 | K17: =J17+1 -> 9.5
A18: Fade step (years 6 to 10) | B18: 0 | C18: 0 | D18: 0 | E18: 0 | F18: 0 | G18: 1 | H18: 2 | I18: 3 | J18: 4 | K18: 5
A20: Bear: equipment downturn in FY28
A21: Revenue | B21: 37 | C21: 32 | D21: 34 | E21: 38 | F21: 41 | G21: =F21*(1+$F22+($B$10-$F22)*G$18/5) -> 43.876474 | H21: =G21*(1+$F22+($B$10-$F22)*H$18/5) -> 46.569104 | I21: =H21*(1+$F22+($B$10-$F22)*I$18/5) -> 49.017658 | J21: =I21*(1+$F22+($B$10-$F22)*J$18/5) -> 51.164115 | K21: =J21*(1+$F22+($B$10-$F22)*K$18/5) -> 52.95486 | L21: =K21*(1+$B$10) -> 54.80828
A22: Revenue growth | B22: =B21/$B$12-1 -> 0.078717201 | C22: =C21/B21-1 -> -0.13513514 | D22: =D21/C21-1 -> 0.0625 | E22: =E21/D21-1 -> 0.11764706 | F22: =F21/E21-1 -> 0.078947368 | G22: =G21/F21-1 -> 0.070157895 | H22: =H21/G21-1 -> 0.061368421 | I22: =I21/H21-1 -> 0.052578947 | J22: =J21/I21-1 -> 0.043789474 | ... L22: =L21/K21-1 -> 0.035
A23: Operating margin | B23: 0.32 | C23: 0.27 | D23: 0.28 | E23: 0.3 | F23: 0.3 | G23: =$F23+($L23-$F23)*G$18/5 -> 0.296 | H23: =$F23+($L23-$F23)*H$18/5 -> 0.292 | I23: =$F23+($L23-$F23)*I$18/5 -> 0.288 | J23: =$F23+($L23-$F23)*J$18/5 -> 0.284 | K23: =$F23+($L23-$F23)*K$18/5 -> 0.28 | L23: 0.28
A24: Operating income | B24: =B21*B23 -> 11.84 | C24: =C21*C23 -> 8.64 | D24: =D21*D23 -> 9.52 | E24: =E21*E23 -> 11.4 | F24: =F21*F23 -> 12.3 | G24: =G21*G23 -> 12.987436 | H24: =H21*H23 -> 13.598178 | I24: =I21*I23 -> 14.117086 | ... L24: =L21*L23 -> 15.346318
A25: NOPAT | B25: =B24*(1-$B$8) -> 10.3008 | C25: =C24*(1-$B$8) -> 7.5168 | D25: =D24*(1-$B$8) -> 8.2824 | E25: =E24*(1-$B$8) -> 9.918 | F25: =F24*(1-$B$8) -> 10.701 | G25: =G24*(1-$B$8) -> 11.29907 | H25: =H24*(1-$B$8) -> 11.830415 | I25: =I24*(1-$B$8) -> 12.281864 | ... L25: =L24*(1-$B$8) -> 13.351297
A26: Net reinvestment, % of revenue | B26: 0.05 | C26: 0.05 | D26: 0.05 | E26: 0.05 | F26: 0.05 | G26: =$F26+($L26-$F26)*G$18/5 -> 0.048 | H26: =$F26+($L26-$F26)*H$18/5 -> 0.046 | I26: =$F26+($L26-$F26)*I$18/5 -> 0.044 | J26: =$F26+($L26-$F26)*J$18/5 -> 0.042 | K26: =$F26+($L26-$F26)*K$18/5 -> 0.04 | L26: 0.04
A27: Net reinvestment | B27: =B21*B26 -> 1.85 | C27: =C21*C26 -> 1.6 | D27: =D21*D26 -> 1.7 | E27: =E21*E26 -> 1.9 | F27: =F21*F26 -> 2.05 | G27: =G21*G26 -> 2.1060707 | H27: =H21*H26 -> 2.1421788 | I27: =I21*I26 -> 2.156777 | ... L27: =L21*L26 -> 2.1923312
A28: Change in working capital | B28: =$B$11*(B21-$B$12) -> 0.405 | C28: =$B$11*(C21-B21) -> -0.75 | D28: =$B$11*(D21-C21) -> 0.3 | E28: =$B$11*(E21-D21) -> 0.6 | F28: =$B$11*(F21-E21) -> 0.45 | G28: =$B$11*(G21-F21) -> 0.43147105 | H28: =$B$11*(H21-G21) -> 0.40389449 | I28: =$B$11*(I21-H21) -> 0.36728317 | J28: =$B$11*(J21-I21) -> 0.32196862 | ... L28: =$B$11*(L21-K21) -> 0.27801301
A29: Free cash flow | B29: =B25-B27-B28 -> 8.0458 | C29: =C25-C27-C28 -> 6.6668 | D29: =D25-D27-D28 -> 6.2824 | E29: =E25-E27-E28 -> 7.418 | F29: =F25-F27-F28 -> 8.201 | G29: =G25-G27-G28 -> 8.7615277 | H29: =H25-H27-H28 -> 9.2843418 | I29: =I25-I27-I28 -> 9.7578043 | ... L29: =L25-L27-L28 -> 10.880953
A30: Discount factor | B30: =1/(1+$B$9)^B$17 -> 0.95130299 | C30: =1/(1+$B$9)^C$17 -> 0.86090768 | D30: =1/(1+$B$9)^D$17 -> 0.77910197 | E30: =1/(1+$B$9)^E$17 -> 0.70506966 | F30: =1/(1+$B$9)^F$17 -> 0.63807209 | G30: =1/(1+$B$9)^G$17 -> 0.57744081 | H30: =1/(1+$B$9)^H$17 -> 0.52257087 | I30: =1/(1+$B$9)^I$17 -> 0.47291481 | ... K30: =1/(1+$B$9)^K$17 -> 0.38730969
A31: PV of free cash flow | B31: =B29*B30 -> 7.6539936 | C31: =C29*C30 -> 5.7394993 | D31: =D29*D30 -> 4.8946302 | E31: =E29*E30 -> 5.2302067 | F31: =F29*F30 -> 5.2328292 | G31: =G29*G30 -> 5.0592636 | H31: =H29*H30 -> 4.8517265 | I31: =I29*I30 -> 4.6146102 | ... K31: =K29*K30 -> 4.0717859
A32: Terminal value | B32: =L29/($B$9-$B$10) -> 155.44218
A33: PV of terminal value | B33: =B32/(1+$B$9)^$K$17 -> 60.204263
A34: Equity value (PV FCF + PV TV + net cash) | B34: =SUM(B31:K31)+B33+$B$7 -> 113.78566
A35: Value per share | B35: =B34/$B$6*$B$13 -> 143.37911
A36: Value vs share price | B36: =B35/$B$4-1 -> -0.6506442
A38: Base: strong FY27, pause in FY29
A39: Revenue | B39: 41 | C39: 46 | D39: 45 | E39: 50 | F39: 55 | G39: =F39*(1+$F40+($B$10-$F40)*G$18/5) -> 59.785 | H39: =G39*(1+$F40+($B$10-$F40)*H$18/5) -> 64.20909 | I39: =H39*(1+$F40+($B$10-$F40)*I$18/5) -> 68.125844 | J39: =I39*(1+$F40+($B$10-$F40)*J$18/5) -> 71.395885 | K39: =J39*(1+$F40+($B$10-$F40)*K$18/5) -> 73.894741 | L39: =K39*(1+$B$10) -> 76.481057
A40: Revenue growth | B40: =B39/$B$12-1 -> 0.19533528 | C40: =C39/B39-1 -> 0.12195122 | D40: =D39/C39-1 -> -0.02173913 | E40: =E39/D39-1 -> 0.11111111 | F40: =F39/E39-1 -> 0.1 | G40: =G39/F39-1 -> 0.087 | H40: =H39/G39-1 -> 0.074 | I40: =I39/H39-1 -> 0.061 | J40: =J39/I39-1 -> 0.048 | ... L40: =L39/K39-1 -> 0.035
A41: Operating margin | B41: 0.34 | C41: 0.35 | D41: 0.33 | E41: 0.34 | F41: 0.34 | G41: =$F41+($L41-$F41)*G$18/5 -> 0.336 | H41: =$F41+($L41-$F41)*H$18/5 -> 0.332 | I41: =$F41+($L41-$F41)*I$18/5 -> 0.328 | J41: =$F41+($L41-$F41)*J$18/5 -> 0.324 | K41: =$F41+($L41-$F41)*K$18/5 -> 0.32 | L41: 0.32
A42: Operating income | B42: =B39*B41 -> 13.94 | C42: =C39*C41 -> 16.1 | D42: =D39*D41 -> 14.85 | E42: =E39*E41 -> 17 | F42: =F39*F41 -> 18.7 | G42: =G39*G41 -> 20.08776 | H42: =H39*H41 -> 21.317418 | I42: =I39*I41 -> 22.345277 | ... L42: =L39*L41 -> 24.473938
A43: NOPAT | B43: =B42*(1-$B$8) -> 12.1278 | C43: =C42*(1-$B$8) -> 14.007 | D43: =D42*(1-$B$8) -> 12.9195 | E43: =E42*(1-$B$8) -> 14.79 | F43: =F42*(1-$B$8) -> 16.269 | G43: =G42*(1-$B$8) -> 17.476351 | H43: =H42*(1-$B$8) -> 18.546154 | I43: =I42*(1-$B$8) -> 19.440391 | ... L43: =L42*(1-$B$8) -> 21.292326
A44: Net reinvestment, % of revenue | B44: 0.05 | C44: 0.05 | D44: 0.05 | E44: 0.05 | F44: 0.05 | G44: =$F44+($L44-$F44)*G$18/5 -> 0.048 | H44: =$F44+($L44-$F44)*H$18/5 -> 0.046 | I44: =$F44+($L44-$F44)*I$18/5 -> 0.044 | J44: =$F44+($L44-$F44)*J$18/5 -> 0.042 | K44: =$F44+($L44-$F44)*K$18/5 -> 0.04 | L44: 0.04
...

Sheet VRT
A1: Vertiv (VRT): 10-year scenario DCF
A2: Units: $B unless noted. Blue = input, black = formula, green = link, yellow = key lever. Years 6 to 10 fade growth, margin and reinvestment toward terminal levels.
A4: Share price | B4: 211.54 | C4: Source: Stock Analysis, Oct 21, 2026 11:36 ET
A5: Price date | B5: Oct 21, 2026 11:36 ET | C5: Text
A6: Shares outstanding (billions) | B6: 0.38499 | C6: Source: Stock Analysis, https://stockanalysis.com
A7: Net cash, negative = net debt ($B) | B7: -0.23 | C7: Stock Analysis: cash $3.11B less debt $3.34B
A8: Tax rate | B8: 0.21 | C8: Analyst assumption
A9: Discount rate (WACC), from WACC tab | B9: =WACC!E26 -> 0.11 | C9: Calculated or assumed, per switch in WACC!B5
A10: Terminal growth | B10: 0.04 | C10: Analyst assumption
A11: Working capital, % of revenue change | B11: 0.12 | C11: Analyst assumption
A12: Base-year revenue ($B) | B12: 14 | C12: 2026 guidance midpoint $13.8B to $14.2B (Vertiv 8-K, Jul 29, 2026). Margins are adjusted operating margins
A13: Per-share multiplier | B13: 1 | C13: Units conversion (1 here)
A14: Selected scenario (1 Bear, 2 Base, 3 Bull) | B14: 2 | C14: Lever
A16: Year | B16: 2027 | C16: 2028 | D16: 2029 | E16: 2030 | F16: 2031 | G16: 2032 | H16: 2033 | I16: 2034 | J16: 2035 | K16: 2036 | L16: Terminal
A17: Discount period (years, mid-year) | B17: 0.5 | C17: =B17+1 -> 1.5 | D17: =C17+1 -> 2.5 | E17: =D17+1 -> 3.5 | F17: =E17+1 -> 4.5 | G17: =F17+1 -> 5.5 | H17: =G17+1 -> 6.5 | I17: =H17+1 -> 7.5 | J17: =I17+1 -> 8.5 | K17: =J17+1 -> 9.5
A18: Fade step (years 6 to 10) | B18: 0 | C18: 0 | D18: 0 | E18: 0 | F18: 0 | G18: 1 | H18: 2 | I18: 3 | J18: 4 | K18: 5
A20: Bear: data center orders stall in 2028
A21: Revenue | B21: 16 | C21: 14.5 | D21: 14 | E21: 15.5 | F21: 17 | G21: =F21*(1+$F22+($B$10-$F22)*G$18/5) -> 18.452129 | H21: =G21*(1+$F22+($B$10-$F22)*H$18/5) -> 19.818777 | I21: =H21*(1+$F22+($B$10-$F22)*I$18/5) -> 21.061606 | J21: =I21*(1+$F22+($B$10-$F22)*J$18/5) -> 22.143222 | K21: =J21*(1+$F22+($B$10-$F22)*K$18/5) -> 23.02895 | L21: =K21*(1+$B$10) -> 23.950108
A22: Revenue growth | B22: =B21/$B$12-1 -> 0.14285714 | C22: =C21/B21-1 -> -0.09375 | D22: =D21/C21-1 -> -0.034482759 | E22: =E21/D21-1 -> 0.10714286 | F22: =F21/E21-1 -> 0.096774194 | G22: =G21/F21-1 -> 0.085419355 | H22: =H21/G21-1 -> 0.074064516 | I22: =I21/H21-1 -> 0.062709677 | J22: =J21/I21-1 -> 0.051354839 | ... L22: =L21/K21-1 -> 0.04
A23: Operating margin | B23: 0.23 | C23: 0.19 | D23: 0.18 | E23: 0.2 | F23: 0.2 | G23: =$F23+($L23-$F23)*G$18/5 -> 0.196 | H23: =$F23+($L23-$F23)*H$18/5 -> 0.192 | I23: =$F23+($L23-$F23)*I$18/5 -> 0.188 | J23: =$F23+($L23-$F23)*J$18/5 -> 0.184 | K23: =$F23+($L23-$F23)*K$18/5 -> 0.18 | L23: 0.18
A24: Operating income | B24: =B21*B23 -> 3.68 | C24: =C21*C23 -> 2.755 | D24: =D21*D23 -> 2.52 | E24: =E21*E23 -> 3.1 | F24: =F21*F23 -> 3.4 | G24: =G21*G23 -> 3.6166173 | H24: =H21*H23 -> 3.8052052 | I24: =I21*I23 -> 3.959582 | ... L24: =L21*L23 -> 4.3110195
A25: NOPAT | B25: =B24*(1-$B$8) -> 2.9072 | C25: =C24*(1-$B$8) -> 2.17645 | D25: =D24*(1-$B$8) -> 1.9908 | E25: =E24*(1-$B$8) -> 2.449 | F25: =F24*(1-$B$8) -> 2.686 | G25: =G24*(1-$B$8) -> 2.8571277 | H25: =H24*(1-$B$8) -> 3.0061121 | I25: =I24*(1-$B$8) -> 3.1280697 | ... L25: =L24*(1-$B$8) -> 3.4057054
A26: Net reinvestment, % of revenue | B26: 0.02 | C26: 0.02 | D26: 0.02 | E26: 0.02 | F26: 0.02 | G26: =$F26+($L26-$F26)*G$18/5 -> 0.02 | H26: =$F26+($L26-$F26)*H$18/5 -> 0.02 | I26: =$F26+($L26-$F26)*I$18/5 -> 0.02 | J26: =$F26+($L26-$F26)*J$18/5 -> 0.02 | K26: =$F26+($L26-$F26)*K$18/5 -> 0.02 | L26: 0.02
A27: Net reinvestment | B27: =B21*B26 -> 0.32 | C27: =C21*C26 -> 0.29 | D27: =D21*D26 -> 0.28 | E27: =E21*E26 -> 0.31 | F27: =F21*F26 -> 0.34 | G27: =G21*G26 -> 0.36904258 | H27: =H21*H26 -> 0.39637554 | I27: =I21*I26 -> 0.42123212 | ... L27: =L21*L26 -> 0.47900217
A28: Change in working capital | B28: =$B$11*(B21-$B$12) -> 0.24 | C28: =$B$11*(C21-B21) -> -0.18 | D28: =$B$11*(D21-C21) -> -0.06 | E28: =$B$11*(E21-D21) -> 0.18 | F28: =$B$11*(F21-E21) -> 0.18 | G28: =$B$11*(G21-F21) -> 0.17425548 | H28: =$B$11*(H21-G21) -> 0.16399776 | I28: =$B$11*(I21-H21) -> 0.14913949 | J28: =$B$11*(J21-I21) -> 0.12979385 | ... L28: =$B$11*(L21-K21) -> 0.11053896
A29: Free cash flow | B29: =B25-B27-B28 -> 2.3472 | C29: =C25-C27-C28 -> 2.06645 | D29: =D25-D27-D28 -> 1.7708 | E29: =E25-E27-E28 -> 1.959 | F29: =F25-F27-F28 -> 2.166 | G29: =G25-G27-G28 -> 2.3138296 | H29: =H25-H27-H28 -> 2.4457388 | I29: =I25-I27-I28 -> 2.5576981 | ... L29: =L25-L27-L28 -> 2.8161643
A30: Discount factor | B30: =1/(1+$B$9)^B$17 -> 0.949158 | C30: =1/(1+$B$9)^C$17 -> 0.85509729 | D30: =1/(1+$B$9)^D$17 -> 0.77035792 | E30: =1/(1+$B$9)^E$17 -> 0.69401615 | F30: =1/(1+$B$9)^F$17 -> 0.62523977 | G30: =1/(1+$B$9)^G$17 -> 0.56327907 | H30: =1/(1+$B$9)^H$17 -> 0.50745862 | I30: =1/(1+$B$9)^I$17 -> 0.45716993 | ... K30: =1/(1+$B$9)^K$17 -> 0.37104937
A31: PV of free cash flow | B31: =B29*B30 -> 2.2278636 | C31: =C29*C30 -> 1.7670158 | D31: =D29*D30 -> 1.3641498 | E31: =E29*E30 -> 1.3595776 | F31: =F29*F30 -> 1.3542693 | G31: =G29*G30 -> 1.3033318 | H31: =H29*H30 -> 1.2411112 | I31: =I29*I30 -> 1.1693027 | ... K31: =K29*K30 -> 1.0047461
A32: Terminal value | B32: =L29/($B$9-$B$10) -> 40.230918
A33: PV of terminal value | B33: =B32/(1+$B$9)^$K$17 -> 14.927657
A34: Equity value (PV FCF + PV TV + net cash) | B34: =SUM(B31:K31)+B33+$B$7 -> 28.578853
A35: Value per share | B35: =B34/$B$6*$B$13 -> 74.232714
A36: Value vs share price | B36: =B35/$B$4-1 -> -0.64908427
A38: Base: backlog converts, growth slows after 2028
A39: Revenue | B39: 17.5 | C39: 20.5 | D39: 21.5 | E39: 23.5 | F39: 25.5 | G39: =F39*(1+$F40+($B$10-$F40)*G$18/5) -> 27.44017 | H39: =G39*(1+$F40+($B$10-$F40)*H$18/5) -> 29.280413 | I39: =H39*(1+$F40+($B$10-$F40)*I$18/5) -> 30.979923 | J39: =I39*(1+$F40+($B$10-$F40)*J$18/5) -> 32.498598 | K39: =J39*(1+$F40+($B$10-$F40)*K$18/5) -> 33.798542 | L39: =K39*(1+$B$10) -> 35.150484
A40: Revenue growth | B40: =B39/$B$12-1 -> 0.25 | C40: =C39/B39-1 -> 0.17142857 | D40: =D39/C39-1 -> 0.048780488 | E40: =E39/D39-1 -> 0.093023256 | F40: =F39/E39-1 -> 0.085106383 | G40: =G39/F39-1 -> 0.076085106 | H40: =H39/G39-1 -> 0.06706383 | I40: =I39/H39-1 -> 0.058042553 | J40: =J39/I39-1 -> 0.049021277 | ... L40: =L39/K39-1 -> 0.04
A41: Operating margin | B41: 0.25 | C41: 0.26 | D41: 0.25 | E41: 0.25 | F41: 0.25 | G41: =$F41+($L41-$F41)*G$18/5 -> 0.248 | H41: =$F41+($L41-$F41)*H$18/5 -> 0.246 | I41: =$F41+($L41-$F41)*I$18/5 -> 0.244 | J41: =$F41+($L41-$F41)*J$18/5 -> 0.242 | K41: =$F41+($L41-$F41)*K$18/5 -> 0.24 | L41: 0.24
A42: Operating income | B42: =B39*B41 -> 4.375 | C42: =C39*C41 -> 5.33 | D42: =D39*D41 -> 5.375 | E42: =E39*E41 -> 5.875 | F42: =F39*F41 -> 6.375 | G42: =G39*G41 -> 6.8051622 | H42: =H39*H41 -> 7.2029816 | I42: =I39*I41 -> 7.5591012 | ... L42: =L39*L41 -> 8.4361162
A43: NOPAT | B43: =B42*(1-$B$8) -> 3.45625 | C43: =C42*(1-$B$8) -> 4.2107 | D43: =D42*(1-$B$8) -> 4.24625 | E43: =E42*(1-$B$8) -> 4.64125 | F43: =F42*(1-$B$8) -> 5.03625 | G43: =G42*(1-$B$8) -> 5.3760781 | H43: =H42*(1-$B$8) -> 5.6903555 | I43: =I42*(1-$B$8) -> 5.97169 | ... L43: =L42*(1-$B$8) -> 6.6645318
A44: Net reinvestment, % of revenue | B44: 0.02 | C44: 0.02 | D44: 0.02 | E44: 0.02 | F44: 0.02 | G44: =$F44+($L44-$F44)*G$18/5 -> 0.02 | H44: =$F44+($L44-$F44)*H$18/5 -> 0.02 | I44: =$F44+($L44-$F44)*I$18/5 -> 0.02 | J44: =$F44+($L44-$F44)*J$18/5 -> 0.02 | K44: =$F44+($L44-$F44)*K$18/5 -> 0.02 | L44: 0.02
...

Sheet ENR
A1: Siemens Energy (ETR: ENR): 10-year scenario DCF
A2: Units: EUR B unless noted. Blue = input, black = formula, green = link, yellow = key lever. Years 6 to 10 fade growth, margin and reinvestment toward terminal levels.
A4: Share price | B4: 133 | C4: Source: Stock Analysis, Oct 21, 2026 17:17 CEST
A5: Price date | B5: Oct 21, 2026 17:17 CEST | C5: Text
A6: Shares outstanding (billions) | B6: 0.85534 | C6: Source: Stock Analysis, https://stockanalysis.com
A7: Net cash, negative = net debt (EUR B) | B7: 8.13 | C7: Stock Analysis: cash EUR 11.09B less debt EUR 2.96B
A8: Tax rate | B8: 0.28 | C8: Analyst assumption
A9: Discount rate (WACC), from WACC tab | B9: =WACC!F26 -> 0.11 | C9: Calculated or assumed, per switch in WACC!B5
A10: Terminal growth | B10: 0.035 | C10: Analyst assumption
A11: Working capital, % of revenue change | B11: 0 | C11: Analyst assumption
A12: Base-year revenue (EUR B) | B12: 44 | C12: FY26E about EUR 44B from TTM EUR 41.84B; analyst estimate. Working capital set to 0 (prepayments ignored, conservative)
A13: Per-share multiplier | B13: 1 | C13: Units conversion (1 here)
A14: Selected scenario (1 Bear, 2 Base, 3 Bull) | B14: 2 | C14: Lever
A16: Year | B16: FY27 | C16: FY28 | D16: FY29 | E16: FY30 | F16: FY31 | G16: FY32 | H16: FY33 | I16: FY34 | J16: FY35 | K16: FY36 | L16: Terminal
A17: Discount period (years, mid-year) | B17: 0.5 | C17: =B17+1 -> 1.5 | D17: =C17+1 -> 2.5 | E17: =D17+1 -> 3.5 | F17: =E17+1 -> 4.5 | G17: =F17+1 -> 5.5 | H17: =G17+1 -> 6.5 | I17: =H17+1 -> 7.5 | J17: =I17+1 -> 8.5 | K17: =J17+1 -> 9.5
A18: Fade step (years 6 to 10) | B18: 0 | C18: 0 | D18: 0 | E18: 0 | F18: 0 | G18: 1 | H18: 2 | I18: 3 | J18: 4 | K18: 5
A20: Bear: wind relapse plus slower gas orders
A21: Revenue | B21: 46 | C21: 46 | D21: 47 | E21: 49 | F21: 51 | G21: =F21*(1+$F22+($B$10-$F22)*G$18/5) -> 53.022306 | H21: =G21*(1+$F22+($B$10-$F22)*H$18/5) -> 55.063124 | I21: =H21*(1+$F22+($B$10-$F22)*I$18/5) -> 57.118439 | J21: =I21*(1+$F22+($B$10-$F22)*J$18/5) -> 59.184029 | K21: =J21*(1+$F22+($B$10-$F22)*K$18/5) -> 61.25547 | L21: =K21*(1+$B$10) -> 63.399411
A22: Revenue growth | B22: =B21/$B$12-1 -> 0.045454545 | C22: =C21/B21-1 -> 0 | D22: =D21/C21-1 -> 0.02173913 | E22: =E21/D21-1 -> 0.042553191 | F22: =F21/E21-1 -> 0.040816327 | G22: =G21/F21-1 -> 0.039653061 | H22: =H21/G21-1 -> 0.038489796 | I22: =I21/H21-1 -> 0.037326531 | J22: =J21/I21-1 -> 0.036163265 | ... L22: =L21/K21-1 -> 0.035
A23: Operating margin | B23: 0.1 | C23: 0.09 | D23: 0.09 | E23: 0.1 | F23: 0.1 | G23: =$F23+($L23-$F23)*G$18/5 -> 0.098 | H23: =$F23+($L23-$F23)*H$18/5 -> 0.096 | I23: =$F23+($L23-$F23)*I$18/5 -> 0.094 | J23: =$F23+($L23-$F23)*J$18/5 -> 0.092 | K23: =$F23+($L23-$F23)*K$18/5 -> 0.09 | L23: 0.09
A24: Operating income | B24: =B21*B23 -> 4.6 | C24: =C21*C23 -> 4.14 | D24: =D21*D23 -> 4.23 | E24: =E21*E23 -> 4.9 | F24: =F21*F23 -> 5.1 | G24: =G21*G23 -> 5.196186 | H24: =H21*H23 -> 5.2860599 | I24: =I21*I23 -> 5.3691333 | ... L24: =L21*L23 -> 5.705947
A25: NOPAT | B25: =B24*(1-$B$8) -> 3.312 | C25: =C24*(1-$B$8) -> 2.9808 | D25: =D24*(1-$B$8) -> 3.0456 | E25: =E24*(1-$B$8) -> 3.528 | F25: =F24*(1-$B$8) -> 3.672 | G25: =G24*(1-$B$8) -> 3.7412539 | H25: =H24*(1-$B$8) -> 3.8059631 | I25: =I24*(1-$B$8) -> 3.865776 | ... L25: =L24*(1-$B$8) -> 4.1082818
A26: Net reinvestment, % of revenue | B26: 0.025 | C26: 0.025 | D26: 0.025 | E26: 0.025 | F26: 0.025 | G26: =$F26+($L26-$F26)*G$18/5 -> 0.025 | H26: =$F26+($L26-$F26)*H$18/5 -> 0.025 | I26: =$F26+($L26-$F26)*I$18/5 -> 0.025 | J26: =$F26+($L26-$F26)*J$18/5 -> 0.025 | K26: =$F26+($L26-$F26)*K$18/5 -> 0.025 | L26: 0.025
A27: Net reinvestment | B27: =B21*B26 -> 1.15 | C27: =C21*C26 -> 1.15 | D27: =D21*D26 -> 1.175 | E27: =E21*E26 -> 1.225 | F27: =F21*F26 -> 1.275 | G27: =G21*G26 -> 1.3255577 | H27: =H21*H26 -> 1.3765781 | I27: =I21*I26 -> 1.427961 | ... L27: =L21*L26 -> 1.5849853
A28: Change in working capital | B28: =$B$11*(B21-$B$12) -> 0 | C28: =$B$11*(C21-B21) -> 0 | D28: =$B$11*(D21-C21) -> 0 | E28: =$B$11*(E21-D21) -> 0 | F28: =$B$11*(F21-E21) -> 0 | G28: =$B$11*(G21-F21) -> 0 | H28: =$B$11*(H21-G21) -> 0 | I28: =$B$11*(I21-H21) -> 0 | J28: =$B$11*(J21-I21) -> 0 | ... L28: =$B$11*(L21-K21) -> 0
A29: Free cash flow | B29: =B25-B27-B28 -> 2.162 | C29: =C25-C27-C28 -> 1.8308 | D29: =D25-D27-D28 -> 1.8706 | E29: =E25-E27-E28 -> 2.303 | F29: =F25-F27-F28 -> 2.397 | G29: =G25-G27-G28 -> 2.4156963 | H29: =H25-H27-H28 -> 2.429385 | I29: =I25-I27-I28 -> 2.437815 | ... L29: =L25-L27-L28 -> 2.5232966
A30: Discount factor | B30: =1/(1+$B$9)^B$17 -> 0.949158 | C30: =1/(1+$B$9)^C$17 -> 0.85509729 | D30: =1/(1+$B$9)^D$17 -> 0.77035792 | E30: =1/(1+$B$9)^E$17 -> 0.69401615 | F30: =1/(1+$B$9)^F$17 -> 0.62523977 | G30: =1/(1+$B$9)^G$17 -> 0.56327907 | H30: =1/(1+$B$9)^H$17 -> 0.50745862 | I30: =1/(1+$B$9)^I$17 -> 0.45716993 | ... K30: =1/(1+$B$9)^K$17 -> 0.37104937
A31: PV of free cash flow | B31: =B29*B30 -> 2.0520796 | C31: =C29*C30 -> 1.5655121 | D31: =D29*D30 -> 1.4410315 | E31: =E29*E30 -> 1.5983192 | F31: =F29*F30 -> 1.4986997 | G31: =G29*G30 -> 1.3607112 | H31: =H29*H30 -> 1.2328124 | I31: =I29*I30 -> 1.1144957 | ... K31: =K29*K30 -> 0.90460638
A32: Terminal value | B32: =L29/($B$9-$B$10) -> 33.643954
A33: PV of terminal value | B33: =B32/(1+$B$9)^$K$17 -> 12.483568
A34: Equity value (PV FCF + PV TV + net cash) | B34: =SUM(B31:K31)+B33+$B$7 -> 34.387095
A35: Value per share | B35: =B34/$B$6*$B$13 -> 40.202837
A36: Value vs share price | B36: =B35/$B$4-1 -> -0.69772303
A38: Base: backlog converts at mid-teens margins
A39: Revenue | B39: 49 | C39: 54 | D39: 57 | E39: 60 | F39: 63 | G39: =F39*(1+$F40+($B$10-$F40)*G$18/5) -> 65.961 | H39: =G39*(1+$F40+($B$10-$F40)*H$18/5) -> 68.863284 | I39: =H39*(1+$F40+($B$10-$F40)*I$18/5) -> 71.686679 | J39: =I39*(1+$F40+($B$10-$F40)*J$18/5) -> 74.410772 | K39: =J39*(1+$F40+($B$10-$F40)*K$18/5) -> 77.015149 | L39: =K39*(1+$B$10) -> 79.71068
A40: Revenue growth | B40: =B39/$B$12-1 -> 0.11363636 | C40: =C39/B39-1 -> 0.10204082 | D40: =D39/C39-1 -> 0.055555556 | E40: =E39/D39-1 -> 0.052631579 | F40: =F39/E39-1 -> 0.05 | G40: =G39/F39-1 -> 0.047 | H40: =H39/G39-1 -> 0.044 | I40: =I39/H39-1 -> 0.041 | J40: =J39/I39-1 -> 0.038 | ... L40: =L39/K39-1 -> 0.035
A41: Operating margin | B41: 0.13 | C41: 0.15 | D41: 0.15 | E41: 0.15 | F41: 0.15 | G41: =$F41+($L41-$F41)*G$18/5 -> 0.148 | H41: =$F41+($L41-$F41)*H$18/5 -> 0.146 | I41: =$F41+($L41-$F41)*I$18/5 -> 0.144 | J41: =$F41+($L41-$F41)*J$18/5 -> 0.142 | K41: =$F41+($L41-$F41)*K$18/5 -> 0.14 | L41: 0.14
A42: Operating income | B42: =B39*B41 -> 6.37 | C42: =C39*C41 -> 8.1 | D42: =D39*D41 -> 8.55 | E42: =E39*E41 -> 9 | F42: =F39*F41 -> 9.45 | G42: =G39*G41 -> 9.762228 | H42: =H39*H41 -> 10.054039 | I42: =I39*I41 -> 10.322882 | ... L42: =L39*L41 -> 11.159495
A43: NOPAT | B43: =B42*(1-$B$8) -> 4.5864 | C43: =C42*(1-$B$8) -> 5.832 | D43: =D42*(1-$B$8) -> 6.156 | E43: =E42*(1-$B$8) -> 6.48 | F43: =F42*(1-$B$8) -> 6.804 | G43: =G42*(1-$B$8) -> 7.0288042 | H43: =H42*(1-$B$8) -> 7.2389084 | I43: =I42*(1-$B$8) -> 7.4324748 | ... L43: =L42*(1-$B$8) -> 8.0348365
A44: Net reinvestment, % of revenue | B44: 0.025 | C44: 0.025 | D44: 0.025 | E44: 0.025 | F44: 0.025 | G44: =$F44+($L44-$F44)*G$18/5 -> 0.025 | H44: =$F44+($L44-$F44)*H$18/5 -> 0.025 | I44: =$F44+($L44-$F44)*I$18/5 -> 0.025 | J44: =$F44+($L44-$F44)*J$18/5 -> 0.025 | K44: =$F44+($L44-$F44)*K$18/5 -> 0.025 | L44: 0.025
...

Sheet NVT
A1: nVent Electric (NVT): 10-year scenario DCF
A2: Units: $B unless noted. Blue = input, black = formula, green = link, yellow = key lever. Years 6 to 10 fade growth, margin and reinvestment toward terminal levels.
A4: Share price | B4: 139.78 | C4: Source: Stock Analysis, Oct 20, 2026 close
A5: Price date | B5: Oct 20, 2026 close | C5: Text
A6: Shares outstanding (billions) | B6: 0.16186 | C6: Source: Stock Analysis, https://stockanalysis.com
A7: Net cash, negative = net debt ($B) | B7: -1.37 | C7: Stock Analysis: cash $0.26B less debt $1.63B
A8: Tax rate | B8: 0.21 | C8: Analyst assumption
A9: Discount rate (WACC), from WACC tab | B9: =WACC!G26 -> 0.1 | C9: Calculated or assumed, per switch in WACC!B5
A10: Terminal growth | B10: 0.04 | C10: Analyst assumption
A11: Working capital, % of revenue change | B11: 0.12 | C11: Analyst assumption
A12: Base-year revenue ($B) | B12: 5.35 | C12: 2026E: FY25 revenue $3.893B plus 38% guided reported growth (Q2 call, Aug 2026); analyst estimate
A13: Per-share multiplier | B13: 1 | C13: Units conversion (1 here)
A14: Selected scenario (1 Bear, 2 Base, 3 Bull) | B14: 2 | C14: Lever
A16: Year | B16: 2027 | C16: 2028 | D16: 2029 | E16: 2030 | F16: 2031 | G16: 2032 | H16: 2033 | I16: 2034 | J16: 2035 | K16: 2036 | L16: Terminal
A17: Discount period (years, mid-year) | B17: 0.5 | C17: =B17+1 -> 1.5 | D17: =C17+1 -> 2.5 | E17: =D17+1 -> 3.5 | F17: =E17+1 -> 4.5 | G17: =F17+1 -> 5.5 | H17: =G17+1 -> 6.5 | I17: =H17+1 -> 7.5 | J17: =I17+1 -> 8.5 | K17: =J17+1 -> 9.5
A18: Fade step (years 6 to 10) | B18: 0 | C18: 0 | D18: 0 | E18: 0 | F18: 0 | G18: 1 | H18: 2 | I18: 3 | J18: 4 | K18: 5
A20: Bear: data center orders stall in 2028
A21: Revenue | B21: 5.7 | C21: 5.3 | D21: 5.4 | E21: 5.8 | F21: 6.2 | G21: =F21*(1+$F22+($B$10-$F22)*G$18/5) -> 6.591669 | H21: =G21*(1+$F22+($B$10-$F22)*H$18/5) -> 6.9698944 | I21: =H21*(1+$F22+($B$10-$F22)*I$18/5) -> 7.3294448 | J21: =I21*(1+$F22+($B$10-$F22)*J$18/5) -> 7.6650828 | K21: =J21*(1+$F22+($B$10-$F22)*K$18/5) -> 7.9716861 | L21: =K21*(1+$B$10) -> 8.2905536
A22: Revenue growth | B22: =B21/$B$12-1 -> 0.065420561 | C22: =C21/B21-1 -> -0.070175439 | D22: =D21/C21-1 -> 0.018867925 | E22: =E21/D21-1 -> 0.074074074 | F22: =F21/E21-1 -> 0.068965517 | G22: =G21/F21-1 -> 0.063172414 | H22: =H21/G21-1 -> 0.05737931 | I22: =I21/H21-1 -> 0.051586207 | J22: =J21/I21-1 -> 0.045793103 | ... L22: =L21/K21-1 -> 0.04
A23: Operating margin | B23: 0.2 | C23: 0.17 | D23: 0.17 | E23: 0.18 | F23: 0.18 | G23: =$F23+($L23-$F23)*G$18/5 -> 0.178 | H23: =$F23+($L23-$F23)*H$18/5 -> 0.176 | I23: =$F23+($L23-$F23)*I$18/5 -> 0.174 | J23: =$F23+($L23-$F23)*J$18/5 -> 0.172 | K23: =$F23+($L23-$F23)*K$18/5 -> 0.17 | L23: 0.17
A24: Operating income | B24: =B21*B23 -> 1.14 | C24: =C21*C23 -> 0.901 | D24: =D21*D23 -> 0.918 | E24: =E21*E23 -> 1.044 | F24: =F21*F23 -> 1.116 | G24: =G21*G23 -> 1.1733171 | H24: =H21*H23 -> 1.2267014 | I24: =I21*I23 -> 1.2753234 | ... L24: =L21*L23 -> 1.4093941
A25: NOPAT | B25: =B24*(1-$B$8) -> 0.9006 | C25: =C24*(1-$B$8) -> 0.71179 | D25: =D24*(1-$B$8) -> 0.72522 | E25: =E24*(1-$B$8) -> 0.82476 | F25: =F24*(1-$B$8) -> 0.88164 | G25: =G24*(1-$B$8) -> 0.92692049 | H25: =H24*(1-$B$8) -> 0.96909412 | I25: =I24*(1-$B$8) -> 1.0075055 | ... L25: =L24*(1-$B$8) -> 1.1134213
A26: Net reinvestment, % of revenue | B26: 0.01 | C26: 0.01 | D26: 0.01 | E26: 0.01 | F26: 0.01 | G26: =$F26+($L26-$F26)*G$18/5 -> 0.01 | H26: =$F26+($L26-$F26)*H$18/5 -> 0.01 | I26: =$F26+($L26-$F26)*I$18/5 -> 0.01 | J26: =$F26+($L26-$F26)*J$18/5 -> 0.01 | K26: =$F26+($L26-$F26)*K$18/5 -> 0.01 | L26: 0.01
A27: Net reinvestment | B27: =B21*B26 -> 0.057 | C27: =C21*C26 -> 0.053 | D27: =D21*D26 -> 0.054 | E27: =E21*E26 -> 0.058 | F27: =F21*F26 -> 0.062 | G27: =G21*G26 -> 0.06591669 | H27: =H21*H26 -> 0.069698944 | I27: =I21*I26 -> 0.073294448 | ... L27: =L21*L26 -> 0.082905536
A28: Change in working capital | B28: =$B$11*(B21-$B$12) -> 0.042 | C28: =$B$11*(C21-B21) -> -0.048 | D28: =$B$11*(D21-C21) -> 0.012 | E28: =$B$11*(E21-D21) -> 0.048 | F28: =$B$11*(F21-E21) -> 0.048 | G28: =$B$11*(G21-F21) -> 0.047000276 | H28: =$B$11*(H21-G21) -> 0.04538705 | I28: =$B$11*(I21-H21) -> 0.04314605 | J28: =$B$11*(J21-I21) -> 0.040276563 | ... L28: =$B$11*(L21-K21) -> 0.038264093
A29: Free cash flow | B29: =B25-B27-B28 -> 0.8016 | C29: =C25-C27-C28 -> 0.70679 | D29: =D25-D27-D28 -> 0.65922 | E29: =E25-E27-E28 -> 0.71876 | F29: =F25-F27-F28 -> 0.77164 | G29: =G25-G27-G28 -> 0.81400352 | H29: =H25-H27-H28 -> 0.85400812 | I29: =I25-I27-I28 -> 0.89106498 | ... L29: =L25-L27-L28 -> 0.99225172
A30: Discount factor | B30: =1/(1+$B$9)^B$17 -> 0.95346259 | C30: =1/(1+$B$9)^C$17 -> 0.86678417 | D30: =1/(1+$B$9)^D$17 -> 0.78798561 | E30: =1/(1+$B$9)^E$17 -> 0.71635056 | F30: =1/(1+$B$9)^F$17 -> 0.65122778 | G30: =1/(1+$B$9)^G$17 -> 0.59202525 | H30: =1/(1+$B$9)^H$17 -> 0.53820477 | I30: =1/(1+$B$9)^I$17 -> 0.48927707 | ... K30: =1/(1+$B$9)^K$17 -> 0.40436121
A31: PV of free cash flow | B31: =B29*B30 -> 0.76429561 | C31: =C29*C30 -> 0.61263438 | D31: =D29*D30 -> 0.51945587 | E31: =E29*E30 -> 0.51488413 | F31: =F29*F30 -> 0.5025134 | G31: =G29*G30 -> 0.48191064 | H31: =H29*H30 -> 0.45963125 | I31: =I29*I30 -> 0.43597766 | ... K31: =K29*K30 -> 0.38579626
A32: Terminal value | B32: =L29/($B$9-$B$10) -> 16.537529
A33: PV of terminal value | B33: =B32/(1+$B$9)^$K$17 -> 6.6871351
A34: Equity value (PV FCF + PV TV + net cash) | B34: =SUM(B31:K31)+B33+$B$7 -> 10.405496
A35: Value per share | B35: =B34/$B$6*$B$13 -> 64.287012
A36: Value vs share price | B36: =B35/$B$4-1 -> -0.54008433
A38: Base: data center growth slows, grid steady
A39: Revenue | B39: 6.3 | C39: 7.1 | D39: 7.4 | E39: 8 | F39: 8.6 | G39: =F39*(1+$F40+($B$10-$F40)*G$18/5) -> 9.1848 | H39: =G39*(1+$F40+($B$10-$F40)*H$18/5) -> 9.7450728 | I39: =H39*(1+$F40+($B$10-$F40)*I$18/5) -> 10.271307 | J39: =I39*(1+$F40+($B$10-$F40)*J$18/5) -> 10.754058 | K39: =J39*(1+$F40+($B$10-$F40)*K$18/5) -> 11.18422 | L39: =K39*(1+$B$10) -> 11.631589
A40: Revenue growth | B40: =B39/$B$12-1 -> 0.17757009 | C40: =C39/B39-1 -> 0.12698413 | D40: =D39/C39-1 -> 0.042253521 | E40: =E39/D39-1 -> 0.081081081 | F40: =F39/E39-1 -> 0.075 | G40: =G39/F39-1 -> 0.068 | H40: =H39/G39-1 -> 0.061 | I40: =I39/H39-1 -> 0.054 | J40: =J39/I39-1 -> 0.047 | ... L40: =L39/K39-1 -> 0.04
A41: Operating margin | B41: 0.22 | C41: 0.22 | D41: 0.21 | E41: 0.22 | F41: 0.22 | G41: =$F41+($L41-$F41)*G$18/5 -> 0.216 | H41: =$F41+($L41-$F41)*H$18/5 -> 0.212 | I41: =$F41+($L41-$F41)*I$18/5 -> 0.208 | J41: =$F41+($L41-$F41)*J$18/5 -> 0.204 | K41: =$F41+($L41-$F41)*K$18/5 -> 0.2 | L41: 0.2
A42: Operating income | B42: =B39*B41 -> 1.386 | C42: =C39*C41 -> 1.562 | D42: =D39*D41 -> 1.554 | E42: =E39*E41 -> 1.76 | F42: =F39*F41 -> 1.892 | G42: =G39*G41 -> 1.9839168 | H42: =H39*H41 -> 2.0659554 | I42: =I39*I41 -> 2.1364318 | ... L42: =L39*L41 -> 2.3263179
A43: NOPAT | B43: =B42*(1-$B$8) -> 1.09494 | C43: =C42*(1-$B$8) -> 1.23398 | D43: =D42*(1-$B$8) -> 1.22766 | E43: =E42*(1-$B$8) -> 1.3904 | F43: =F42*(1-$B$8) -> 1.49468 | G43: =G42*(1-$B$8) -> 1.5672943 | H43: =H42*(1-$B$8) -> 1.6321048 | I43: =I42*(1-$B$8) -> 1.6877811 | ... L43: =L42*(1-$B$8) -> 1.8377911
A44: Net reinvestment, % of revenue | B44: 0.01 | C44: 0.01 | D44: 0.01 | E44: 0.01 | F44: 0.01 | G44: =$F44+($L44-$F44)*G$18/5 -> 0.01 | H44: =$F44+($L44-$F44)*H$18/5 -> 0.01 | I44: =$F44+($L44-$F44)*I$18/5 -> 0.01 | J44: =$F44+($L44-$F44)*J$18/5 -> 0.01 | K44: =$F44+($L44-$F44)*K$18/5 -> 0.01 | L44: 0.01
...
